<robot name="onshape">
<link name="torso">
<!-- Shapes for x_plate -->
<collision>
<origin xyz="0.057868973494375273992 3.7816295597551288572e-15 0.059500000000000496936" rpy="1.5707963267948927832 -3.7125353914934716787e-15 1.5707963267949058839" />
<geometry>
<box size="0.13300000000000000711 0.11300000000000000322 0.0060000000000000001249" />
</geometry>
</collision>
<!-- Shapes for mx-64at_ar -->
<collision>
<origin xyz="0.023418973494356523646 -0.046400000000006297318 -0.01699999999999969244" rpy="-3.1415926535897926719 2.0394558334225169899e-15 -1.570796326795006026" />
<geometry>
<box size="0.040199999999999999623 0.061100000000000001532 0.041000000000000001721" />
</geometry>
</collision>
<!-- Shapes for mx-64at_ar -->
<collision>
<origin xyz="0.013318973494383691547 0.056000000000007300882 0.14300000000000975819" rpy="-1.5707963267949880404 -1.5707963267948745756 0" />
<geometry>
<box size="0.040199999999999999623 0.061100000000000001532 0.041000000000000001721" />
</geometry>
</collision>
<!-- Shapes for x_plate -->
<collision>
<origin xyz="-0.05713102650564363949 7.7472351814137248476e-15 0.059500000000000226319" rpy="1.5707963267948952257 -1.2157103114052321777e-15 1.5707963267949001107" />
<geometry>
<box size="0.13300000000000000711 0.11300000000000000322 0.0060000000000000001249" />
</geometry>
</collision>
<!-- Shapes for mx-64at_ar -->
<collision>
<origin xyz="0.023418973494361561283 0.046400000000008469192 -0.016999999999999768768" rpy="-3.1415926535897926719 2.0256134443711579168e-15 -1.570796326795006026" />
<geometry>
<box size="0.040199999999999999623 0.061100000000000001532 0.041000000000000001721" />
</geometry>
</collision>
<!-- Shapes for mx-64at_ar -->
<collision>
<origin xyz="0.0183189734943615401 5.1733021121216969054e-15 0.13600000000000000977" rpy="4.0245584642703556725e-16 1.0634679180433978839e-14 -1.570796326795006026" />
<geometry>
<box size="0.040199999999999999623 0.061100000000000001532 0.041000000000000001721" />
</geometry>
</collision>
<!-- Shapes for mx-64at_ar -->
<collision>
<origin xyz="0.013318973494377002453 -0.055999999999997537858 0.14300000000001039657" rpy="1.5707963267949873742 1.5707963267948845676 0" />
<geometry>
<box size="0.040199999999999999623 0.061100000000000001532 0.041000000000000001721" />
</geometry>
</collision>
<visual>
<origin xyz="0 0 0" rpy="0 -0 0" />
<geometry>
<mesh filename="package:///torso_visual.stl"/>
</geometry>
<material name="torso_material">
<color rgba="0.19290227848641136599 0.19795953421683204487 0.203016789947252696 1.0"/>
</material>
</visual>
<inertial>
<origin xyz="0.0030062230546194206732 0.001852593969069553587 0.06872042031790170924" rpy="0 0 0"/>
<mass value="2.3224634991401664763" />
<inertia ixx="0.011224307318969789157" ixy="-4.8566894310192453382e-06"  ixz="0.00021812167095550168291" iyy="0.010571052859840234656" iyz="-4.7744972223613473764e-05" izz="0.0072547982502737572499" />
</inertial>
</link>

<link name="head_base">
<inertial>
<origin xyz="0 0 0" rpy="0 0 0" />
<mass value="1e-9" />
<inertia ixx="0" ixy="0" ixz="0" iyy="0" iyz="0" izz="0" />
</inertial>
</link>
<joint name="head_base_frame" type="fixed">
<origin xyz="0.035868973494361730547 2.8785898342325425989e-15 0.15950000000001055001" rpy="3.7964142151183067762e-14 -9.9503738582029639158e-15 -1.0422282733566275005e-13" />
<parent link="torso" />
<child link="head_base" />
<axis xyz="0 0 0"/>
</joint>

<link name="trunk">
<inertial>
<origin xyz="0 0 0" rpy="0 0 0" />
<mass value="1e-9" />
<inertia ixx="0" ixy="0" ixz="0" iyy="0" iyz="0" izz="0" />
</inertial>
</link>
<joint name="trunk_frame" type="fixed">
<origin xyz="0.0058680275433185069903 -3.8373166558143998956e-15 -0.10150000000000038158" rpy="2.6042242647039365222e-15 -1.132015398992152165e-28 -6.5838035962736754478e-15" />
<parent link="torso" />
<child link="trunk" />
<axis xyz="0 0 0"/>
</joint>

<link name="u_shoulder">
<!-- Shapes for u_base_64 -->
<collision>
<origin xyz="-3.449073356937238628e-33 -3.5821479661024894114e-33 -0.0031250000000000001735" rpy="-1.1399492769849534596e-30 1.0977093533243529221e-30 2.3419308123748787973e-31" />
<geometry>
<box size="0.049000000000000001887 0.02999999999999999889 0.0062500000000000003469" />
</geometry>
</collision>
<visual>
<origin xyz="0 0 0" rpy="0 -0 0" />
<geometry>
<mesh filename="package:///u_shoulder_visual.stl"/>
</geometry>
<material name="u_shoulder_material">
<color rgba="0.30196078431372547213 0.30196078431372547213 0.30196078431372547213 1.0"/>
</material>
</visual>
<inertial>
<origin xyz="-1.4279621964222781834e-15 -0.0056623385441345380417 -0.015967577811135637983" rpy="0 0 0"/>
<mass value="0.057010148283040865125" />
<inertia ixx="2.2175831062598994335e-05" ixy="-2.0942889620862575883e-19"  ixz="9.31498013963315101e-19" iyy="4.0331441206531850696e-05" iyz="-6.107032435584823057e-06" izz="3.5862924589732239947e-05" />
</inertial>
</link>

<link name="right_humerus">
<!-- Shapes for mx-64at_ar -->
<collision>
<origin xyz="3.8633431404773955145e-18 -0.017549999999999996159 -0.023500000000010002471" rpy="-7.0776717819834362917e-16 -3.6457258243990818313e-30 3.9443045261050555238e-30" />
<geometry>
<box size="0.040199999999999999623 0.061100000000000001532 0.041000000000000001721" />
</geometry>
</collision>
<visual>
<origin xyz="0 0 0" rpy="0 -0 0" />
<geometry>
<mesh filename="package:///right_humerus_visual.stl"/>
</geometry>
<material name="right_humerus_material">
<color rgba="0.1686274509803921684 0.1686274509803921684 0.1686274509803921684 1.0"/>
</material>
</visual>
<inertial>
<origin xyz="0.00089663189558000355034 -0.0506168292087223054 -0.024227783076275471313" rpy="0 0 0"/>
<mass value="0.21891648912829692053" />
<inertia ixx="0.00062836186142250767626" ixy="1.4577972502765392952e-05"  ixz="-1.3477156532987289936e-06" iyy="6.7719613468240175917e-05" iyz="-4.0514772324774824658e-05" izz="0.00061652046704584282256" />
</inertial>
</link>

<link name="radius_v2">
<!-- Shapes for hand -->
<collision>
<origin xyz="1.2340500617816998344e-19 0.12760000000000007447 0.042000000000009987677" rpy="3.141592653589793116 -1.3877787807814644726e-17 1.57079632679489678" />
<geometry>
<cylinder length="0.0030000000000000000625" radius="0.040000000000000000833" />
</geometry>
</collision>
<collision>
<origin xyz="4.2103802088886768226e-18 0.053975600000000040213 0.042000000000009987677" rpy="3.141592653589793116 -1.3877787807814644726e-17 1.57079632679489678" />
<geometry>
<box size="0.077551200000000000689 0.041200000000000000511 0.0030000000000000000625" />
</geometry>
</collision>
<!-- Shapes for hand -->
<collision>
<origin xyz="-1.456361811209818317e-16 0.12760000000000060183 0.0050000000000099695599" rpy="3.141592653589793116 -1.3877787807816693916e-17 1.570796326794896558" />
<geometry>
<cylinder length="0.0030000000000000000625" radius="0.040000000000000000833" />
</geometry>
</collision>
<collision>
<origin xyz="-1.4972315632370011294e-16 0.053975599999998402634 0.0050000000000099686925" rpy="3.141592653589793116 -1.3877787807816693916e-17 1.570796326794896558" />
<geometry>
<box size="0.077551200000000000689 0.041200000000000000511 0.0030000000000000000625" />
</geometry>
</collision>
<!-- Shapes for mx-64at_ar -->
<collision>
<origin xyz="-6.9388939039072283776e-18 0.017550000000000013506 0.023500000000009985124" rpy="-3.141592653589793116 -6.505213034838388152e-19 2.4651903288156618919e-32" />
<geometry>
<box size="0.040199999999999999623 0.061100000000000001532 0.041000000000000001721" />
</geometry>
</collision>
<visual>
<origin xyz="0 0 0" rpy="0 -0 0" />
<geometry>
<mesh filename="package:///radius_v2_visual.stl"/>
</geometry>
<material name="radius_v2_material">
<color rgba="0.20630461665822108497 0.20630461665822108497 0.20630461665822108497 1.0"/>
</material>
</visual>
<inertial>
<origin xyz="9.0078609988980320729e-05 0.050592813860687431415 0.02216412816099538538" rpy="0 0 0"/>
<mass value="0.22758681850404099967" />
<inertia ixx="0.00063622372865133598827" ixy="6.8818031269177623409e-07"  ixz="-6.3997466140507423643e-07" iyy="0.00011529484226279212869" iyz="-1.2452787769693677222e-05" izz="0.00065540810703738677703" />
</inertial>
</link>

<joint name="right_elbow" type="revolute">
<origin xyz="-0.023500000000010012879 -0.1420000000000199436 -0.0024999999999998703815" rpy="3.141592653589793116 -1.5707963267948956698 0" />
<parent link="right_humerus" />
<child link="radius_v2" />
<axis xyz="0 0 1"/>
<limit effort="10" velocity="6" />
<joint_properties friction="0.0"/>
</joint>

<joint name="right_shoulder_roll" type="revolute">
<origin xyz="-0.023500000000005162593 -0.029999999999999721334 -0.034999999999995812239" rpy="-3.6082248300526689938e-16 -1.5707963267948750197 0" />
<parent link="u_shoulder" />
<child link="right_humerus" />
<axis xyz="0 0 1"/>
<limit effort="10" velocity="6" />
<joint_properties friction="0.0"/>
</joint>

<joint name="right_shoulder_pitch" type="revolute">
<origin xyz="0.030868973494376360234 -0.079500000000014142687 0.14300000000001011902" rpy="1.5707963267948708008 -4.8017145815038012485e-15 3.141592653589783346" />
<parent link="torso" />
<child link="u_shoulder" />
<axis xyz="0 0 1"/>
<limit effort="10" velocity="6" />
<joint_properties friction="0.0"/>
</joint>

<link name="u_shoulder_2">
<!-- Shapes for u_base_64 -->
<collision>
<origin xyz="-2.2742318684323046797e-34 5.5767765781037352038e-33 0.0031250000000000001735" rpy="-3.141592653589793116 -1.7803232810543605508e-32 5.3412457120770700902e-32" />
<geometry>
<box size="0.049000000000000001887 0.02999999999999999889 0.0062500000000000003469" />
</geometry>
</collision>
<visual>
<origin xyz="0 0 0" rpy="0 -0 0" />
<geometry>
<mesh filename="package:///u_shoulder_2_visual.stl"/>
</geometry>
<material name="u_shoulder_2_material">
<color rgba="0.30196078431372547213 0.30196078431372547213 0.30196078431372547213 1.0"/>
</material>
</visual>
<inertial>
<origin xyz="3.8243415810955606309e-17 0.0056623385441346872279 0.015967577811136370036" rpy="0 0 0"/>
<mass value="0.057010148283040872064" />
<inertia ixx="2.2175831062599699067e-05" ixy="6.9139064319632265176e-20"  ixz="-6.6465616579860879731e-20" iyy="4.0331441206528069541e-05" iyz="-6.1070324355848162808e-06" izz="3.5862924589727862481e-05" />
</inertial>
</link>

<link name="left_humerus">
<!-- Shapes for mx-64at_ar -->
<collision>
<origin xyz="-3.6533276404086269294e-18 -0.017549999999999899014 -0.023500000000009405726" rpy="-3.6082248300317336114e-16 -1.5096984604399660079e-15 1.0643723572585666396e-17" />
<geometry>
<box size="0.040199999999999999623 0.061100000000000001532 0.041000000000000001721" />
</geometry>
</collision>
<visual>
<origin xyz="0 0 0" rpy="0 -0 0" />
<geometry>
<mesh filename="package:///left_humerus_visual.stl"/>
</geometry>
<material name="left_humerus_material">
<color rgba="0.1686274509803921684 0.1686274509803921684 0.1686274509803921684 1.0"/>
</material>
</visual>
<inertial>
<origin xyz="-0.00070933944006917827498 -0.050616829199539470352 -0.024244762808352745415" rpy="0 0 0"/>
<mass value="0.21891648912829692053" />
<inertia ixx="0.00062835638739090781714" ixy="-1.5955317761662684585e-05"  ixz="2.5456885382785554311e-06" iyy="6.7779986888158260229e-05" iyz="-4.0495008981122782173e-05" izz="0.00061658631376241819586" />
</inertial>
</link>

<link name="radius_v2_2">
<!-- Shapes for mx-64at_ar -->
<collision>
<origin xyz="1.2784218128558833439e-17 -0.017549999999999909422 -0.023500000000009912265" rpy="2.2146409489398982036e-15 -5.2447900715974208122e-16 1.110223024625163936e-16" />
<geometry>
<box size="0.040199999999999999623 0.061100000000000001532 0.041000000000000001721" />
</geometry>
</collision>
<!-- Shapes for hand -->
<collision>
<origin xyz="-4.7176934470313848149e-17 -0.12760000000000012998 -0.0050000000000101733899" rpy="-4.9034850239004565199e-16 1.5820678100908695666e-15 -1.570796326794896336" />
<geometry>
<cylinder length="0.0030000000000000000625" radius="0.040000000000000000833" />
</geometry>
</collision>
<collision>
<origin xyz="-7.5785760889284458016e-17 -0.053975599999998180589 -0.0050000000000100571634" rpy="-4.9034850239004565199e-16 1.5820678100908695666e-15 -1.570796326794896336" />
<geometry>
<box size="0.077551200000000000689 0.041200000000000000511 0.0030000000000000000625" />
</geometry>
</collision>
<!-- Shapes for hand -->
<collision>
<origin xyz="8.4428592053086125056e-18 -0.12759999999999957487 -0.042000000000010015433" rpy="-5.5727991665773771823e-16 1.5820678100908733137e-15 -1.570796326794896336" />
<geometry>
<cylinder length="0.0030000000000000000625" radius="0.040000000000000000833" />
</geometry>
</collision>
<collision>
<origin xyz="-1.1992016808244949944e-17 -0.053975599999999776535 -0.042000000000009897472" rpy="-5.5727991665773771823e-16 1.5820678100908733137e-15 -1.570796326794896336" />
<geometry>
<box size="0.077551200000000000689 0.041200000000000000511 0.0030000000000000000625" />
</geometry>
</collision>
<visual>
<origin xyz="0 0 0" rpy="0 -0 0" />
<geometry>
<mesh filename="package:///radius_v2_2_visual.stl"/>
</geometry>
<material name="radius_v2_2_material">
<color rgba="0.20630461665822111272 0.20630461665822111272 0.20630461665822111272 1.0"/>
</material>
</visual>
<inertial>
<origin xyz="9.0078609989017847676e-05 -0.050592813860687244065 -0.022164128160995381911" rpy="0 0 0"/>
<mass value="0.22758681850404099967" />
<inertia ixx="0.00063622372865133197672" ixy="-6.8818031269148061959e-07"  ixz="6.3997466140511817626e-07" iyy="0.00011529484226279136975" iyz="-1.2452787769694304026e-05" izz="0.00065540810703738146444" />
</inertial>
</link>

<joint name="left_elbow" type="revolute">
<origin xyz="0.023499999999999174327 -0.14200000000002915845 -0.0024999999999899061298" rpy="-1.1721201801673205241e-15 1.5707963267948961139 0" />
<parent link="left_humerus" />
<child link="radius_v2_2" />
<axis xyz="0 0 1"/>
<limit effort="10" velocity="6" />
<joint_properties friction="0.0"/>
</joint>

<joint name="left_shoulder_roll" type="revolute">
<origin xyz="0.02350000000000003475 0.029999999999999957256 0.035000000000000100475" rpy="-3.141592653589793116 -1.5707963267948841235 0" />
<parent link="u_shoulder_2" />
<child link="left_humerus" />
<axis xyz="0 0 1"/>
<limit effort="10" velocity="6" />
<joint_properties friction="0.0"/>
</joint>

<joint name="left_shoulder_pitch" type="revolute">
<origin xyz="0.030868973494384634865 0.079500000000020762392 0.14300000000001031331" rpy="-1.5707963267949047736 1.5866937393608840934e-15 1.2760953914789753679e-15" />
<parent link="torso" />
<child link="u_shoulder_2" />
<axis xyz="0 0 1"/>
<limit effort="10" velocity="6" />
<joint_properties friction="0.0"/>
</joint>

<link name="u_hip_with_saver">
<inertial>
<origin xyz="-6.066189937938495782e-11 0.0012617757666184457269 -0.032913798334010091473" rpy="0 0 0"/>
<mass value="0.13603079497559261712" />
<inertia ixx="0.00012159106574301458369" ixy="4.6578748726061140235e-14"  ixz="1.9417493698314885375e-13" iyy="7.5515874860534274999e-05" iyz="7.1305998545029701415e-07" izz="5.6688399673280287473e-05" />
</inertial>
</link>

<link name="mx106_with_u_r">
<!-- Shapes for inner -->
<collision>
<origin xyz="-0.015149999999999212708 -0.00015000000000067389982 -0.079943750000000091127" rpy="-3.1415926535897922278 3.228583736873494373e-15 1.5707963267948954478" />
<geometry>
<box size="0.026999999999999999695 0.058000000000000002942 0.025999999999999998807" />
</geometry>
</collision>
<!-- Shapes for inner -->
<collision>
<origin xyz="-0.015149999999999500672 -0.00049999999999980788978 -0.020249999999999976352" rpy="-1.5707963267948945596 -1.5707963267948918951 0" />
<geometry>
<box size="0.026999999999999999695 0.058000000000000002942 0.025999999999999998807" />
</geometry>
</collision>
<visual>
<origin xyz="0 0 0" rpy="0 -0 0" />
<geometry>
<mesh filename="package:///mx106_with_u_r_visual.stl"/>
</geometry>
<material name="mx106_with_u_r_material">
<color rgba="0.64705882352941179736 0.64705882352941179736 0.64705882352941179736 1.0"/>
</material>
</visual>
<inertial>
<origin xyz="-0.016034034687357073129 -0.0024855086627690019946 -0.042423551723118263501" rpy="0 0 0"/>
<mass value="0.13646106366842530866" />
<inertia ixx="0.00012653897607754386418" ixy="1.4013009140675569802e-06"  ixz="-7.3381179937599855278e-06" iyy="0.00015886442271599807174" iyz="7.5459141585533953629e-06" izz="8.1606165644482008383e-05" />
</inertial>
</link>

<link name="thigh_horn_left">
<!-- Shapes for thigh_free_left -->
<collision>
<origin xyz="-4.8062121825055156229e-17 0.039999999999999896749 -0.0053999999999998979372" rpy="3.1415926535897922278 2.2204460492504171119e-16 2.2898349882893794482e-16" />
<geometry>
<box size="0.02999999999999999889 0.080000000000000001665 0.0030000000000000000625" />
</geometry>
</collision>
<!-- Shapes for thigh_horn -->
<collision>
<origin xyz="-1.44001944170100448e-16 0.040000000000000576761 0.043600000000000360689" rpy="-3.1415926535897908956 1.1102230246179906019e-16 2.0816681711720035921e-16" />
<geometry>
<box size="0.02999999999999999889 0.080000000000000001665 0.0030000000000000000625" />
</geometry>
</collision>
<!-- Shapes for inner -->
<collision>
<origin xyz="0.00014999999999970592413 0.12485000000000023856 0.016500000000020387247" rpy="-3.1415926535897922278 4.2743586448067390847e-15 -3.1415926535897922278" />
<geometry>
<box size="0.026999999999999999695 0.058000000000000002942 0.025999999999999998807" />
</geometry>
</collision>
<visual>
<origin xyz="0 0 0" rpy="0 -0 0" />
<geometry>
<mesh filename="package:///thigh_horn_left_visual.stl"/>
</geometry>
<material name="thigh_horn_left_material">
<color rgba="0.64705882352941179736 0.64705882352941179736 0.64705882352941179736 1.0"/>
</material>
</visual>
<inertial>
<origin xyz="-9.3607420558616577684e-05 0.08686273003829289574 0.015690262141934023521" rpy="0 0 0"/>
<mass value="0.084554717205627710763" />
<inertia ixx="0.00032732886979571916737" ixy="2.3832990931729521158e-08"  ixz="-1.2507329298489463823e-09" iyy="3.6205724865159367922e-05" iyz="-4.5673960747492644652e-05" izz="0.00030587666416608439053" />
</inertial>
</link>

<link name="tibia_left_full">
<!-- Shapes for tibia_horn_side -->
<collision>
<origin xyz="-0.064999999999989649391 1.5319744124744550247e-14 0.043500000000007491008" rpy="-1.2156942119645156462e-14 1.9821168646937639238e-14 -5.7138016002716118152e-14" />
<geometry>
<box size="0.14999999999999999445 0.035000000000000003331 0.0030000000000000000625" />
</geometry>
</collision>
<!-- Shapes for tibia_left -->
<collision>
<origin xyz="-0.064999999999992758015 -0.0024999999999906633366 -0.0084999999999944581691" rpy="-2.9706954939922338739e-31 -8.7661207377951485569e-31 -9.9507668969770201492e-30" />
<geometry>
<box size="0.14999999999999999445 0.035000000000000003331 0.0030000000000000000625" />
</geometry>
</collision>
<visual>
<origin xyz="0 0 0" rpy="0 -0 0" />
<geometry>
<mesh filename="package:///tibia_left_full_visual.stl"/>
</geometry>
<material name="tibia_left_full_material">
<color rgba="0.5 0.5 0.5 1.0"/>
</material>
</visual>
<inertial>
<origin xyz="-0.070000001170443013065 1.758669057392155357e-13 0.0013921737730304333067" rpy="0 0 0"/>
<mass value="0.050146782973123575633" />
<inertia ixx="1.6277029155994916597e-05" ixy="1.4619267923942306229e-17"  ixz="-1.2986502227741830414e-13" iyy="0.00026199625807211794626" iyz="-3.3843943140268751589e-16" izz="0.00024814461872021395311" />
</inertial>
</link>

<link name="mx106_with_u_l">
<!-- Shapes for inner -->
<collision>
<origin xyz="0.015149999999999188421 -0.059843750000000452138 0.015849999999999302147" rpy="1.5707963267948921171 -1.5707963267948954478 0" />
<geometry>
<box size="0.026999999999999999695 0.058000000000000002942 0.025999999999999998807" />
</geometry>
</collision>
<!-- Shapes for inner -->
<collision>
<origin xyz="0.015149999999999507611 0.00015000000000028879121 0.016499999999999778733" rpy="-3.1415926535897904515 4.7739590058865165159e-15 -1.570796326794896558" />
<geometry>
<box size="0.026999999999999999695 0.058000000000000002942 0.025999999999999998807" />
</geometry>
</collision>
<visual>
<origin xyz="0 0 0" rpy="0 -0 0" />
<geometry>
<mesh filename="package:///mx106_with_u_l_visual.stl"/>
</geometry>
<material name="mx106_with_u_l_material">
<color rgba="0.64705882352941179736 0.64705882352941179736 0.64705882352941179736 1.0"/>
</material>
</visual>
<inertial>
<origin xyz="0.016034034687357062721 -0.022317314664823957593 0.018479271590264544078" rpy="0 0 0"/>
<mass value="0.13646106366842530866" />
<inertia ixx="0.00012658119622732417076" ixy="7.3294705909746919514e-06"  ixz="1.4099476186479416491e-06" iyy="8.1610391256079224784e-05" iyz="-7.576163998991999715e-06" izz="0.00015890241725418244941" />
</inertial>
</link>

<link name="left_foot_asm">
<!-- Shapes for cleat -->
<collision>
<origin xyz="0.051999999999999407807 -0.032499999999999383549 -0.075630000000000544014" rpy="-1.570796326794896558 -1.1343060455615296966 -1.5707963267948978903" />
<geometry>
<cylinder length="0.016000000000000000333" radius="0.0080000000000000001665" />
</geometry>
</collision>
<!-- Shapes for cleat -->
<collision>
<origin xyz="0.051999999999999255151 0.043500000000000614564 0.065969999999999806573" rpy="-1.570796326794896558 -1.1343060455615281423 -1.5707963267948992225" />
<geometry>
<cylinder length="0.016000000000000000333" radius="0.0080000000000000001665" />
</geometry>
</collision>
<!-- Shapes for cleat -->
<collision>
<origin xyz="0.051999999999999255151 -0.03249999999999868272 0.065969999999999792695" rpy="-1.570796326794896558 -1.1343060455615292526 -1.57079632679489678" />
<geometry>
<cylinder length="0.016000000000000000333" radius="0.0080000000000000001665" />
</geometry>
</collision>
<!-- Shapes for cleat -->
<collision>
<origin xyz="0.051999999999999380051 0.043500000000000045575 -0.075630000000000544014" rpy="-1.570796326794896558 -1.1343060455615274762 -1.5707963267948981123" />
<geometry>
<cylinder length="0.016000000000000000333" radius="0.0080000000000000001665" />
</geometry>
</collision>
<!-- Shapes for foot_plate -->
<collision>
<origin xyz="0.041499999999999426237 0.0055000000000005461187 -0.0048300000000003964762" rpy="-1.570796326794896558 -9.3713847205708011454e-31 1.570796326794896558" />
<geometry>
<box size="0.091999999999999998446 0.1575999999999999901 0.0030000000000000000625" />
</geometry>
</collision>
<visual>
<origin xyz="0 0 0" rpy="0 -0 0" />
<geometry>
<mesh filename="package:///left_foot_asm_visual.stl"/>
</geometry>
<material name="left_foot_asm_material">
<color rgba="0.30196078431372547213 0.30077323167299724327 0.29800227551129809811 1.0"/>
</material>
</visual>
<inertial>
<origin xyz="0.031258906017487958495 0.0041429761138332263024 0.0008174521875965917771" rpy="0 0 0"/>
<mass value="0.32138977066764801149" />
<inertia ixx="0.0010224927730150461334" ixy="-8.6967442944984442124e-06"  ixz="-2.1885686287278519963e-05" iyy="0.00086439986274515923786" iyz="-1.0407520697592360524e-05" izz="0.00032657256034924434396" />
</inertial>
</link>

<link name="left_foot">
<inertial>
<origin xyz="0 0 0" rpy="0 0 0" />
<mass value="1e-9" />
<inertia ixx="0" ixy="0" ixz="0" iyy="0" iyz="0" izz="0" />
</inertial>
</link>
<joint name="left_foot_frame" type="fixed">
<origin xyz="0.059999999999999109601 5.3429483060085658508e-16 -0.02033000000000043106" rpy="-2.775557561558958448e-17 -1.570796326794891451 0" />
<parent link="left_foot_asm" />
<child link="left_foot" />
<axis xyz="0 0 0"/>
</joint>

<joint name="left_ankle_roll" type="revolute">
<origin xyz="-3.3306690738754696213e-16 0.020100000000000041445 0.015999999999999917066" rpy="1.5707963267948990005 2.8517487916724881289e-15 -3.1415926535897926719" />
<parent link="mx106_with_u_l" />
<child link="left_foot_asm" />
<axis xyz="0 0 1"/>
<limit effort="10" velocity="6" />
<joint_properties friction="0.0"/>
</joint>

<joint name="left_ankle_pitch" type="revolute">
<origin xyz="-0.13999999999999410139 9.4230179215060161368e-15 4.6629367034256574698e-15" rpy="6.6613381477670753924e-16 -8.970180271625489804e-15 -5.3999664202879601807e-14" />
<parent link="tibia_left_full" />
<child link="mx106_with_u_l" />
<axis xyz="0 0 1"/>
<limit effort="10" velocity="6" />
<joint_properties friction="0.0"/>
</joint>

<joint name="left_knee" type="revolute">
<origin xyz="-5.1521287236511170704e-16 0.13999999999999945821 -0.00099999999997956584563" rpy="5.6066262743583744929e-15 6.7205214539759444841e-15 -1.5707963267947766539" />
<parent link="thigh_horn_left" />
<child link="tibia_left_full" />
<axis xyz="0 0 1"/>
<limit effort="10" velocity="6" />
<joint_properties friction="0.0"/>
</joint>

<joint name="left_hip_pitch" type="revolute">
<origin xyz="-1.8041124150158793782e-16 0.016000000000000007272 -0.020099999999999802053" rpy="1.5707963267948976682 -1.5707963267948936714 0" />
<parent link="mx106_with_u_r" />
<child link="thigh_horn_left" />
<axis xyz="0 0 1"/>
<limit effort="10" velocity="6" />
<joint_properties friction="0.0"/>
</joint>

<joint name="left_hip_roll" type="revolute">
<origin xyz="2.3592239273284576484e-16 -0.020099054048956215696 -0.060399999999998552069" rpy="1.5707963267948876762 -1.5707963267948923392 0" />
<parent link="u_hip_with_saver" />
<child link="mx106_with_u_r" />
<axis xyz="0 0 1"/>
<limit effort="10" velocity="6" />
<joint_properties friction="0.0"/>
</joint>

<joint name="left_hip_yaw" type="revolute">
<origin xyz="0.0058689734943615451748 0.04640000000001042596 -0.04109999999999978948" rpy="-1.824649325745780325e-15 -3.0483134745539648229e-15 1.5707963267949009989" />
<parent link="torso" />
<child link="u_hip_with_saver" />
<axis xyz="0 0 1"/>
<limit effort="10" velocity="6" />
<joint_properties friction="0.0"/>
</joint>

<link name="u_hip_with_saver_2">
<inertial>
<origin xyz="-6.0662208488337922048e-11 0.001261775766618823463 -0.03291379833401136823" rpy="0 0 0"/>
<mass value="0.13603079497559264488" />
<inertia ixx="0.00012159106574302275586" ixy="4.6578776019089728531e-14"  ixz="1.9417476882145037183e-13" iyy="7.551587486053958759e-05" iyz="7.130599854505188309e-07" izz="5.6688399673284210929e-05" />
</inertial>
</link>

<link name="mx106_with_u_l_2">
<!-- Shapes for inner -->
<collision>
<origin xyz="-0.014914056614044417931 0.00049999999999998483158 -0.019949999999999995515" rpy="1.5707963267948976682 1.5707963267948950037 0" />
<geometry>
<box size="0.026999999999999999695 0.058000000000000002942 0.025999999999999998807" />
</geometry>
</collision>
<!-- Shapes for inner -->
<collision>
<origin xyz="-0.014914056614044702426 -0.00015000000000019338142 -0.079943749999999244582" rpy="-3.1415926535897922278 -3.7964109315971228825e-16 1.5707963267948954478" />
<geometry>
<box size="0.026999999999999999695 0.058000000000000002942 0.025999999999999998807" />
</geometry>
</collision>
<visual>
<origin xyz="0 0 0" rpy="0 -0 0" />
<geometry>
<mesh filename="package:///mx106_with_u_l_2_visual.stl"/>
</geometry>
<material name="mx106_with_u_l_2_material">
<color rgba="0.64705882352941179736 0.64705882352941179736 0.64705882352941179736 1.0"/>
</material>
</visual>
<inertial>
<origin xyz="-0.01579809130140210488 0.0024792715902648234695 -0.042417314664823596582" rpy="0 0 0"/>
<mass value="0.13646106366842530866" />
<inertia ixx="0.00012658119622731964422" ixy="-1.4099476186479759539e-06"  ixz="-7.3294705909758871149e-06" iyy="0.00015890241725417908838" iyz="-7.5761639989914923422e-06" izz="8.1610391256078316765e-05" />
</inertial>
</link>

<link name="thigh_horn_right">
<!-- Shapes for thigh_horn -->
<collision>
<origin xyz="1.9003476771990647301e-16 0.040000000000002616796 -0.043399999999981446475" rpy="-3.141592653589793116 1.7763568394003163346e-15 -1.4918621893408456738e-16" />
<geometry>
<box size="0.02999999999999999889 0.080000000000000001665 0.0030000000000000000625" />
</geometry>
</collision>
<!-- Shapes for inner -->
<collision>
<origin xyz="-0.0001500000000002436884 0.12485000000000420761 -0.016500000000020879909" rpy="3.2081522159913522029e-16 8.3266726847070545123e-16 6.2946161775837381903e-16" />
<geometry>
<box size="0.026999999999999999695 0.058000000000000002942 0.025999999999999998807" />
</geometry>
</collision>
<!-- Shapes for thigh_free_right -->
<collision>
<origin xyz="-7.0374261973352485148e-17 0.036000000000001516898 0.0053999999999999187539" rpy="-9.1335288072722800642e-16 2.1649348980208507012e-15 5.7259359355008947865e-30" />
<geometry>
<box size="0.02999999999999999889 0.080000000000000001665 0.0030000000000000000625" />
</geometry>
</collision>
<visual>
<origin xyz="0 0 0" rpy="0 -0 0" />
<geometry>
<mesh filename="package:///thigh_horn_right_visual.stl"/>
</geometry>
<material name="thigh_horn_right_material">
<color rgba="0.64705882352941179736 0.64705882352941179736 0.64705882352941179736 1.0"/>
</material>
</visual>
<inertial>
<origin xyz="-0.00010367327667696853502 0.086862730038295754564 -0.015690262434277596482" rpy="0 0 0"/>
<mass value="0.084554717205627710763" />
<inertia ixx="0.00032732886981105119555" ixy="4.6764730093353614228e-08"  ixz="-6.4174717795137690053e-09" iyy="3.6205556971791682023e-05" iyz="4.5673960792295022605e-05" izz="0.00030587649625741977072" />
</inertial>
</link>

<link name="tibia_right_full">
<!-- Shapes for tibia_right -->
<collision>
<origin xyz="-0.065000000000248372989 0.00050000000005403708037 0.0085000000000484427637" rpy="3.141592653589793116 -3.505123089511776538e-32 6.3179236144352576726e-31" />
<geometry>
<box size="0.14999999999999999445 0.035000000000000003331 0.0030000000000000000625" />
</geometry>
</collision>
<!-- Shapes for tibia_horn_side -->
<collision>
<origin xyz="-0.065000000000266552891 1.0764973240539433027e-14 -0.04350000000002792605" rpy="4.9460435747050723876e-14 -1.6975419599881278126e-13 3.1207827358612381235e-14" />
<geometry>
<box size="0.14999999999999999445 0.035000000000000003331 0.0030000000000000000625" />
</geometry>
</collision>
<visual>
<origin xyz="0 0 0" rpy="0 -0 0" />
<geometry>
<mesh filename="package:///tibia_right_full_visual.stl"/>
</geometry>
<material name="tibia_right_full_material">
<color rgba="0.5 0.5 0.5 1.0"/>
</material>
</visual>
<inertial>
<origin xyz="-0.070000001170571216069 -1.7599220944606213366e-13 -0.0013921737730080263173" rpy="0 0 0"/>
<mass value="0.050146782973123575633" />
<inertia ixx="1.6277029156049170752e-05" ixy="-2.4706620520861365731e-17"  ixz="1.2995770536366069853e-13" iyy="0.00026199625807307713992" iyz="-3.3311071770419292017e-16" izz="0.00024814461872111888245" />
</inertial>
</link>

<link name="mx106_with_u_r_2">
<!-- Shapes for inner -->
<collision>
<origin xyz="0.015149999999999622102 -0.00015000000000013960499 -0.016500000000000146494" rpy="8.0184747838330719239e-17 -1.1102230246244146167e-15 1.57079632679489678" />
<geometry>
<box size="0.026999999999999999695 0.058000000000000002942 0.025999999999999998807" />
</geometry>
</collision>
<!-- Shapes for inner -->
<collision>
<origin xyz="0.01514999999999963598 -0.059843750000000084377 -0.016150000000000122591" rpy="1.57079632679489678 -1.570796326794896558 0" />
<geometry>
<box size="0.026999999999999999695 0.058000000000000002942 0.025999999999999998807" />
</geometry>
</collision>
<visual>
<origin xyz="0 0 0" rpy="0 -0 0" />
<geometry>
<mesh filename="package:///mx106_with_u_r_2_visual.stl"/>
</geometry>
<material name="mx106_with_u_r_2_material">
<color rgba="0.64705882352941179736 0.64705882352941179736 0.64705882352941179736 1.0"/>
</material>
</visual>
<inertial>
<origin xyz="0.016034034687357368032 -0.022323551723118340018 -0.018485508662769063043" rpy="0 0 0"/>
<mass value="0.13646106366842530866" />
<inertia ixx="0.00012653897607754413523" ixy="7.3381179937609062526e-06"  ixz="-1.4013009140676505774e-06" iyy="8.1606165644483919289e-05" iyz="7.5459141585546997936e-06" izz="0.00015886442271599956252" />
</inertial>
</link>

<link name="right_foot_asm">
<!-- Shapes for cleat -->
<collision>
<origin xyz="0.052000000000000060063 -0.043500000000000059452 -0.075629999999999031335" rpy="1.5707963267948990005 -1.5113294060669746344 1.5707963267948847896" />
<geometry>
<cylinder length="0.016000000000000000333" radius="0.0080000000000000001665" />
</geometry>
</collision>
<!-- Shapes for cleat -->
<collision>
<origin xyz="0.05199999999999989353 -0.043499999999999781897 0.065970000000000861284" rpy="1.5707963267948990005 -1.5113294060669755225 1.5707963267949096586" />
<geometry>
<cylinder length="0.016000000000000000333" radius="0.0080000000000000001665" />
</geometry>
</collision>
<!-- Shapes for cleat -->
<collision>
<origin xyz="0.052000000000000067002 0.032500000000000077438 -0.075629999999999211746" rpy="1.5707963267948990005 -1.5113294060669755225 1.5707963267949260899" />
<geometry>
<cylinder length="0.016000000000000000333" radius="0.0080000000000000001665" />
</geometry>
</collision>
<!-- Shapes for cleat -->
<collision>
<origin xyz="0.051999999999999997613 0.032500000000000223155 0.065970000000000680873" rpy="1.5707963267948990005 -1.5113294060669761887 1.5707963267949103248" />
<geometry>
<cylinder length="0.016000000000000000333" radius="0.0080000000000000001665" />
</geometry>
</collision>
<!-- Shapes for foot_plate -->
<collision>
<origin xyz="0.041499999999999988287 -0.0054999999999997056452 -0.0048299999999991856392" rpy="-1.570796326794896558 -1.2796151809045244678e-29 1.5707963267948961139" />
<geometry>
<box size="0.091999999999999998446 0.1575999999999999901 0.0030000000000000000625" />
</geometry>
</collision>
<visual>
<origin xyz="0 0 0" rpy="0 -0 0" />
<geometry>
<mesh filename="package:///right_foot_asm_visual.stl"/>
</geometry>
<material name="right_foot_asm_material">
<color rgba="0.30196078431372547213 0.30077323167299724327 0.29800227551129809811 1.0"/>
</material>
</visual>
<inertial>
<origin xyz="0.031258906017488714835 -0.004143021908171709046 0.00081745218760271101417" rpy="0 0 0"/>
<mass value="0.32138977066764795598" />
<inertia ixx="0.0010224924474882507268" ixy="8.6971207758316878856e-06"  ixz="-2.1885686287244343878e-05" iyy="0.00086439986274518948711" iyz="1.0406619706265090542e-05" izz="0.00032657223482245013001" />
</inertial>
</link>

<link name="right_foot">
<inertial>
<origin xyz="0 0 0" rpy="0 0 0" />
<mass value="1e-9" />
<inertia ixx="0" ixy="0" ixz="0" iyy="0" iyz="0" izz="0" />
</inertial>
</link>
<joint name="right_foot_frame" type="fixed">
<origin xyz="0.059999999999999220623 2.9143354396410359186e-16 -0.02032999999999917512" rpy="-3.3006666615197048961e-16 -1.5707963267948956698 0" />
<parent link="right_foot_asm" />
<child link="right_foot" />
<axis xyz="0 0 0"/>
</joint>

<joint name="right_ankle_roll" type="revolute">
<origin xyz="-3.3306690738754696213e-16 0.020100000000000037975 -0.016000000000000163397" rpy="1.5707963267948956698 -3.9136528551464144388e-15 3.1415926535897922278" />
<parent link="mx106_with_u_r_2" />
<child link="right_foot_asm" />
<axis xyz="0 0 1"/>
<limit effort="10" velocity="6" />
<joint_properties friction="0.0"/>
</joint>

<joint name="right_ankle_pitch" type="revolute">
<origin xyz="-0.14000000000024503954 -1.5279444376403716888e-14 5.0570658771675880416e-14" rpy="-4.4408920984981649157e-16 -2.9422456746621798078e-15 3.0350301903487526264e-14" />
<parent link="tibia_right_full" />
<child link="mx106_with_u_r_2" />
<axis xyz="0 0 1"/>
<limit effort="10" velocity="6" />
<joint_properties friction="0.0"/>
</joint>

<joint name="right_knee" type="revolute">
<origin xyz="-1.1449174941446926823e-16 0.14000000000000401013 -2.057382042508493214e-14" rpy="1.2767564783171990634e-15 -1.5808749702337738819e-15 -1.5707963267948610309" />
<parent link="thigh_horn_right" />
<child link="tibia_right_full" />
<axis xyz="0 0 1"/>
<limit effort="10" velocity="6" />
<joint_properties friction="0.0"/>
</joint>

<joint name="right_hip_pitch" type="revolute">
<origin xyz="0.00023594338595563091321 -0.015999999999999979516 -0.020100000000000027567" rpy="1.5707963267948981123 -1.5707963267948947816 0" />
<parent link="mx106_with_u_l_2" />
<child link="thigh_horn_right" />
<axis xyz="0 0 1"/>
<limit effort="10" velocity="6" />
<joint_properties friction="0.0"/>
</joint>

<joint name="right_hip_roll" type="revolute">
<origin xyz="-2.3592239273284576484e-16 -0.020099054048956514068 -0.060400000000000696188" rpy="1.5707963267948976682 -1.5707963267948952257 0" />
<parent link="u_hip_with_saver_2" />
<child link="mx106_with_u_l_2" />
<axis xyz="0 0 1"/>
<limit effort="10" velocity="6" />
<joint_properties friction="0.0"/>
</joint>

<joint name="right_hip_yaw" type="revolute">
<origin xyz="0.0058689734943574000531 -0.046400000000004514022 -0.041099999999998734768" rpy="2.1625062851527426286e-14 -1.9816742826592979678e-15 1.5707963267948987784" />
<parent link="torso" />
<child link="u_hip_with_saver_2" />
<axis xyz="0 0 1"/>
<limit effort="10" velocity="6" />
<joint_properties friction="0.0"/>
</joint>

<link name="u_neck">
<!-- Shapes for u_base_64 -->
<collision>
<origin xyz="1.5777218104420236108e-30 0 0.0031250000000000001735" rpy="3.141592653589793116 3.1554436208840472216e-30 -5.542117549423108371e-31" />
<geometry>
<box size="0.049000000000000001887 0.02999999999999999889 0.0062500000000000003469" />
</geometry>
</collision>
<!-- Shapes for u_side_neck -->
<collision>
<origin xyz="0.025000000000002020606 -7.9593096814311157704e-16 0.03290104185101920542" rpy="1.570796326794881681 -1.4467593789647997428e-14 -1.5707963267949802688" />
<geometry>
<box size="0.02999999999999999889 0.065802000000000013258 0.0030000000000000000625" />
</geometry>
</collision>
<!-- Shapes for u_side_neck -->
<collision>
<origin xyz="-0.025000000000002336326 -1.3773524799408755992e-16 0.032901041851018816842" rpy="1.5707963267949118791 1.4467593789647997428e-14 1.5707963267948130692" />
<geometry>
<box size="0.02999999999999999889 0.065802000000000013258 0.0030000000000000000625" />
</geometry>
</collision>
<visual>
<origin xyz="0 0 0" rpy="0 -0 0" />
<geometry>
<mesh filename="package:///u_neck_visual.stl"/>
</geometry>
<material name="u_neck_material">
<color rgba="0.30196078431372547213 0.30196078431372547213 0.30196078431372547213 1.0"/>
</material>
</visual>
<inertial>
<origin xyz="-5.8054823695327929249e-17 -2.34706914436173141e-16 0.020633402679854664225" rpy="0 0 0"/>
<mass value="0.054479900613359215356" />
<inertia ixx="3.0578702573706214457e-05" ixy="-1.3594422435499718083e-11"  ixz="-2.2663425294972873447e-19" iyy="5.1695196768451778021e-05" iyz="3.5165102200854312514e-20" izz="2.9852490907294667726e-05" />
</inertial>
</link>

<link name="head__field_of_view_false">
<!-- Shapes for mx-64at_ar -->
<collision>
<origin xyz="-1.4558606275431786865e-16 -0.017549999999999899014 -0.02350000000001051248" rpy="-8.2131769560499658099e-16 4.4470048528371167449e-15 -9.334017546113301853e-15" />
<geometry>
<box size="0.040199999999999999623 0.061100000000000001532 0.041000000000000001721" />
</geometry>
</collision>
<!-- Shapes for head_plate -->
<collision>
<origin xyz="-0.023799999999999925382 0.036500000000000518141 -0.042000000000010771772" rpy="-3.141592653589793116 -4.4470048528371364665e-15 3.1415926535897837901" />
<geometry>
<cylinder length="0.0030000000000000000625" radius="0.023500000000000000056" />
</geometry>
</collision>
<collision>
<origin xyz="0.0099999999999994954036 0.036500000000000198952 -0.042000000000010924428" rpy="-3.141592653589793116 -4.4470048528371364665e-15 3.1415926535897837901" />
<geometry>
<box size="0.061600000000000001976 0.047000000000000000111 0.0030000000000000000625" />
</geometry>
</collision>
<!-- Shapes for head_plate -->
<collision>
<origin xyz="-0.023800000000009903511 0.036500000000010454637 -0.0050000000000000772993" rpy="-3.141592653589793116 -4.4470048528371096452e-15 3.1415926535897837901" />
<geometry>
<cylinder length="0.0030000000000000000625" radius="0.023500000000000000056" />
</geometry>
</collision>
<collision>
<origin xyz="0.0099999999999895346214 0.036500000000010142387 -0.0050000000000002273529" rpy="-3.141592653589793116 -4.4470048528371096452e-15 3.1415926535897837901" />
<geometry>
<box size="0.061600000000000001976 0.047000000000000000111 0.0030000000000000000625" />
</geometry>
</collision>
<visual>
<origin xyz="0 0 0" rpy="0 -0 0" />
<geometry>
<mesh filename="package:///head__field_of_view_false_visual.stl"/>
</geometry>
<material name="head__field_of_view_false_material">
<color rgba="0.28125299738283077167 0.27711235229450581485 0.26469041702953099993 1.0"/>
</material>
</visual>
<inertial>
<origin xyz="-0.001030035465120174255 0.0021294117325469379305 -0.022097835096361564261" rpy="0 0 0"/>
<mass value="0.22740577538449363582" />
<inertia ixx="0.00021508425454754194223" ixy="1.0807486480164808418e-05"  ixz="3.0361594707869092588e-07" iyy="8.2015204757479777007e-05" iyz="4.1996875137778825728e-06" izz="0.00021574975376810137271" />
</inertial>
</link>

<link name="camera">
<inertial>
<origin xyz="0 0 0" rpy="0 0 0" />
<mass value="1e-9" />
<inertia ixx="0" ixy="0" ixz="0" iyy="0" iyz="0" izz="0" />
</inertial>
</link>
<joint name="camera_frame" type="fixed">
<origin xyz="-0.02493300000402396549 0.033500000000056068261 -0.023500000000011109225" rpy="-3.1415926535897855665 1.5707963267948905628 0" />
<parent link="head__field_of_view_false" />
<child link="camera" />
<axis xyz="0 0 0"/>
</joint>

<joint name="head_pitch" type="revolute">
<origin xyz="-0.023500000000001953354 1.0408340855860842566e-16 0.058302041851018782115" rpy="1.570796326794881459 -9.3340175461126013445e-15 -1.5707963267949771602" />
<parent link="u_neck" />
<child link="head__field_of_view_false" />
<axis xyz="0 0 1"/>
<limit effort="10" velocity="6" />
<joint_properties friction="0.0"/>
</joint>

<joint name="head_yaw" type="revolute">
<origin xyz="0.035868973494361661158 2.8796409701214989879e-15 0.15950000000001055001" rpy="1.0059319781662864725e-14 2.2541937107368225271e-14 -1.570796326795006026" />
<parent link="torso" />
<child link="u_neck" />
<axis xyz="0 0 1"/>
<limit effort="10" velocity="6" />
<joint_properties friction="0.0"/>
</joint>


</robot>
