<robot name="onshape">
<link name="torso">
<!-- Shapes for x_plate -->
<collision>
<origin xyz="0.057869 3.81527e-15 0.0595" rpy="1.5708 -3.71254e-15 1.5708" />
<geometry>
<box size="0.133 0.113 0.006" />
</geometry>
</collision>
<!-- Shapes for x_plate -->
<visual>
<origin xyz="0.057869 3.81527e-15 0.0595" rpy="1.5708 -3.71254e-15 1.5708" />
<geometry>
<box size="0.133 0.113 0.006" />
</geometry>
<material name="x_plate_material">
<color rgba="0.262745 0.282353 0.301961 1.0"/>
</material>
</visual>
<!-- Shapes for mx-64at_ar -->
<collision>
<origin xyz="0.023419 -0.0464 -0.017" rpy="-3.14159 2.03946e-15 -1.5708" />
<geometry>
<box size="0.0402 0.0611 0.041" />
</geometry>
</collision>
<!-- Shapes for mx-64at_ar -->
<visual>
<origin xyz="0.023419 -0.0464 -0.017" rpy="-3.14159 2.03946e-15 -1.5708" />
<geometry>
<box size="0.0402 0.0611 0.041" />
</geometry>
<material name="mx-64at_ar_material">
<color rgba="0.168627 0.168627 0.168627 1.0"/>
</material>
</visual>
<!-- Shapes for mx-64at_ar -->
<collision>
<origin xyz="0.013319 0.056 0.143" rpy="-1.5708 -1.5708 0" />
<geometry>
<box size="0.0402 0.0611 0.041" />
</geometry>
</collision>
<!-- Shapes for mx-64at_ar -->
<visual>
<origin xyz="0.013319 0.056 0.143" rpy="-1.5708 -1.5708 0" />
<geometry>
<box size="0.0402 0.0611 0.041" />
</geometry>
<material name="mx-64at_ar_material">
<color rgba="0.168627 0.168627 0.168627 1.0"/>
</material>
</visual>
<!-- Shapes for x_plate -->
<collision>
<origin xyz="-0.057131 7.78087e-15 0.0595" rpy="1.5708 -1.21571e-15 1.5708" />
<geometry>
<box size="0.133 0.113 0.006" />
</geometry>
</collision>
<!-- Shapes for x_plate -->
<visual>
<origin xyz="-0.057131 7.78087e-15 0.0595" rpy="1.5708 -1.21571e-15 1.5708" />
<geometry>
<box size="0.133 0.113 0.006" />
</geometry>
<material name="x_plate_material">
<color rgba="0.262745 0.282353 0.301961 1.0"/>
</material>
</visual>
<!-- Shapes for mx-64at_ar -->
<collision>
<origin xyz="0.023419 0.0464 -0.017" rpy="-3.14159 2.02561e-15 -1.5708" />
<geometry>
<box size="0.0402 0.0611 0.041" />
</geometry>
</collision>
<!-- Shapes for mx-64at_ar -->
<visual>
<origin xyz="0.023419 0.0464 -0.017" rpy="-3.14159 2.02561e-15 -1.5708" />
<geometry>
<box size="0.0402 0.0611 0.041" />
</geometry>
<material name="mx-64at_ar_material">
<color rgba="0.168627 0.168627 0.168627 1.0"/>
</material>
</visual>
<!-- Shapes for mx-64at_ar -->
<collision>
<origin xyz="0.018319 5.20694e-15 0.136" rpy="4.02456e-16 1.06347e-14 -1.5708" />
<geometry>
<box size="0.0402 0.0611 0.041" />
</geometry>
</collision>
<!-- Shapes for mx-64at_ar -->
<visual>
<origin xyz="0.018319 5.20694e-15 0.136" rpy="4.02456e-16 1.06347e-14 -1.5708" />
<geometry>
<box size="0.0402 0.0611 0.041" />
</geometry>
<material name="mx-64at_ar_material">
<color rgba="0.168627 0.168627 0.168627 1.0"/>
</material>
</visual>
<!-- Shapes for mx-64at_ar -->
<collision>
<origin xyz="0.013319 -0.056 0.143" rpy="1.5708 1.5708 0" />
<geometry>
<box size="0.0402 0.0611 0.041" />
</geometry>
</collision>
<!-- Shapes for mx-64at_ar -->
<visual>
<origin xyz="0.013319 -0.056 0.143" rpy="1.5708 1.5708 0" />
<geometry>
<box size="0.0402 0.0611 0.041" />
</geometry>
<material name="mx-64at_ar_material">
<color rgba="0.168627 0.168627 0.168627 1.0"/>
</material>
</visual>
<inertial>
<origin xyz="-0.00999148 0.0067075 0.0847028" rpy="0 0 0"/>
<mass value="1.74256" />
<inertia ixx="0.0256992" ixy="0.00212058"  ixz="0.00444597" iyy="0.0280135" iyz="-0.00204502" izz="0.0103838" />
</inertial>
</link>

<link name="head_base">
<inertial>
<origin xyz="0 0 0" rpy="0 0 0" />
<mass value="1e-9" />
<inertia ixx="0" ixy="0" ixz="0" iyy="0" iyz="0" izz="0" />
</inertial>
</link>
<joint name="head_base_frame" type="fixed">
<origin xyz="0.035869 2.87859e-15 0.1595" rpy="3.79641e-14 -9.95037e-15 -1.04223e-13" />
<parent link="torso" />
<child link="head_base" />
<axis xyz="0 0 0"/>
</joint>

<link name="trunk">
<inertial>
<origin xyz="0 0 0" rpy="0 0 0" />
<mass value="1e-9" />
<inertia ixx="0" ixy="0" ixz="0" iyy="0" iyz="0" izz="0" />
</inertial>
</link>
<joint name="trunk_frame" type="fixed">
<origin xyz="0.00586803 -3.58583e-15 -0.1015" rpy="-2.22624e-15 4.13778e-27 -1.14065e-13" />
<parent link="torso" />
<child link="trunk" />
<axis xyz="0 0 0"/>
</joint>

<link name="u_shoulder">
<!-- Shapes for u_base_64 -->
<collision>
<origin xyz="-2.13528e-33 -3.58215e-33 -0.003125" rpy="-1.13995e-30 1.27353e-30 1.29422e-30" />
<geometry>
<box size="0.049 0.03 0.00625" />
</geometry>
</collision>
<!-- Shapes for u_base_64 -->
<visual>
<origin xyz="-2.13528e-33 -3.58215e-33 -0.003125" rpy="-1.13995e-30 1.27353e-30 1.29422e-30" />
<geometry>
<box size="0.049 0.03 0.00625" />
</geometry>
<material name="u_base_64_material">
<color rgba="0.301961 0.301961 0.301961 1.0"/>
</material>
</visual>
<inertial>
<origin xyz="-1.42778e-15 -0.00566234 -0.0159676" rpy="0 0 0"/>
<mass value="0.0570101" />
<inertia ixx="2.21758e-05" ixy="-2.10263e-19"  ixz="9.28639e-19" iyy="4.03314e-05" iyz="-6.10703e-06" izz="3.58629e-05" />
</inertial>
</link>

<link name="right_humerus">
<!-- Shapes for mx-64at_ar -->
<collision>
<origin xyz="1.54658e-17 -0.01755 -0.0235" rpy="-8.07063e-16 -5.18375e-30 -4.64906e-16" />
<geometry>
<box size="0.0402 0.0611 0.041" />
</geometry>
</collision>
<!-- Shapes for mx-64at_ar -->
<visual>
<origin xyz="1.54658e-17 -0.01755 -0.0235" rpy="-8.07063e-16 -5.18375e-30 -4.64906e-16" />
<geometry>
<box size="0.0402 0.0611 0.041" />
</geometry>
<material name="mx-64at_ar_material">
<color rgba="0.168627 0.168627 0.168627 1.0"/>
</material>
</visual>
<inertial>
<origin xyz="-0.0219502 0.0714677 -0.0108756" rpy="0 0 0"/>
<mass value="0.111948" />
<inertia ixx="0.0132959" ixy="0.00182099"  ixz="0.000176202" iyy="0.000422449" iyz="-0.00129199" izz="0.0134217" />
</inertial>
</link>

<link name="radius_v2">
<!-- Shapes for hand -->
<collision>
<origin xyz="-2.76384e-17 0.1276 0.042" rpy="3.14159 4.25254e-16 1.5708" />
<geometry>
<cylinder length="0.003" radius="0.04" />
</geometry>
</collision>
<collision>
<origin xyz="-1.12905e-17 0.0539756 0.042" rpy="3.14159 4.25254e-16 1.5708" />
<geometry>
<box size="0.0775512 0.0412 0.003" />
</geometry>
</collision>
<!-- Shapes for hand -->
<visual>
<origin xyz="-2.76384e-17 0.1276 0.042" rpy="3.14159 4.25254e-16 1.5708" />
<geometry>
<cylinder length="0.003" radius="0.04" />
</geometry>
<material name="hand_material">
<color rgba="0.301961 0.301961 0.301961 1.0"/>
</material>
</visual>
<visual>
<origin xyz="-1.12905e-17 0.0539756 0.042" rpy="3.14159 4.25254e-16 1.5708" />
<geometry>
<box size="0.0775512 0.0412 0.003" />
</geometry>
<material name="hand_material">
<color rgba="0.301961 0.301961 0.301961 1.0"/>
</material>
</visual>
<!-- Shapes for hand -->
<collision>
<origin xyz="-1.24846e-16 0.1276 0.005" rpy="3.14159 4.25254e-16 1.5708" />
<geometry>
<cylinder length="0.003" radius="0.04" />
</geometry>
</collision>
<collision>
<origin xyz="-1.28933e-16 0.0539756 0.005" rpy="3.14159 4.25254e-16 1.5708" />
<geometry>
<box size="0.0775512 0.0412 0.003" />
</geometry>
</collision>
<!-- Shapes for hand -->
<visual>
<origin xyz="-1.24846e-16 0.1276 0.005" rpy="3.14159 4.25254e-16 1.5708" />
<geometry>
<cylinder length="0.003" radius="0.04" />
</geometry>
<material name="hand_material">
<color rgba="0.301961 0.301961 0.301961 1.0"/>
</material>
</visual>
<visual>
<origin xyz="-1.28933e-16 0.0539756 0.005" rpy="3.14159 4.25254e-16 1.5708" />
<geometry>
<box size="0.0775512 0.0412 0.003" />
</geometry>
<material name="hand_material">
<color rgba="0.301961 0.301961 0.301961 1.0"/>
</material>
</visual>
<!-- Shapes for mx-64at_ar -->
<collision>
<origin xyz="-2.92266e-18 0.01755 0.0235" rpy="3.14159 -1.27021e-30 5.55112e-17" />
<geometry>
<box size="0.0402 0.0611 0.041" />
</geometry>
</collision>
<!-- Shapes for mx-64at_ar -->
<visual>
<origin xyz="-2.92266e-18 0.01755 0.0235" rpy="3.14159 -1.27021e-30 5.55112e-17" />
<geometry>
<box size="0.0402 0.0611 0.041" />
</geometry>
<material name="mx-64at_ar_material">
<color rgba="0.168627 0.168627 0.168627 1.0"/>
</material>
</visual>
<inertial>
<origin xyz="-0.0615379 -0.10265 0.0219354" rpy="0 0 0"/>
<mass value="0.120619" />
<inertia ixx="0.0207428" ixy="-0.00638349"  ixz="-2.1871e-05" iyy="0.00208063" iyz="-7.96366e-05" izz="0.022758" />
</inertial>
</link>

<joint name="right_elbow" type="revolute">
<origin xyz="-0.0235 -0.142 -0.0025" rpy="3.14159 -1.5708 0" />
<parent link="right_humerus" />
<child link="radius_v2" />
<axis xyz="0 0 1"/>
<limit effort="10" velocity="6" lower="-2.79253" upper="-0"/>
<joint_properties friction="0.0"/>
</joint>

<joint name="right_shoulder_roll" type="revolute">
<origin xyz="-0.0235 -0.03 -0.035" rpy="-3.58863e-16 -1.5708 0" />
<parent link="u_shoulder" />
<child link="right_humerus" />
<axis xyz="0 0 1"/>
<limit effort="10" velocity="6" lower="-1.5708" upper="0.0872665"/>
<joint_properties friction="0.0"/>
</joint>

<joint name="right_shoulder_pitch" type="revolute">
<origin xyz="0.030869 -0.0795 0.143" rpy="1.5708 -1.84019e-14 3.14159" />
<parent link="torso" />
<child link="u_shoulder" />
<axis xyz="0 0 1"/>
<limit effort="10" velocity="6" lower="-2.18166" upper="2.18166"/>
<joint_properties friction="0.0"/>
</joint>

<link name="u_shoulder_2">
<!-- Shapes for u_base_64 -->
<collision>
<origin xyz="-4.32799e-34 1.44897e-33 0.003125" rpy="3.14159 1.38496e-31 3.69779e-31" />
<geometry>
<box size="0.049 0.03 0.00625" />
</geometry>
</collision>
<!-- Shapes for u_base_64 -->
<visual>
<origin xyz="-4.32799e-34 1.44897e-33 0.003125" rpy="3.14159 1.38496e-31 3.69779e-31" />
<geometry>
<box size="0.049 0.03 0.00625" />
</geometry>
<material name="u_base_64_material">
<color rgba="0.301961 0.301961 0.301961 1.0"/>
</material>
</visual>
<inertial>
<origin xyz="-5.66222e-16 0.00566234 0.0159676" rpy="0 0 0"/>
<mass value="0.0570101" />
<inertia ixx="2.21758e-05" ixy="1.13873e-19"  ixz="3.1237e-19" iyy="4.03314e-05" iyz="-6.10703e-06" izz="3.58629e-05" />
</inertial>
</link>

<link name="left_humerus">
<!-- Shapes for mx-64at_ar -->
<collision>
<origin xyz="6.81954e-18 -0.01755 -0.0235" rpy="6.15036e-16 1.39816e-29 1.05471e-15" />
<geometry>
<box size="0.0402 0.0611 0.041" />
</geometry>
</collision>
<!-- Shapes for mx-64at_ar -->
<visual>
<origin xyz="6.81954e-18 -0.01755 -0.0235" rpy="6.15036e-16 1.39816e-29 1.05471e-15" />
<geometry>
<box size="0.0402 0.0611 0.041" />
</geometry>
<material name="mx-64at_ar_material">
<color rgba="0.168627 0.168627 0.168627 1.0"/>
</material>
</visual>
<inertial>
<origin xyz="-0.0663577 0.040272 -0.0134765" rpy="0 0 0"/>
<mass value="0.111948" />
<inertia ixx="0.00896033" ixy="0.00398528"  ixz="0.00041087" iyy="0.00197497" iyz="-0.000899791" izz="0.0107095" />
</inertial>
</link>

<link name="radius_v2_2">
<!-- Shapes for mx-64at_ar -->
<collision>
<origin xyz="-3.89688e-18 -0.01755 -0.0235" rpy="-7.99013e-17 1.14505e-16 1.11022e-16" />
<geometry>
<box size="0.0402 0.0611 0.041" />
</geometry>
</collision>
<!-- Shapes for mx-64at_ar -->
<visual>
<origin xyz="-3.89688e-18 -0.01755 -0.0235" rpy="-7.99013e-17 1.14505e-16 1.11022e-16" />
<geometry>
<box size="0.0402 0.0611 0.041" />
</geometry>
<material name="mx-64at_ar_material">
<color rgba="0.168627 0.168627 0.168627 1.0"/>
</material>
</visual>
<!-- Shapes for hand -->
<collision>
<origin xyz="2.08452e-16 -0.1276 -0.005" rpy="-3.51984e-16 -7.99013e-17 -1.5708" />
<geometry>
<cylinder length="0.003" radius="0.04" />
</geometry>
</collision>
<collision>
<origin xyz="2.248e-16 -0.0539756 -0.005" rpy="-3.51984e-16 -7.99013e-17 -1.5708" />
<geometry>
<box size="0.0775512 0.0412 0.003" />
</geometry>
</collision>
<!-- Shapes for hand -->
<visual>
<origin xyz="2.08452e-16 -0.1276 -0.005" rpy="-3.51984e-16 -7.99013e-17 -1.5708" />
<geometry>
<cylinder length="0.003" radius="0.04" />
</geometry>
<material name="hand_material">
<color rgba="0.301961 0.301961 0.301961 1.0"/>
</material>
</visual>
<visual>
<origin xyz="2.248e-16 -0.0539756 -0.005" rpy="-3.51984e-16 -7.99013e-17 -1.5708" />
<geometry>
<box size="0.0775512 0.0412 0.003" />
</geometry>
<material name="hand_material">
<color rgba="0.301961 0.301961 0.301961 1.0"/>
</material>
</visual>
<!-- Shapes for hand -->
<collision>
<origin xyz="-2.91138e-16 -0.1276 -0.042" rpy="-1.42185e-16 -7.99013e-17 -1.5708" />
<geometry>
<cylinder length="0.003" radius="0.04" />
</geometry>
</collision>
<collision>
<origin xyz="-2.87051e-16 -0.0539756 -0.042" rpy="-1.42185e-16 -7.99013e-17 -1.5708" />
<geometry>
<box size="0.0775512 0.0412 0.003" />
</geometry>
</collision>
<!-- Shapes for hand -->
<visual>
<origin xyz="-2.91138e-16 -0.1276 -0.042" rpy="-1.42185e-16 -7.99013e-17 -1.5708" />
<geometry>
<cylinder length="0.003" radius="0.04" />
</geometry>
<material name="hand_material">
<color rgba="0.301961 0.301961 0.301961 1.0"/>
</material>
</visual>
<visual>
<origin xyz="-2.87051e-16 -0.0539756 -0.042" rpy="-1.42185e-16 -7.99013e-17 -1.5708" />
<geometry>
<box size="0.0775512 0.0412 0.003" />
</geometry>
<material name="hand_material">
<color rgba="0.301961 0.301961 0.301961 1.0"/>
</material>
</visual>
<inertial>
<origin xyz="0.0776041 0.104341 -0.0531645" rpy="0 0 0"/>
<mass value="0.120619" />
<inertia ixx="0.021585" ixy="-0.00811906"  ixz="0.00124466" iyy="0.0037442" iyz="0.00318708" izz="0.0242843" />
</inertial>
</link>

<joint name="left_elbow" type="revolute">
<origin xyz="0.0235 -0.142 -0.0025" rpy="1.63031e-15 1.5708 0" />
<parent link="left_humerus" />
<child link="radius_v2_2" />
<axis xyz="0 0 1"/>
<limit effort="10" velocity="6" lower="-2.79253" upper="0"/>
<joint_properties friction="0.0"/>
</joint>

<joint name="left_shoulder_roll" type="revolute">
<origin xyz="0.0235 0.03 0.035" rpy="-3.14159 -1.5708 0" />
<parent link="u_shoulder_2" />
<child link="left_humerus" />
<axis xyz="0 0 1"/>
<limit effort="10" velocity="6" lower="-0.0872665" upper="1.5708"/>
<joint_properties friction="0.0"/>
</joint>

<joint name="left_shoulder_pitch" type="revolute">
<origin xyz="0.030869 0.0795 0.143" rpy="-1.5708 -7.21645e-15 2.48831e-15" />
<parent link="torso" />
<child link="u_shoulder_2" />
<axis xyz="0 0 1"/>
<limit effort="10" velocity="6" lower="-2.18166" upper="2.18166"/>
<joint_properties friction="0.0"/>
</joint>

<link name="u_hip_with_saver">
<inertial>
<origin xyz="-6.06621e-11 0.00126178 -0.0329138" rpy="0 0 0"/>
<mass value="0.136031" />
<inertia ixx="0.000121591" ixy="4.65787e-14"  ixz="1.94175e-13" iyy="7.55159e-05" iyz="7.1306e-07" izz="5.66884e-05" />
</inertial>
</link>

<link name="mx106_with_u_r">
<!-- Shapes for inner -->
<collision>
<origin xyz="-0.01515 -0.00015 -0.0799438" rpy="-3.14159 2.16493e-15 1.5708" />
<geometry>
<box size="0.027 0.058 0.026" />
</geometry>
</collision>
<!-- Shapes for inner -->
<visual>
<origin xyz="-0.01515 -0.00015 -0.0799438" rpy="-3.14159 2.16493e-15 1.5708" />
<geometry>
<box size="0.027 0.058 0.026" />
</geometry>
<material name="inner_material">
<color rgba="0.647059 0.647059 0.647059 1.0"/>
</material>
</visual>
<!-- Shapes for inner -->
<collision>
<origin xyz="-0.01515 -0.0005 -0.02025" rpy="-1.5708 -1.5708 0" />
<geometry>
<box size="0.027 0.058 0.026" />
</geometry>
</collision>
<!-- Shapes for inner -->
<visual>
<origin xyz="-0.01515 -0.0005 -0.02025" rpy="-1.5708 -1.5708 0" />
<geometry>
<box size="0.027 0.058 0.026" />
</geometry>
<material name="inner_material">
<color rgba="0.647059 0.647059 0.647059 1.0"/>
</material>
</visual>
<inertial>
<origin xyz="-0.016034 -0.00248551 -0.0424236" rpy="0 0 0"/>
<mass value="0.136461" />
<inertia ixx="0.000126539" ixy="1.4013e-06"  ixz="-7.33812e-06" iyy="0.000158864" iyz="7.54591e-06" izz="8.16062e-05" />
</inertial>
</link>

<link name="thigh_horn_left">
<!-- Shapes for thigh_free_left -->
<collision>
<origin xyz="-1.15245e-16 0.04 -0.0054" rpy="3.14159 -1.37092e-29 -5.71942e-19" />
<geometry>
<box size="0.03 0.08 0.003" />
</geometry>
</collision>
<!-- Shapes for thigh_free_left -->
<visual>
<origin xyz="-1.15245e-16 0.04 -0.0054" rpy="3.14159 -1.37092e-29 -5.71942e-19" />
<geometry>
<box size="0.03 0.08 0.003" />
</geometry>
<material name="thigh_free_left_material">
<color rgba="0.615686 0.811765 0.929412 1.0"/>
</material>
</visual>
<!-- Shapes for thigh_horn -->
<collision>
<origin xyz="1.75621e-16 0.04 0.0436" rpy="3.14159 -1.39398e-29 -5.74647e-19" />
<geometry>
<box size="0.03 0.08 0.003" />
</geometry>
</collision>
<!-- Shapes for thigh_horn -->
<visual>
<origin xyz="1.75621e-16 0.04 0.0436" rpy="3.14159 -1.39398e-29 -5.74647e-19" />
<geometry>
<box size="0.03 0.08 0.003" />
</geometry>
<material name="thigh_horn_material">
<color rgba="0.615686 0.811765 0.929412 1.0"/>
</material>
</visual>
<!-- Shapes for inner -->
<collision>
<origin xyz="0.00015 0.12485 0.0165" rpy="-3.14159 2.0529e-15 -3.14159" />
<geometry>
<box size="0.027 0.058 0.026" />
</geometry>
</collision>
<!-- Shapes for inner -->
<visual>
<origin xyz="0.00015 0.12485 0.0165" rpy="-3.14159 2.0529e-15 -3.14159" />
<geometry>
<box size="0.027 0.058 0.026" />
</geometry>
<material name="inner_material">
<color rgba="0.647059 0.647059 0.647059 1.0"/>
</material>
</visual>
<inertial>
<origin xyz="-9.36074e-05 0.0868627 0.0156903" rpy="0 0 0"/>
<mass value="0.0845547" />
<inertia ixx="0.000327329" ixy="2.3833e-08"  ixz="-1.25073e-09" iyy="3.62057e-05" iyz="-4.5674e-05" izz="0.000305877" />
</inertial>
</link>

<link name="tibia_left_full">
<!-- Shapes for tibia_horn_side -->
<collision>
<origin xyz="-0.065 1.52525e-14 0.0435" rpy="-1.249e-14 1.99003e-14 -5.7303e-14" />
<geometry>
<box size="0.15 0.035 0.003" />
</geometry>
</collision>
<!-- Shapes for tibia_horn_side -->
<visual>
<origin xyz="-0.065 1.52525e-14 0.0435" rpy="-1.249e-14 1.99003e-14 -5.7303e-14" />
<geometry>
<box size="0.15 0.035 0.003" />
</geometry>
<material name="tibia_horn_side_material">
<color rgba="0.615686 0.811765 0.929412 1.0"/>
</material>
</visual>
<!-- Shapes for tibia_left -->
<collision>
<origin xyz="-0.065 -0.0025 -0.0085" rpy="9.56646e-30 -1.52821e-30 -1.07717e-18" />
<geometry>
<box size="0.15 0.035 0.003" />
</geometry>
</collision>
<!-- Shapes for tibia_left -->
<visual>
<origin xyz="-0.065 -0.0025 -0.0085" rpy="9.56646e-30 -1.52821e-30 -1.07717e-18" />
<geometry>
<box size="0.15 0.035 0.003" />
</geometry>
<material name="tibia_left_material">
<color rgba="0.615686 0.811765 0.929412 1.0"/>
</material>
</visual>
<inertial>
<origin xyz="-0.07 1.75919e-13 0.00139217" rpy="0 0 0"/>
<mass value="0.0501468" />
<inertia ixx="1.6277e-05" ixy="1.474e-17"  ixz="-1.29865e-13" iyy="0.000261996" iyz="-3.38442e-16" izz="0.000248145" />
</inertial>
</link>

<link name="mx106_with_u_l">
<!-- Shapes for inner -->
<collision>
<origin xyz="0.01515 -0.0598438 0.01585" rpy="1.5708 -1.5708 0" />
<geometry>
<box size="0.027 0.058 0.026" />
</geometry>
</collision>
<!-- Shapes for inner -->
<visual>
<origin xyz="0.01515 -0.0598438 0.01585" rpy="1.5708 -1.5708 0" />
<geometry>
<box size="0.027 0.058 0.026" />
</geometry>
<material name="inner_material">
<color rgba="0.647059 0.647059 0.647059 1.0"/>
</material>
</visual>
<!-- Shapes for inner -->
<collision>
<origin xyz="0.01515 0.00015 0.0165" rpy="-3.14159 3.27516e-15 -1.5708" />
<geometry>
<box size="0.027 0.058 0.026" />
</geometry>
</collision>
<!-- Shapes for inner -->
<visual>
<origin xyz="0.01515 0.00015 0.0165" rpy="-3.14159 3.27516e-15 -1.5708" />
<geometry>
<box size="0.027 0.058 0.026" />
</geometry>
<material name="inner_material">
<color rgba="0.647059 0.647059 0.647059 1.0"/>
</material>
</visual>
<inertial>
<origin xyz="0.016034 -0.0223173 0.0184793" rpy="0 0 0"/>
<mass value="0.136461" />
<inertia ixx="0.000126581" ixy="7.32947e-06"  ixz="1.40995e-06" iyy="8.16104e-05" iyz="-7.57616e-06" izz="0.000158902" />
</inertial>
</link>

<link name="left_foot_asm">
<!-- Shapes for cleat -->
<collision>
<origin xyz="0.052 -0.0325 -0.07563" rpy="-1.5708 -1.13409 -1.5708" />
<geometry>
<cylinder length="0.016" radius="0.008" />
</geometry>
</collision>
<!-- Shapes for cleat -->
<visual>
<origin xyz="0.052 -0.0325 -0.07563" rpy="-1.5708 -1.13409 -1.5708" />
<geometry>
<cylinder length="0.016" radius="0.008" />
</geometry>
<material name="cleat_material">
<color rgba="0.301961 0.290196 0.262745 1.0"/>
</material>
</visual>
<!-- Shapes for cleat -->
<collision>
<origin xyz="0.052 0.0435 0.06597" rpy="-1.5708 -1.13468 -1.5708" />
<geometry>
<cylinder length="0.016" radius="0.008" />
</geometry>
</collision>
<!-- Shapes for cleat -->
<visual>
<origin xyz="0.052 0.0435 0.06597" rpy="-1.5708 -1.13468 -1.5708" />
<geometry>
<cylinder length="0.016" radius="0.008" />
</geometry>
<material name="cleat_material">
<color rgba="0.301961 0.290196 0.262745 1.0"/>
</material>
</visual>
<!-- Shapes for cleat -->
<collision>
<origin xyz="0.052 -0.0325 0.06597" rpy="-1.5708 -1.13409 -1.5708" />
<geometry>
<cylinder length="0.016" radius="0.008" />
</geometry>
</collision>
<!-- Shapes for cleat -->
<visual>
<origin xyz="0.052 -0.0325 0.06597" rpy="-1.5708 -1.13409 -1.5708" />
<geometry>
<cylinder length="0.016" radius="0.008" />
</geometry>
<material name="cleat_material">
<color rgba="0.301961 0.290196 0.262745 1.0"/>
</material>
</visual>
<!-- Shapes for cleat -->
<collision>
<origin xyz="0.052 0.0435 -0.07563" rpy="-1.5708 -1.13409 -1.5708" />
<geometry>
<cylinder length="0.016" radius="0.008" />
</geometry>
</collision>
<!-- Shapes for cleat -->
<visual>
<origin xyz="0.052 0.0435 -0.07563" rpy="-1.5708 -1.13409 -1.5708" />
<geometry>
<cylinder length="0.016" radius="0.008" />
</geometry>
<material name="cleat_material">
<color rgba="0.301961 0.290196 0.262745 1.0"/>
</material>
</visual>
<!-- Shapes for foot_plate -->
<collision>
<origin xyz="0.0415 0.0055 -0.00483" rpy="-1.5708 -8.96762e-20 1.5708" />
<geometry>
<box size="0.092 0.1576 0.003" />
</geometry>
</collision>
<!-- Shapes for foot_plate -->
<visual>
<origin xyz="0.0415 0.0055 -0.00483" rpy="-1.5708 -8.96762e-20 1.5708" />
<geometry>
<box size="0.092 0.1576 0.003" />
</geometry>
<material name="foot_plate_material">
<color rgba="0.301961 0.301961 0.301961 1.0"/>
</material>
</visual>
<inertial>
<origin xyz="0.0312589 0.00414298 0.000817452" rpy="0 0 0"/>
<mass value="0.32139" />
<inertia ixx="0.00102249" ixy="-8.69674e-06"  ixz="-2.18857e-05" iyy="0.0008644" iyz="-1.04075e-05" izz="0.000326573" />
</inertial>
</link>

<link name="left_foot">
<inertial>
<origin xyz="0 0 0" rpy="0 0 0" />
<mass value="1e-9" />
<inertia ixx="0" ixy="0" ixz="0" iyy="0" iyz="0" izz="0" />
</inertial>
</link>
<joint name="left_foot_frame" type="fixed">
<origin xyz="0.06 6.45317e-16 -0.02033" rpy="8.38389e-16 -1.5708 0" />
<parent link="left_foot_asm" />
<child link="left_foot" />
<axis xyz="0 0 0"/>
</joint>

<joint name="left_ankle_roll" type="revolute">
<origin xyz="-2.22045e-16 0.0201 0.016" rpy="1.5708 7.53536e-19 3.14159" />
<parent link="mx106_with_u_l" />
<child link="left_foot_asm" />
<axis xyz="0 0 1"/>
<limit effort="10" velocity="6" lower="-0.785398" upper="0.785398"/>
<joint_properties friction="0.0"/>
</joint>

<joint name="left_ankle_pitch" type="revolute">
<origin xyz="-0.14 9.46118e-15 4.71151e-15" rpy="-2.63106e-14 -1.45196e-14 -1.5669e-13" />
<parent link="tibia_left_full" />
<child link="mx106_with_u_l" />
<axis xyz="0 0 1"/>
<limit effort="10" velocity="6" lower="-1.5708" upper="1.5708"/>
<joint_properties friction="0.0"/>
</joint>

<joint name="left_knee" type="revolute">
<origin xyz="-7.5287e-16 0.14 -0.001" rpy="1.92498e-15 1.2611e-14 -1.5708" />
<parent link="thigh_horn_left" />
<child link="tibia_left_full" />
<axis xyz="0 0 1"/>
<limit effort="10" velocity="6" lower="0." upper="3.14159"/>
<joint_properties friction="0.0"/>
</joint>

<joint name="left_hip_pitch" type="revolute">
<origin xyz="1.38778e-16 0.016 -0.0201" rpy="1.5708 -1.56511 -9.4895e-13" />
<parent link="mx106_with_u_r" />
<child link="thigh_horn_left" />
<axis xyz="0 0 1"/>
<limit effort="10" velocity="6" lower="-1.5708" upper="1.5708"/>
<joint_properties friction="0.0"/>
</joint>

<joint name="left_hip_roll" type="revolute">
<origin xyz="-1.11022e-16 -0.0200991 -0.0604" rpy="1.5708 -1.5708 0" />
<parent link="u_hip_with_saver" />
<child link="mx106_with_u_r" />
<axis xyz="0 0 1"/>
<limit effort="10" velocity="6" lower="-0.523599" upper="0.523599"/>
<joint_properties friction="0.0"/>
</joint>

<joint name="left_hip_yaw" type="revolute">
<origin xyz="0.00586897 0.0464 -0.0411" rpy="1.43162e-16 -2.2295e-14 1.5708" />
<parent link="torso" />
<child link="u_hip_with_saver" />
<axis xyz="0 0 1"/>
<limit effort="10" velocity="6" lower="-1.0472" upper="1.0472"/>
<joint_properties friction="0.0"/>
</joint>

<link name="u_hip_with_saver_2">
<inertial>
<origin xyz="-6.0662e-11 0.00126178 -0.0329138" rpy="0 0 0"/>
<mass value="0.136031" />
<inertia ixx="0.000121591" ixy="4.65788e-14"  ixz="1.94175e-13" iyy="7.55159e-05" iyz="7.1306e-07" izz="5.66884e-05" />
</inertial>
</link>

<link name="mx106_with_u_l_2">
<!-- Shapes for inner -->
<collision>
<origin xyz="-0.0149141 0.0005 -0.01995" rpy="1.5708 1.5708 0" />
<geometry>
<box size="0.027 0.058 0.026" />
</geometry>
</collision>
<!-- Shapes for inner -->
<visual>
<origin xyz="-0.0149141 0.0005 -0.01995" rpy="1.5708 1.5708 0" />
<geometry>
<box size="0.027 0.058 0.026" />
</geometry>
<material name="inner_material">
<color rgba="0.647059 0.647059 0.647059 1.0"/>
</material>
</visual>
<!-- Shapes for inner -->
<collision>
<origin xyz="-0.0149141 -0.00015 -0.0799437" rpy="3.14159 -6.10623e-16 1.5708" />
<geometry>
<box size="0.027 0.058 0.026" />
</geometry>
</collision>
<!-- Shapes for inner -->
<visual>
<origin xyz="-0.0149141 -0.00015 -0.0799437" rpy="3.14159 -6.10623e-16 1.5708" />
<geometry>
<box size="0.027 0.058 0.026" />
</geometry>
<material name="inner_material">
<color rgba="0.647059 0.647059 0.647059 1.0"/>
</material>
</visual>
<inertial>
<origin xyz="-0.0157981 0.00247927 -0.0424173" rpy="0 0 0"/>
<mass value="0.136461" />
<inertia ixx="0.000126581" ixy="-1.40995e-06"  ixz="-7.32947e-06" iyy="0.000158902" iyz="-7.57616e-06" izz="8.16104e-05" />
</inertial>
</link>

<link name="thigh_horn_right">
<!-- Shapes for thigh_horn -->
<collision>
<origin xyz="2.15499e-16 0.04 -0.0434" rpy="3.14159 5.55112e-17 2.01916e-16" />
<geometry>
<box size="0.03 0.08 0.003" />
</geometry>
</collision>
<!-- Shapes for thigh_horn -->
<visual>
<origin xyz="2.15499e-16 0.04 -0.0434" rpy="3.14159 5.55112e-17 2.01916e-16" />
<geometry>
<box size="0.03 0.08 0.003" />
</geometry>
<material name="thigh_horn_material">
<color rgba="0.615686 0.811765 0.929412 1.0"/>
</material>
</visual>
<!-- Shapes for inner -->
<collision>
<origin xyz="-0.00015 0.12485 -0.0165" rpy="2.3019e-16 -1.11022e-16 6.46001e-16" />
<geometry>
<box size="0.027 0.058 0.026" />
</geometry>
</collision>
<!-- Shapes for inner -->
<visual>
<origin xyz="-0.00015 0.12485 -0.0165" rpy="2.3019e-16 -1.11022e-16 6.46001e-16" />
<geometry>
<box size="0.027 0.058 0.026" />
</geometry>
<material name="inner_material">
<color rgba="0.647059 0.647059 0.647059 1.0"/>
</material>
</visual>
<!-- Shapes for thigh_free_right -->
<collision>
<origin xyz="-6.15994e-17 0.036 0.0054" rpy="-8.53145e-16 1.04637e-29 -1.04003e-18" />
<geometry>
<box size="0.03 0.08 0.003" />
</geometry>
</collision>
<!-- Shapes for thigh_free_right -->
<visual>
<origin xyz="-6.15994e-17 0.036 0.0054" rpy="-8.53145e-16 1.04637e-29 -1.04003e-18" />
<geometry>
<box size="0.03 0.08 0.003" />
</geometry>
<material name="thigh_free_right_material">
<color rgba="0.615686 0.811765 0.929412 1.0"/>
</material>
</visual>
<inertial>
<origin xyz="-0.000103673 0.0868627 -0.0156903" rpy="0 0 0"/>
<mass value="0.0845547" />
<inertia ixx="0.000327329" ixy="4.67647e-08"  ixz="-6.41747e-09" iyy="3.62056e-05" iyz="4.5674e-05" izz="0.000305876" />
</inertial>
</link>

<link name="tibia_right_full">
<!-- Shapes for tibia_right -->
<collision>
<origin xyz="-0.065 0.0005 0.0085" rpy="3.14159 4.34305e-31 -7.29719e-19" />
<geometry>
<box size="0.15 0.035 0.003" />
</geometry>
</collision>
<!-- Shapes for tibia_right -->
<visual>
<origin xyz="-0.065 0.0005 0.0085" rpy="3.14159 4.34305e-31 -7.29719e-19" />
<geometry>
<box size="0.15 0.035 0.003" />
</geometry>
<material name="tibia_right_material">
<color rgba="0.615686 0.811765 0.929412 1.0"/>
</material>
</visual>
<!-- Shapes for tibia_horn_side -->
<collision>
<origin xyz="-0.065 1.05036e-14 -0.0435" rpy="4.89053e-14 -1.70336e-13 3.06391e-14" />
<geometry>
<box size="0.15 0.035 0.003" />
</geometry>
</collision>
<!-- Shapes for tibia_horn_side -->
<visual>
<origin xyz="-0.065 1.05036e-14 -0.0435" rpy="4.89053e-14 -1.70336e-13 3.06391e-14" />
<geometry>
<box size="0.15 0.035 0.003" />
</geometry>
<material name="tibia_horn_side_material">
<color rgba="0.615686 0.811765 0.929412 1.0"/>
</material>
</visual>
<inertial>
<origin xyz="-0.07 -1.76056e-13 -0.00139217" rpy="0 0 0"/>
<mass value="0.0501468" />
<inertia ixx="1.6277e-05" ixy="-2.49887e-17"  ixz="1.29958e-13" iyy="0.000261996" iyz="-3.33217e-16" izz="0.000248145" />
</inertial>
</link>

<link name="mx106_with_u_r_2">
<!-- Shapes for inner -->
<collision>
<origin xyz="0.01515 -0.00015 -0.0165" rpy="6.89553e-17 -9.4369e-16 1.5708" />
<geometry>
<box size="0.027 0.058 0.026" />
</geometry>
</collision>
<!-- Shapes for inner -->
<visual>
<origin xyz="0.01515 -0.00015 -0.0165" rpy="6.89553e-17 -9.4369e-16 1.5708" />
<geometry>
<box size="0.027 0.058 0.026" />
</geometry>
<material name="inner_material">
<color rgba="0.647059 0.647059 0.647059 1.0"/>
</material>
</visual>
<!-- Shapes for inner -->
<collision>
<origin xyz="0.01515 -0.0598438 -0.01615" rpy="1.5708 -1.5708 0" />
<geometry>
<box size="0.027 0.058 0.026" />
</geometry>
</collision>
<!-- Shapes for inner -->
<visual>
<origin xyz="0.01515 -0.0598438 -0.01615" rpy="1.5708 -1.5708 0" />
<geometry>
<box size="0.027 0.058 0.026" />
</geometry>
<material name="inner_material">
<color rgba="0.647059 0.647059 0.647059 1.0"/>
</material>
</visual>
<inertial>
<origin xyz="0.016034 -0.0223236 -0.0184855" rpy="0 0 0"/>
<mass value="0.136461" />
<inertia ixx="0.000126539" ixy="7.33812e-06"  ixz="-1.4013e-06" iyy="8.16062e-05" iyz="7.54591e-06" izz="0.000158864" />
</inertial>
</link>

<link name="right_foot_asm">
<!-- Shapes for cleat -->
<collision>
<origin xyz="0.052 -0.0435 -0.07563" rpy="1.5708 0.653869 1.5708" />
<geometry>
<cylinder length="0.016" radius="0.008" />
</geometry>
</collision>
<!-- Shapes for cleat -->
<visual>
<origin xyz="0.052 -0.0435 -0.07563" rpy="1.5708 0.653869 1.5708" />
<geometry>
<cylinder length="0.016" radius="0.008" />
</geometry>
<material name="cleat_material">
<color rgba="0.301961 0.290196 0.262745 1.0"/>
</material>
</visual>
<!-- Shapes for cleat -->
<collision>
<origin xyz="0.052 -0.0435 0.06597" rpy="-1.5708 -1.27175 -1.5708" />
<geometry>
<cylinder length="0.016" radius="0.008" />
</geometry>
</collision>
<!-- Shapes for cleat -->
<visual>
<origin xyz="0.052 -0.0435 0.06597" rpy="-1.5708 -1.27175 -1.5708" />
<geometry>
<cylinder length="0.016" radius="0.008" />
</geometry>
<material name="cleat_material">
<color rgba="0.301961 0.290196 0.262745 1.0"/>
</material>
</visual>
<!-- Shapes for cleat -->
<collision>
<origin xyz="0.052 0.0325 -0.07563" rpy="1.5708 0.653869 1.5708" />
<geometry>
<cylinder length="0.016" radius="0.008" />
</geometry>
</collision>
<!-- Shapes for cleat -->
<visual>
<origin xyz="0.052 0.0325 -0.07563" rpy="1.5708 0.653869 1.5708" />
<geometry>
<cylinder length="0.016" radius="0.008" />
</geometry>
<material name="cleat_material">
<color rgba="0.301961 0.290196 0.262745 1.0"/>
</material>
</visual>
<!-- Shapes for cleat -->
<collision>
<origin xyz="0.052 0.0325 0.06597" rpy="1.5708 0.653869 1.5708" />
<geometry>
<cylinder length="0.016" radius="0.008" />
</geometry>
</collision>
<!-- Shapes for cleat -->
<visual>
<origin xyz="0.052 0.0325 0.06597" rpy="1.5708 0.653869 1.5708" />
<geometry>
<cylinder length="0.016" radius="0.008" />
</geometry>
<material name="cleat_material">
<color rgba="0.301961 0.290196 0.262745 1.0"/>
</material>
</visual>
<!-- Shapes for foot_plate -->
<collision>
<origin xyz="0.0415 -0.0055 -0.00483" rpy="-1.5708 2.8968e-19 1.5708" />
<geometry>
<box size="0.092 0.1576 0.003" />
</geometry>
</collision>
<!-- Shapes for foot_plate -->
<visual>
<origin xyz="0.0415 -0.0055 -0.00483" rpy="-1.5708 2.8968e-19 1.5708" />
<geometry>
<box size="0.092 0.1576 0.003" />
</geometry>
<material name="foot_plate_material">
<color rgba="0.301961 0.301961 0.301961 1.0"/>
</material>
</visual>
<inertial>
<origin xyz="0.0312589 -0.00414302 0.000817452" rpy="0 0 0"/>
<mass value="0.32139" />
<inertia ixx="0.00102249" ixy="8.69712e-06"  ixz="-2.18857e-05" iyy="0.0008644" iyz="1.04066e-05" izz="0.000326572" />
</inertial>
</link>

<link name="right_foot">
<inertial>
<origin xyz="0 0 0" rpy="0 0 0" />
<mass value="1e-9" />
<inertia ixx="0" ixy="0" ixz="0" iyy="0" iyz="0" izz="0" />
</inertial>
</link>
<joint name="right_foot_frame" type="fixed">
<origin xyz="0.06 1.02696e-15 -0.02033" rpy="4.64969e-19 -1.5708 0" />
<parent link="right_foot_asm" />
<child link="right_foot" />
<axis xyz="0 0 0"/>
</joint>

<joint name="right_ankle_roll" type="revolute">
<origin xyz="-2.22045e-16 0.0201 -0.016" rpy="1.5708 4.64969e-19 -3.14159" />
<parent link="mx106_with_u_r_2" />
<child link="right_foot_asm" />
<axis xyz="0 0 1"/>
<limit effort="10" velocity="6" lower="-0.785398" upper="0.785398"/>
<joint_properties friction="0.0"/>
</joint>

<joint name="right_ankle_pitch" type="revolute">
<origin xyz="-0.14 -1.56732e-14 5.03798e-14" rpy="-4.4409e-16 -4.49305e-15 1.11963e-13" />
<parent link="tibia_right_full" />
<child link="mx106_with_u_r_2" />
<axis xyz="0 0 1"/>
<limit effort="10" velocity="6" lower="-1.5708" upper="1.5708"/>
<joint_properties friction="0.0"/>
</joint>

<joint name="right_knee" type="revolute">
<origin xyz="-3.81639e-17 0.14 -2.05357e-14" rpy="-1.24994e-15 -5.32933e-16 -1.5708" />
<parent link="thigh_horn_right" />
<child link="tibia_right_full" />
<axis xyz="0 0 1"/>
<limit effort="10" velocity="6" lower="0." upper="3.14159"/>
<joint_properties friction="0.0"/>
</joint>

<joint name="right_hip_pitch" type="revolute">
<origin xyz="0.000235943 -0.016 -0.0201" rpy="1.5708 -1.56511 -2.92366e-13" />
<parent link="mx106_with_u_l_2" />
<child link="thigh_horn_right" />
<axis xyz="0 0 1"/>
<limit effort="10" velocity="6" lower="-1.5708" upper="1.5708"/>
<joint_properties friction="0.0"/>
</joint>

<joint name="right_hip_roll" type="revolute">
<origin xyz="6.245e-17 -0.0200991 -0.0604" rpy="1.5708 -1.5708 0" />
<parent link="u_hip_with_saver_2" />
<child link="mx106_with_u_l_2" />
<axis xyz="0 0 1"/>
<limit effort="10" velocity="6" lower="-0.523599" upper="0.523599"/>
<joint_properties friction="0.0"/>
</joint>

<joint name="right_hip_yaw" type="revolute">
<origin xyz="0.00586897 -0.0464 -0.0411" rpy="1.22835e-15 -2.11957e-15 1.5708" />
<parent link="torso" />
<child link="u_hip_with_saver_2" />
<axis xyz="0 0 1"/>
<limit effort="10" velocity="6" lower="-1.0472" upper="1.0472"/>
<joint_properties friction="0.0"/>
</joint>

<link name="u_neck">
<!-- Shapes for u_base_64 -->
<collision>
<origin xyz="5.24496e-34 -1.92593e-35 0.003125" rpy="3.14159 1.57269e-31 1.0424e-30" />
<geometry>
<box size="0.049 0.03 0.00625" />
</geometry>
</collision>
<!-- Shapes for u_base_64 -->
<visual>
<origin xyz="5.24496e-34 -1.92593e-35 0.003125" rpy="3.14159 1.57269e-31 1.0424e-30" />
<geometry>
<box size="0.049 0.03 0.00625" />
</geometry>
<material name="u_base_64_material">
<color rgba="0.301961 0.301961 0.301961 1.0"/>
</material>
</visual>
<!-- Shapes for u_side_neck -->
<collision>
<origin xyz="0.025 -3.04572e-15 0.032901" rpy="1.5708 -1.36551e-14 -1.5708" />
<geometry>
<box size="0.03 0.065802 0.003" />
</geometry>
</collision>
<!-- Shapes for u_side_neck -->
<visual>
<origin xyz="0.025 -3.04572e-15 0.032901" rpy="1.5708 -1.36551e-14 -1.5708" />
<geometry>
<box size="0.03 0.065802 0.003" />
</geometry>
<material name="u_side_neck_material">
<color rgba="0.301961 0.301961 0.301961 1.0"/>
</material>
</visual>
<!-- Shapes for u_side_neck -->
<collision>
<origin xyz="-0.025 2.111e-15 0.032901" rpy="1.5708 1.47653e-14 1.5708" />
<geometry>
<box size="0.03 0.065802 0.003" />
</geometry>
</collision>
<!-- Shapes for u_side_neck -->
<visual>
<origin xyz="-0.025 2.111e-15 0.032901" rpy="1.5708 1.47653e-14 1.5708" />
<geometry>
<box size="0.03 0.065802 0.003" />
</geometry>
<material name="u_side_neck_material">
<color rgba="0.301961 0.301961 0.301961 1.0"/>
</material>
</visual>
<inertial>
<origin xyz="-6.22838e-17 -2.25985e-16 0.0206334" rpy="0 0 0"/>
<mass value="0.0544799" />
<inertia ixx="3.05787e-05" ixy="-1.35944e-11"  ixz="-1.74859e-19" iyy="5.16952e-05" iyz="4.29472e-20" izz="2.98525e-05" />
</inertial>
</link>

<link name="head__field_of_view_false">
<!-- Shapes for mx-64at_ar -->
<collision>
<origin xyz="2.01086e-16 -0.01755 -0.0235" rpy="-3.09954e-16 1.24585e-15 1.34226e-14" />
<geometry>
<box size="0.0402 0.0611 0.041" />
</geometry>
</collision>
<!-- Shapes for mx-64at_ar -->
<visual>
<origin xyz="2.01086e-16 -0.01755 -0.0235" rpy="-3.09954e-16 1.24585e-15 1.34226e-14" />
<geometry>
<box size="0.0402 0.0611 0.041" />
</geometry>
<material name="mx-64at_ar_material">
<color rgba="0.168627 0.168627 0.168627 1.0"/>
</material>
</visual>
<!-- Shapes for head_plate -->
<collision>
<origin xyz="-0.0238 0.0365 -0.042" rpy="3.14159 -7.46249e-16 -3.14159" />
<geometry>
<cylinder length="0.003" radius="0.0235" />
</geometry>
</collision>
<collision>
<origin xyz="0.01 0.0365 -0.042" rpy="3.14159 -7.46249e-16 -3.14159" />
<geometry>
<box size="0.0616 0.047 0.003" />
</geometry>
</collision>
<!-- Shapes for head_plate -->
<visual>
<origin xyz="-0.0238 0.0365 -0.042" rpy="3.14159 -7.46249e-16 -3.14159" />
<geometry>
<cylinder length="0.003" radius="0.0235" />
</geometry>
<material name="head_plate_material">
<color rgba="0.701961 0.682353 0.623529 1.0"/>
</material>
</visual>
<visual>
<origin xyz="0.01 0.0365 -0.042" rpy="3.14159 -7.46249e-16 -3.14159" />
<geometry>
<box size="0.0616 0.047 0.003" />
</geometry>
<material name="head_plate_material">
<color rgba="0.701961 0.682353 0.623529 1.0"/>
</material>
</visual>
<!-- Shapes for head_plate -->
<collision>
<origin xyz="-0.0238 0.0365 -0.005" rpy="-3.14159 -8.57271e-16 -3.14159" />
<geometry>
<cylinder length="0.003" radius="0.0235" />
</geometry>
</collision>
<collision>
<origin xyz="0.01 0.0365 -0.005" rpy="-3.14159 -8.57271e-16 -3.14159" />
<geometry>
<box size="0.0616 0.047 0.003" />
</geometry>
</collision>
<!-- Shapes for head_plate -->
<visual>
<origin xyz="-0.0238 0.0365 -0.005" rpy="-3.14159 -8.57271e-16 -3.14159" />
<geometry>
<cylinder length="0.003" radius="0.0235" />
</geometry>
<material name="head_plate_material">
<color rgba="0.701961 0.682353 0.623529 1.0"/>
</material>
</visual>
<visual>
<origin xyz="0.01 0.0365 -0.005" rpy="-3.14159 -8.57271e-16 -3.14159" />
<geometry>
<box size="0.0616 0.047 0.003" />
</geometry>
<material name="head_plate_material">
<color rgba="0.701961 0.682353 0.623529 1.0"/>
</material>
</visual>
<inertial>
<origin xyz="0.0180026 0.128543 -0.0843703" rpy="0 0 0"/>
<mass value="0.120438" />
<inertia ixx="0.00740784" ixy="-0.00108575"  ixz="0.000667157" iyy="0.00228607" iyz="0.00327733" izz="0.00563245" />
</inertial>
</link>

<link name="camera">
<inertial>
<origin xyz="0 0 0" rpy="0 0 0" />
<mass value="1e-9" />
<inertia ixx="0" ixy="0" ixz="0" iyy="0" iyz="0" izz="0" />
</inertial>
</link>
<joint name="camera_frame" type="fixed">
<origin xyz="-0.024933 0.0335 -0.0235" rpy="3.14159 1.5708 0" />
<parent link="head__field_of_view_false" />
<child link="camera" />
<axis xyz="0 0 0"/>
</joint>

<joint name="head_pitch" type="revolute">
<origin xyz="-0.0235 1.67921e-15 0.058302" rpy="1.5708 -5.26755e-18 -1.5708" />
<parent link="u_neck" />
<child link="head__field_of_view_false" />
<axis xyz="0 0 1"/>
<limit effort="10" velocity="6" lower="-0.785398" upper="1.5708"/>
<joint_properties friction="0.0"/>
</joint>

<joint name="head_yaw" type="revolute">
<origin xyz="0.035869 4.36359e-15 0.1595" rpy="3.46945e-16 2.84444e-15 -1.5708" />
<parent link="torso" />
<child link="u_neck" />
<axis xyz="0 0 1"/>
<limit effort="10" velocity="6" lower="-2.0944" upper="2.0944"/>
<joint_properties friction="0.0"/>
</joint>


</robot>
