<robot name="onshape">
<link name="torso">
<!-- Shapes for x_plate -->
<collision>
<origin xyz="0.057869 3.81527e-15 0.0595" rpy="1.5708 -3.71254e-15 1.5708" />
<geometry>
<box size="0.133 0.113 0.006" />
</geometry>
</collision>
<!-- Shapes for x_plate -->
<visual>
<origin xyz="0.057869 3.81527e-15 0.0595" rpy="1.5708 -3.71254e-15 1.5708" />
<geometry>
<box size="0.133 0.113 0.006" />
</geometry>
<material name="x_plate_material">
<color rgba="0.262745 0.282353 0.301961 1.0"/>
</material>
</visual>
<!-- Shapes for mx-64at_ar -->
<collision>
<origin xyz="0.023419 -0.0464 -0.017" rpy="-3.14159 2.03946e-15 -1.5708" />
<geometry>
<box size="0.0402 0.0611 0.041" />
</geometry>
</collision>
<!-- Shapes for mx-64at_ar -->
<visual>
<origin xyz="0.023419 -0.0464 -0.017" rpy="-3.14159 2.03946e-15 -1.5708" />
<geometry>
<box size="0.0402 0.0611 0.041" />
</geometry>
<material name="mx-64at_ar_material">
<color rgba="0.168627 0.168627 0.168627 1.0"/>
</material>
</visual>
<!-- Shapes for mx-64at_ar -->
<collision>
<origin xyz="0.013319 0.056 0.143" rpy="-1.5708 -1.5708 0" />
<geometry>
<box size="0.0402 0.0611 0.041" />
</geometry>
</collision>
<!-- Shapes for mx-64at_ar -->
<visual>
<origin xyz="0.013319 0.056 0.143" rpy="-1.5708 -1.5708 0" />
<geometry>
<box size="0.0402 0.0611 0.041" />
</geometry>
<material name="mx-64at_ar_material">
<color rgba="0.168627 0.168627 0.168627 1.0"/>
</material>
</visual>
<!-- Shapes for x_plate -->
<collision>
<origin xyz="-0.057131 7.78087e-15 0.0595" rpy="1.5708 -1.21571e-15 1.5708" />
<geometry>
<box size="0.133 0.113 0.006" />
</geometry>
</collision>
<!-- Shapes for x_plate -->
<visual>
<origin xyz="-0.057131 7.78087e-15 0.0595" rpy="1.5708 -1.21571e-15 1.5708" />
<geometry>
<box size="0.133 0.113 0.006" />
</geometry>
<material name="x_plate_material">
<color rgba="0.262745 0.282353 0.301961 1.0"/>
</material>
</visual>
<!-- Shapes for mx-64at_ar -->
<collision>
<origin xyz="0.023419 0.0464 -0.017" rpy="-3.14159 2.02561e-15 -1.5708" />
<geometry>
<box size="0.0402 0.0611 0.041" />
</geometry>
</collision>
<!-- Shapes for mx-64at_ar -->
<visual>
<origin xyz="0.023419 0.0464 -0.017" rpy="-3.14159 2.02561e-15 -1.5708" />
<geometry>
<box size="0.0402 0.0611 0.041" />
</geometry>
<material name="mx-64at_ar_material">
<color rgba="0.168627 0.168627 0.168627 1.0"/>
</material>
</visual>
<!-- Shapes for mx-64at_ar -->
<collision>
<origin xyz="0.018319 5.20694e-15 0.136" rpy="4.02456e-16 1.06347e-14 -1.5708" />
<geometry>
<box size="0.0402 0.0611 0.041" />
</geometry>
</collision>
<!-- Shapes for mx-64at_ar -->
<visual>
<origin xyz="0.018319 5.20694e-15 0.136" rpy="4.02456e-16 1.06347e-14 -1.5708" />
<geometry>
<box size="0.0402 0.0611 0.041" />
</geometry>
<material name="mx-64at_ar_material">
<color rgba="0.168627 0.168627 0.168627 1.0"/>
</material>
</visual>
<!-- Shapes for mx-64at_ar -->
<collision>
<origin xyz="0.013319 -0.056 0.143" rpy="1.5708 1.5708 0" />
<geometry>
<box size="0.0402 0.0611 0.041" />
</geometry>
</collision>
<!-- Shapes for mx-64at_ar -->
<visual>
<origin xyz="0.013319 -0.056 0.143" rpy="1.5708 1.5708 0" />
<geometry>
<box size="0.0402 0.0611 0.041" />
</geometry>
<material name="mx-64at_ar_material">
<color rgba="0.168627 0.168627 0.168627 1.0"/>
</material>
</visual>
<inertial>
<origin xyz="-0.00228246 0.00486462 0.0826876" rpy="0 0 0"/>
<mass value="2.39006" />
<inertia ixx="0.031289" ixy="0.00221215"  ixz="0.00473162" iyy="0.032668" iyz="-0.00207203" izz="0.012466" />
</inertial>
</link>

<link name="head_base">
<inertial>
<origin xyz="0 0 0" rpy="0 0 0" />
<mass value="1e-9" />
<inertia ixx="0" ixy="0" ixz="0" iyy="0" iyz="0" izz="0" />
</inertial>
</link>
<joint name="head_base_frame" type="fixed">
<origin xyz="0.035869 2.87859e-15 0.1595" rpy="3.79641e-14 -9.95037e-15 -1.04223e-13" />
<parent link="torso" />
<child link="head_base" />
<axis xyz="0 0 0"/>
</joint>

<link name="trunk">
<inertial>
<origin xyz="0 0 0" rpy="0 0 0" />
<mass value="1e-9" />
<inertia ixx="0" ixy="0" ixz="0" iyy="0" iyz="0" izz="0" />
</inertial>
</link>
<joint name="trunk_frame" type="fixed">
<origin xyz="0.00586803 -3.95579e-15 -0.1015" rpy="2.09431e-15 2.18595e-26 -4.72596e-14" />
<parent link="torso" />
<child link="trunk" />
<axis xyz="0 0 0"/>
</joint>

<link name="u_shoulder">
<!-- Shapes for u_base_64 -->
<collision>
<origin xyz="-2.05957e-33 -1.79199e-33 -0.003125" rpy="-5.70266e-31 1.2977e-30 -9.30609e-31" />
<geometry>
<box size="0.049 0.03 0.00625" />
</geometry>
</collision>
<!-- Shapes for u_base_64 -->
<visual>
<origin xyz="-2.05957e-33 -1.79199e-33 -0.003125" rpy="-5.70266e-31 1.2977e-30 -9.30609e-31" />
<geometry>
<box size="0.049 0.03 0.00625" />
</geometry>
<material name="u_base_64_material">
<color rgba="0.301961 0.301961 0.301961 1.0"/>
</material>
</visual>
<inertial>
<origin xyz="-1.43643e-15 -0.00566234 -0.0159676" rpy="0 0 0"/>
<mass value="0.0570101" />
<inertia ixx="2.21758e-05" ixy="-1.99013e-19"  ixz="9.23531e-19" iyy="4.03314e-05" iyz="-6.10703e-06" izz="3.58629e-05" />
</inertial>
</link>

<link name="right_humerus">
<!-- Shapes for mx-64at_ar -->
<collision>
<origin xyz="1.46133e-17 -0.01755 -0.0235" rpy="-8.04912e-16 6.93889e-18 -3.88578e-16" />
<geometry>
<box size="0.0402 0.0611 0.041" />
</geometry>
</collision>
<!-- Shapes for mx-64at_ar -->
<visual>
<origin xyz="1.46133e-17 -0.01755 -0.0235" rpy="-8.04912e-16 6.93889e-18 -3.88578e-16" />
<geometry>
<box size="0.0402 0.0611 0.041" />
</geometry>
<material name="mx-64at_ar_material">
<color rgba="0.168627 0.168627 0.168627 1.0"/>
</material>
</visual>
<inertial>
<origin xyz="-0.0100924 0.0240054 -0.0167465" rpy="0 0 0"/>
<mass value="0.241448" />
<inertia ixx="0.0138297" ixy="0.00193846"  ixz="0.00019138" iyy="0.000488317" iyz="-0.00135015" izz="0.0139663" />
</inertial>
</link>

<link name="radius_v2">
<!-- Shapes for hand -->
<collision>
<origin xyz="-2.76099e-17 0.1276 0.042" rpy="3.14159 3.33067e-16 1.5708" />
<geometry>
<cylinder length="0.003" radius="0.04" />
</geometry>
</collision>
<collision>
<origin xyz="-7.17498e-18 0.0539756 0.042" rpy="3.14159 3.33067e-16 1.5708" />
<geometry>
<box size="0.0775512 0.0412 0.003" />
</geometry>
</collision>
<!-- Shapes for hand -->
<visual>
<origin xyz="-2.76099e-17 0.1276 0.042" rpy="3.14159 3.33067e-16 1.5708" />
<geometry>
<cylinder length="0.003" radius="0.04" />
</geometry>
<material name="hand_material">
<color rgba="0.301961 0.301961 0.301961 1.0"/>
</material>
</visual>
<visual>
<origin xyz="-7.17498e-18 0.0539756 0.042" rpy="3.14159 3.33067e-16 1.5708" />
<geometry>
<box size="0.0775512 0.0412 0.003" />
</geometry>
<material name="hand_material">
<color rgba="0.301961 0.301961 0.301961 1.0"/>
</material>
</visual>
<!-- Shapes for hand -->
<collision>
<origin xyz="-1.52635e-16 0.1276 0.005" rpy="3.14159 4.44089e-16 1.5708" />
<geometry>
<cylinder length="0.003" radius="0.04" />
</geometry>
</collision>
<collision>
<origin xyz="-1.54678e-16 0.0539756 0.005" rpy="3.14159 4.44089e-16 1.5708" />
<geometry>
<box size="0.0775512 0.0412 0.003" />
</geometry>
</collision>
<!-- Shapes for hand -->
<visual>
<origin xyz="-1.52635e-16 0.1276 0.005" rpy="3.14159 4.44089e-16 1.5708" />
<geometry>
<cylinder length="0.003" radius="0.04" />
</geometry>
<material name="hand_material">
<color rgba="0.301961 0.301961 0.301961 1.0"/>
</material>
</visual>
<visual>
<origin xyz="-1.54678e-16 0.0539756 0.005" rpy="3.14159 4.44089e-16 1.5708" />
<geometry>
<box size="0.0775512 0.0412 0.003" />
</geometry>
<material name="hand_material">
<color rgba="0.301961 0.301961 0.301961 1.0"/>
</material>
</visual>
<!-- Shapes for mx-64at_ar -->
<collision>
<origin xyz="3.52912e-18 0.01755 0.0235" rpy="3.14159 -8.03036e-30 2.77556e-17" />
<geometry>
<box size="0.0402 0.0611 0.041" />
</geometry>
</collision>
<!-- Shapes for mx-64at_ar -->
<visual>
<origin xyz="3.52912e-18 0.01755 0.0235" rpy="3.14159 -8.03036e-30 2.77556e-17" />
<geometry>
<box size="0.0402 0.0611 0.041" />
</geometry>
<material name="mx-64at_ar_material">
<color rgba="0.168627 0.168627 0.168627 1.0"/>
</material>
</visual>
<inertial>
<origin xyz="-0.0295944 -0.040688 0.0218765" rpy="0 0 0"/>
<mass value="0.250119" />
<inertia ixx="0.0216936" ixy="-0.00684459"  ixz="-2.20795e-05" iyy="0.00234767" iyz="-7.87859e-05" izz="0.0239352" />
</inertial>
</link>

<joint name="right_elbow" type="revolute">
<origin xyz="-0.0235 -0.142 -0.0025" rpy="3.14159 -1.5708 0" />
<parent link="right_humerus" />
<child link="radius_v2" />
<axis xyz="0 0 1"/>
<limit effort="10" velocity="6" lower="-2.79253" upper="-0"/>
<joint_properties friction="0.0"/>
</joint>

<joint name="right_shoulder_roll" type="revolute">
<origin xyz="-0.0235 -0.03 -0.035" rpy="-5.55112e-17 -1.5708 0" />
<parent link="u_shoulder" />
<child link="right_humerus" />
<axis xyz="0 0 1"/>
<limit effort="10" velocity="6" lower="-1.5708" upper="0.0872665"/>
<joint_properties friction="0.0"/>
</joint>

<joint name="right_shoulder_pitch" type="revolute">
<origin xyz="0.030869 -0.0795 0.143" rpy="1.5708 -1.84019e-14 3.14159" />
<parent link="torso" />
<child link="u_shoulder" />
<axis xyz="0 0 1"/>
<limit effort="10" velocity="6" lower="-2.18166" upper="2.18166"/>
<joint_properties friction="0.0"/>
</joint>

<link name="u_shoulder_2">
<!-- Shapes for u_base_64 -->
<collision>
<origin xyz="-4.32799e-34 1.44897e-33 0.003125" rpy="3.14159 1.38496e-31 3.69779e-31" />
<geometry>
<box size="0.049 0.03 0.00625" />
</geometry>
</collision>
<!-- Shapes for u_base_64 -->
<visual>
<origin xyz="-4.32799e-34 1.44897e-33 0.003125" rpy="3.14159 1.38496e-31 3.69779e-31" />
<geometry>
<box size="0.049 0.03 0.00625" />
</geometry>
<material name="u_base_64_material">
<color rgba="0.301961 0.301961 0.301961 1.0"/>
</material>
</visual>
<inertial>
<origin xyz="-5.67381e-16 0.00566234 0.0159676" rpy="0 0 0"/>
<mass value="0.0570101" />
<inertia ixx="2.21758e-05" ixy="1.12444e-19"  ixz="3.13085e-19" iyy="4.03314e-05" iyz="-6.10703e-06" izz="3.58629e-05" />
</inertial>
</link>

<link name="left_humerus">
<!-- Shapes for mx-64at_ar -->
<collision>
<origin xyz="6.81954e-18 -0.01755 -0.0235" rpy="6.15036e-16 1.39816e-29 1.05471e-15" />
<geometry>
<box size="0.0402 0.0611 0.041" />
</geometry>
</collision>
<!-- Shapes for mx-64at_ar -->
<visual>
<origin xyz="6.81954e-18 -0.01755 -0.0235" rpy="6.15036e-16 1.39816e-29 1.05471e-15" />
<geometry>
<box size="0.0402 0.0611 0.041" />
</geometry>
<material name="mx-64at_ar_material">
<color rgba="0.168627 0.168627 0.168627 1.0"/>
</material>
</visual>
<inertial>
<origin xyz="-0.0306821 0.00954138 -0.0179524" rpy="0 0 0"/>
<mass value="0.241448" />
<inertia ixx="0.00921809" ixy="0.00421411"  ixz="0.000444846" iyy="0.00227413" iyz="-0.0009285" izz="0.0112174" />
</inertial>
</link>

<link name="radius_v2_2">
<!-- Shapes for mx-64at_ar -->
<collision>
<origin xyz="-3.89688e-18 -0.01755 -0.0235" rpy="-7.99013e-17 1.14505e-16 1.11022e-16" />
<geometry>
<box size="0.0402 0.0611 0.041" />
</geometry>
</collision>
<!-- Shapes for mx-64at_ar -->
<visual>
<origin xyz="-3.89688e-18 -0.01755 -0.0235" rpy="-7.99013e-17 1.14505e-16 1.11022e-16" />
<geometry>
<box size="0.0402 0.0611 0.041" />
</geometry>
<material name="mx-64at_ar_material">
<color rgba="0.168627 0.168627 0.168627 1.0"/>
</material>
</visual>
<!-- Shapes for hand -->
<collision>
<origin xyz="2.08452e-16 -0.1276 -0.005" rpy="-3.51984e-16 -7.99013e-17 -1.5708" />
<geometry>
<cylinder length="0.003" radius="0.04" />
</geometry>
</collision>
<collision>
<origin xyz="2.248e-16 -0.0539756 -0.005" rpy="-3.51984e-16 -7.99013e-17 -1.5708" />
<geometry>
<box size="0.0775512 0.0412 0.003" />
</geometry>
</collision>
<!-- Shapes for hand -->
<visual>
<origin xyz="2.08452e-16 -0.1276 -0.005" rpy="-3.51984e-16 -7.99013e-17 -1.5708" />
<geometry>
<cylinder length="0.003" radius="0.04" />
</geometry>
<material name="hand_material">
<color rgba="0.301961 0.301961 0.301961 1.0"/>
</material>
</visual>
<visual>
<origin xyz="2.248e-16 -0.0539756 -0.005" rpy="-3.51984e-16 -7.99013e-17 -1.5708" />
<geometry>
<box size="0.0775512 0.0412 0.003" />
</geometry>
<material name="hand_material">
<color rgba="0.301961 0.301961 0.301961 1.0"/>
</material>
</visual>
<!-- Shapes for hand -->
<collision>
<origin xyz="-2.91138e-16 -0.1276 -0.042" rpy="-1.42185e-16 -7.99013e-17 -1.5708" />
<geometry>
<cylinder length="0.003" radius="0.04" />
</geometry>
</collision>
<collision>
<origin xyz="-2.87051e-16 -0.0539756 -0.042" rpy="-1.42185e-16 -7.99013e-17 -1.5708" />
<geometry>
<box size="0.0775512 0.0412 0.003" />
</geometry>
</collision>
<!-- Shapes for hand -->
<visual>
<origin xyz="-2.91138e-16 -0.1276 -0.042" rpy="-1.42185e-16 -7.99013e-17 -1.5708" />
<geometry>
<cylinder length="0.003" radius="0.04" />
</geometry>
<material name="hand_material">
<color rgba="0.301961 0.301961 0.301961 1.0"/>
</material>
</visual>
<visual>
<origin xyz="-2.87051e-16 -0.0539756 -0.042" rpy="-1.42185e-16 -7.99013e-17 -1.5708" />
<geometry>
<box size="0.0775512 0.0412 0.003" />
</geometry>
<material name="hand_material">
<color rgba="0.301961 0.301961 0.301961 1.0"/>
</material>
</visual>
<inertial>
<origin xyz="0.0375062 0.0415038 -0.0369366" rpy="0 0 0"/>
<mass value="0.250119" />
<inertia ixx="0.0226227" ixy="-0.00870605"  ixz="0.0013969" iyy="0.00420944" iyz="0.00342464" izz="0.0256238" />
</inertial>
</link>

<joint name="left_elbow" type="revolute">
<origin xyz="0.0235 -0.142 -0.0025" rpy="1.63031e-15 1.5708 0" />
<parent link="left_humerus" />
<child link="radius_v2_2" />
<axis xyz="0 0 1"/>
<limit effort="10" velocity="6" lower="-2.79253" upper="0"/>
<joint_properties friction="0.0"/>
</joint>

<joint name="left_shoulder_roll" type="revolute">
<origin xyz="0.0235 0.03 0.035" rpy="-3.14159 -1.5708 0" />
<parent link="u_shoulder_2" />
<child link="left_humerus" />
<axis xyz="0 0 1"/>
<limit effort="10" velocity="6" lower="-0.0872665" upper="1.5708"/>
<joint_properties friction="0.0"/>
</joint>

<joint name="left_shoulder_pitch" type="revolute">
<origin xyz="0.030869 0.0795 0.143" rpy="-1.5708 -7.21645e-15 2.48831e-15" />
<parent link="torso" />
<child link="u_shoulder_2" />
<axis xyz="0 0 1"/>
<limit effort="10" velocity="6" lower="-2.18166" upper="2.18166"/>
<joint_properties friction="0.0"/>
</joint>

<link name="u_hip_with_saver">
<inertial>
<origin xyz="-6.06621e-11 0.00126178 -0.0329138" rpy="0 0 0"/>
<mass value="0.136031" />
<inertia ixx="0.000121591" ixy="4.65786e-14"  ixz="1.94175e-13" iyy="7.55159e-05" iyz="7.1306e-07" izz="5.66884e-05" />
</inertial>
</link>

<link name="mx106_with_u_r">
<!-- Shapes for inner -->
<collision>
<origin xyz="-0.01515 -0.00015 -0.0799438" rpy="-3.14159 2.33147e-15 1.5708" />
<geometry>
<box size="0.027 0.058 0.026" />
</geometry>
</collision>
<!-- Shapes for inner -->
<visual>
<origin xyz="-0.01515 -0.00015 -0.0799438" rpy="-3.14159 2.33147e-15 1.5708" />
<geometry>
<box size="0.027 0.058 0.026" />
</geometry>
<material name="inner_material">
<color rgba="0.647059 0.647059 0.647059 1.0"/>
</material>
</visual>
<!-- Shapes for inner -->
<collision>
<origin xyz="-0.01515 -0.0005 -0.02025" rpy="-1.5708 -1.5708 0" />
<geometry>
<box size="0.027 0.058 0.026" />
</geometry>
</collision>
<!-- Shapes for inner -->
<visual>
<origin xyz="-0.01515 -0.0005 -0.02025" rpy="-1.5708 -1.5708 0" />
<geometry>
<box size="0.027 0.058 0.026" />
</geometry>
<material name="inner_material">
<color rgba="0.647059 0.647059 0.647059 1.0"/>
</material>
</visual>
<inertial>
<origin xyz="-0.0131496 -0.00103215 -0.0475243" rpy="0 0 0"/>
<mass value="0.421574" />
<inertia ixx="0.000440314" ixy="4.41959e-07"  ixz="-4.51991e-06" iyy="0.000581579" iyz="1.16474e-05" izz="0.000245732" />
</inertial>
</link>

<link name="thigh_horn_left">
<!-- Shapes for thigh_free_left -->
<collision>
<origin xyz="-7.85706e-17 0.04 -0.0054" rpy="3.14159 5.55112e-16 -7.22946e-16" />
<geometry>
<box size="0.03 0.08 0.003" />
</geometry>
</collision>
<!-- Shapes for thigh_free_left -->
<visual>
<origin xyz="-7.85706e-17 0.04 -0.0054" rpy="3.14159 5.55112e-16 -7.22946e-16" />
<geometry>
<box size="0.03 0.08 0.003" />
</geometry>
<material name="thigh_free_left_material">
<color rgba="0.615686 0.811765 0.929412 1.0"/>
</material>
</visual>
<!-- Shapes for thigh_horn -->
<collision>
<origin xyz="-2.34837e-16 0.04 0.0436" rpy="3.14159 -1.11022e-16 -1.16669e-16" />
<geometry>
<box size="0.03 0.08 0.003" />
</geometry>
</collision>
<!-- Shapes for thigh_horn -->
<visual>
<origin xyz="-2.34837e-16 0.04 0.0436" rpy="3.14159 -1.11022e-16 -1.16669e-16" />
<geometry>
<box size="0.03 0.08 0.003" />
</geometry>
<material name="thigh_horn_material">
<color rgba="0.615686 0.811765 0.929412 1.0"/>
</material>
</visual>
<!-- Shapes for inner -->
<collision>
<origin xyz="0.00015 0.12485 0.0165" rpy="-3.14159 -1.05471e-15 3.14159" />
<geometry>
<box size="0.027 0.058 0.026" />
</geometry>
</collision>
<!-- Shapes for inner -->
<visual>
<origin xyz="0.00015 0.12485 0.0165" rpy="-3.14159 -1.05471e-15 3.14159" />
<geometry>
<box size="0.027 0.058 0.026" />
</geometry>
<material name="inner_material">
<color rgba="0.647059 0.647059 0.647059 1.0"/>
</material>
</visual>
<inertial>
<origin xyz="-1.5876e-05 0.112829 0.0162882" rpy="0 0 0"/>
<mass value="0.227111" />
<inertia ixx="0.000493196" ixy="-1.161e-07"  ixz="-1.76694e-08" iyy="6.33947e-05" iyz="-4.7784e-05" izz="0.000483708" />
</inertial>
</link>

<link name="tibia_left_full">
<!-- Shapes for tibia_horn_side -->
<collision>
<origin xyz="-0.065 1.71938e-14 0.0435" rpy="-3.57492e-14 -1.03071e-13 -3.84321e-14" />
<geometry>
<box size="0.15 0.035 0.003" />
</geometry>
</collision>
<!-- Shapes for tibia_horn_side -->
<visual>
<origin xyz="-0.065 1.71938e-14 0.0435" rpy="-3.57492e-14 -1.03071e-13 -3.84321e-14" />
<geometry>
<box size="0.15 0.035 0.003" />
</geometry>
<material name="tibia_horn_side_material">
<color rgba="0.615686 0.811765 0.929412 1.0"/>
</material>
</visual>
<!-- Shapes for tibia_left -->
<collision>
<origin xyz="-0.065 -0.0025 -0.0085" rpy="2.13355e-30 -1.94078e-32 1.36352e-19" />
<geometry>
<box size="0.15 0.035 0.003" />
</geometry>
</collision>
<!-- Shapes for tibia_left -->
<visual>
<origin xyz="-0.065 -0.0025 -0.0085" rpy="2.13355e-30 -1.94078e-32 1.36352e-19" />
<geometry>
<box size="0.15 0.035 0.003" />
</geometry>
<material name="tibia_left_material">
<color rgba="0.615686 0.811765 0.929412 1.0"/>
</material>
</visual>
<inertial>
<origin xyz="-0.07 1.75683e-13 0.00139217" rpy="0 0 0"/>
<mass value="0.0501468" />
<inertia ixx="1.6277e-05" ixy="1.37678e-17"  ixz="-1.29879e-13" iyy="0.000261996" iyz="-3.38785e-16" izz="0.000248145" />
</inertial>
</link>

<link name="mx106_with_u_l">
<!-- Shapes for inner -->
<collision>
<origin xyz="0.01515 -0.0598438 0.01585" rpy="1.5708 -1.5708 0" />
<geometry>
<box size="0.027 0.058 0.026" />
</geometry>
</collision>
<!-- Shapes for inner -->
<visual>
<origin xyz="0.01515 -0.0598438 0.01585" rpy="1.5708 -1.5708 0" />
<geometry>
<box size="0.027 0.058 0.026" />
</geometry>
<material name="inner_material">
<color rgba="0.647059 0.647059 0.647059 1.0"/>
</material>
</visual>
<!-- Shapes for inner -->
<collision>
<origin xyz="0.01515 0.00015 0.0165" rpy="3.14159 4.16334e-15 -1.5708" />
<geometry>
<box size="0.027 0.058 0.026" />
</geometry>
</collision>
<!-- Shapes for inner -->
<visual>
<origin xyz="0.01515 0.00015 0.0165" rpy="3.14159 4.16334e-15 -1.5708" />
<geometry>
<box size="0.027 0.058 0.026" />
</geometry>
<material name="inner_material">
<color rgba="0.647059 0.647059 0.647059 1.0"/>
</material>
</visual>
<inertial>
<origin xyz="0.0131496 -0.0274018 0.0170097" rpy="0 0 0"/>
<mass value="0.421574" />
<inertia ixx="0.000440852" ixy="4.25678e-06"  ixz="7.05086e-07" iyy="0.000245751" iyz="-1.19495e-05" izz="0.000582098" />
</inertial>
</link>

<link name="left_foot_asm">
<!-- Shapes for cleat -->
<collision>
<origin xyz="0.052 -0.0325 -0.07563" rpy="1.5708 -0.367068 1.5708" />
<geometry>
<cylinder length="0.016" radius="0.008" />
</geometry>
</collision>
<!-- Shapes for cleat -->
<visual>
<origin xyz="0.052 -0.0325 -0.07563" rpy="1.5708 -0.367068 1.5708" />
<geometry>
<cylinder length="0.016" radius="0.008" />
</geometry>
<material name="cleat_material">
<color rgba="0.301961 0.290196 0.262745 1.0"/>
</material>
</visual>
<!-- Shapes for cleat -->
<collision>
<origin xyz="0.052 0.0435 0.06597" rpy="-1.5708 -0.641317 -1.5708" />
<geometry>
<cylinder length="0.016" radius="0.008" />
</geometry>
</collision>
<!-- Shapes for cleat -->
<visual>
<origin xyz="0.052 0.0435 0.06597" rpy="-1.5708 -0.641317 -1.5708" />
<geometry>
<cylinder length="0.016" radius="0.008" />
</geometry>
<material name="cleat_material">
<color rgba="0.301961 0.290196 0.262745 1.0"/>
</material>
</visual>
<!-- Shapes for cleat -->
<collision>
<origin xyz="0.052 -0.0325 0.06597" rpy="1.5708 -0.367068 1.5708" />
<geometry>
<cylinder length="0.016" radius="0.008" />
</geometry>
</collision>
<!-- Shapes for cleat -->
<visual>
<origin xyz="0.052 -0.0325 0.06597" rpy="1.5708 -0.367068 1.5708" />
<geometry>
<cylinder length="0.016" radius="0.008" />
</geometry>
<material name="cleat_material">
<color rgba="0.301961 0.290196 0.262745 1.0"/>
</material>
</visual>
<!-- Shapes for cleat -->
<collision>
<origin xyz="0.052 0.0435 -0.07563" rpy="1.5708 -0.367068 1.5708" />
<geometry>
<cylinder length="0.016" radius="0.008" />
</geometry>
</collision>
<!-- Shapes for cleat -->
<visual>
<origin xyz="0.052 0.0435 -0.07563" rpy="1.5708 -0.367068 1.5708" />
<geometry>
<cylinder length="0.016" radius="0.008" />
</geometry>
<material name="cleat_material">
<color rgba="0.301961 0.290196 0.262745 1.0"/>
</material>
</visual>
<!-- Shapes for foot_plate -->
<collision>
<origin xyz="0.0415 0.0055 -0.00483" rpy="-1.5708 3.82914e-19 1.5708" />
<geometry>
<box size="0.092 0.1576 0.003" />
</geometry>
</collision>
<!-- Shapes for foot_plate -->
<visual>
<origin xyz="0.0415 0.0055 -0.00483" rpy="-1.5708 3.82914e-19 1.5708" />
<geometry>
<box size="0.092 0.1576 0.003" />
</geometry>
<material name="foot_plate_material">
<color rgba="0.301961 0.301961 0.301961 1.0"/>
</material>
</visual>
<inertial>
<origin xyz="0.0312589 0.00414298 0.000817452" rpy="0 0 0"/>
<mass value="0.32139" />
<inertia ixx="0.00102249" ixy="-8.69674e-06"  ixz="-2.18857e-05" iyy="0.0008644" iyz="-1.04075e-05" izz="0.000326573" />
</inertial>
</link>

<link name="left_foot">
<inertial>
<origin xyz="0 0 0" rpy="0 0 0" />
<mass value="1e-9" />
<inertia ixx="0" ixy="0" ixz="0" iyy="0" iyz="0" izz="0" />
</inertial>
</link>
<joint name="left_foot_frame" type="fixed">
<origin xyz="0.06 0.0055 -0.00483" rpy="3.04574e-27 -1.5708 0" />
<parent link="left_foot_asm" />
<child link="left_foot" />
<axis xyz="0 0 0"/>
</joint>

<joint name="left_ankle_roll" type="revolute">
<origin xyz="-2.22045e-16 0.0201 0.016" rpy="1.5708 -4.79033e-15 -3.14159" />
<parent link="mx106_with_u_l" />
<child link="left_foot_asm" />
<axis xyz="0 0 1"/>
<limit effort="10" velocity="6" lower="-0.785398" upper="0.785398"/>
<joint_properties friction="0.0"/>
</joint>

<joint name="left_ankle_pitch" type="revolute">
<origin xyz="-0.14 8.93643e-15 -4.26742e-15" rpy="6.00611e-15 -4.79034e-15 -6.38113e-14" />
<parent link="tibia_left_full" />
<child link="mx106_with_u_l" />
<axis xyz="0 0 1"/>
<limit effort="10" velocity="6" lower="-1.5708" upper="1.5708"/>
<joint_properties friction="0.0"/>
</joint>

<joint name="left_knee" type="revolute">
<origin xyz="4.11129e-16 0.14 -0.001" rpy="-1.18197e-15 -3.78471e-15 -1.5708" />
<parent link="thigh_horn_left" />
<child link="tibia_left_full" />
<axis xyz="0 0 1"/>
<limit effort="10" velocity="6" lower="0" upper="3.14159"/>
<joint_properties friction="0.0"/>
</joint>

<joint name="left_hip_pitch" type="revolute">
<origin xyz="-2.08167e-16 0.016 -0.0201" rpy="1.5708 -1.56511 8.40664e-12" />
<parent link="mx106_with_u_r" />
<child link="thigh_horn_left" />
<axis xyz="0 0 1"/>
<limit effort="10" velocity="6" lower="-1.5708" upper="1.5708"/>
<joint_properties friction="0.0"/>
</joint>

<joint name="left_hip_roll" type="revolute">
<origin xyz="-1.17961e-16 -0.0200991 -0.0604" rpy="1.5708 -1.5708 0" />
<parent link="u_hip_with_saver" />
<child link="mx106_with_u_r" />
<axis xyz="0 0 1"/>
<limit effort="10" velocity="6" lower="-0.523599" upper="0.523599"/>
<joint_properties friction="0.0"/>
</joint>

<joint name="left_hip_yaw" type="revolute">
<origin xyz="0.00586897 0.0464 -0.0411" rpy="1.38778e-17 -2.2295e-14 1.5708" />
<parent link="torso" />
<child link="u_hip_with_saver" />
<axis xyz="0 0 1"/>
<limit effort="10" velocity="6" lower="-1.0472" upper="1.0472"/>
<joint_properties friction="0.0"/>
</joint>

<link name="u_hip_with_saver_2">
<inertial>
<origin xyz="-6.0662e-11 0.00126178 -0.0329138" rpy="0 0 0"/>
<mass value="0.136031" />
<inertia ixx="0.000121591" ixy="4.65787e-14"  ixz="1.94175e-13" iyy="7.55159e-05" iyz="7.1306e-07" izz="5.66884e-05" />
</inertial>
</link>

<link name="mx106_with_u_l_2">
<!-- Shapes for inner -->
<collision>
<origin xyz="-0.0149141 0.0005 -0.01995" rpy="1.5708 1.5708 0" />
<geometry>
<box size="0.027 0.058 0.026" />
</geometry>
</collision>
<!-- Shapes for inner -->
<visual>
<origin xyz="-0.0149141 0.0005 -0.01995" rpy="1.5708 1.5708 0" />
<geometry>
<box size="0.027 0.058 0.026" />
</geometry>
<material name="inner_material">
<color rgba="0.647059 0.647059 0.647059 1.0"/>
</material>
</visual>
<!-- Shapes for inner -->
<collision>
<origin xyz="-0.0149141 -0.00015 -0.0799438" rpy="3.14159 -3.88578e-16 1.5708" />
<geometry>
<box size="0.027 0.058 0.026" />
</geometry>
</collision>
<!-- Shapes for inner -->
<visual>
<origin xyz="-0.0149141 -0.00015 -0.0799438" rpy="3.14159 -3.88578e-16 1.5708" />
<geometry>
<box size="0.027 0.058 0.026" />
</geometry>
<material name="inner_material">
<color rgba="0.647059 0.647059 0.647059 1.0"/>
</material>
</visual>
<inertial>
<origin xyz="-0.0129136 0.00100969 -0.0475018" rpy="0 0 0"/>
<mass value="0.421574" />
<inertia ixx="0.000440852" ixy="-7.05086e-07"  ixz="-4.25678e-06" iyy="0.000582098" iyz="-1.19495e-05" izz="0.000245751" />
</inertial>
</link>

<link name="thigh_horn_right">
<!-- Shapes for thigh_horn -->
<collision>
<origin xyz="-4.90141e-16 0.04 -0.0434" rpy="3.14159 2.22045e-16 -1.6603e-15" />
<geometry>
<box size="0.03 0.08 0.003" />
</geometry>
</collision>
<!-- Shapes for thigh_horn -->
<visual>
<origin xyz="-4.90141e-16 0.04 -0.0434" rpy="3.14159 2.22045e-16 -1.6603e-15" />
<geometry>
<box size="0.03 0.08 0.003" />
</geometry>
<material name="thigh_horn_material">
<color rgba="0.615686 0.811765 0.929412 1.0"/>
</material>
</visual>
<!-- Shapes for inner -->
<collision>
<origin xyz="-0.00015 0.12485 -0.0165" rpy="-3.84884e-16 -1.66533e-15 7.59603e-16" />
<geometry>
<box size="0.027 0.058 0.026" />
</geometry>
</collision>
<!-- Shapes for inner -->
<visual>
<origin xyz="-0.00015 0.12485 -0.0165" rpy="-3.84884e-16 -1.66533e-15 7.59603e-16" />
<geometry>
<box size="0.027 0.058 0.026" />
</geometry>
<material name="inner_material">
<color rgba="0.647059 0.647059 0.647059 1.0"/>
</material>
</visual>
<!-- Shapes for thigh_free_right -->
<collision>
<origin xyz="-2.02173e-16 0.036 0.0054" rpy="-6.10659e-16 -2.77556e-16 -7.47855e-17" />
<geometry>
<box size="0.03 0.08 0.003" />
</geometry>
</collision>
<!-- Shapes for thigh_free_right -->
<visual>
<origin xyz="-2.02173e-16 0.036 0.0054" rpy="-6.10659e-16 -2.77556e-16 -7.47855e-17" />
<geometry>
<box size="0.03 0.08 0.003" />
</geometry>
<material name="thigh_free_right_material">
<color rgba="0.615686 0.811765 0.929412 1.0"/>
</material>
</visual>
<inertial>
<origin xyz="-5.75727e-05 0.112829 -0.0162882" rpy="0 0 0"/>
<mass value="0.227111" />
<inertia ixx="0.000493196" ixy="-2.46452e-07"  ixz="-1.28619e-08" iyy="6.3394e-05" iyz="4.7784e-05" izz="0.000483708" />
</inertial>
</link>

<link name="tibia_right_full">
<!-- Shapes for tibia_right -->
<collision>
<origin xyz="-0.065 0.0005 0.0085" rpy="-3.14159 6.46989e-32 -1.00361e-18" />
<geometry>
<box size="0.15 0.035 0.003" />
</geometry>
</collision>
<!-- Shapes for tibia_right -->
<visual>
<origin xyz="-0.065 0.0005 0.0085" rpy="-3.14159 6.46989e-32 -1.00361e-18" />
<geometry>
<box size="0.15 0.035 0.003" />
</geometry>
<material name="tibia_right_material">
<color rgba="0.615686 0.811765 0.929412 1.0"/>
</material>
</visual>
<!-- Shapes for tibia_horn_side -->
<collision>
<origin xyz="-0.065 1.0586e-14 -0.0435" rpy="4.89608e-14 -1.70234e-13 3.05148e-14" />
<geometry>
<box size="0.15 0.035 0.003" />
</geometry>
</collision>
<!-- Shapes for tibia_horn_side -->
<visual>
<origin xyz="-0.065 1.0586e-14 -0.0435" rpy="4.89608e-14 -1.70234e-13 3.05148e-14" />
<geometry>
<box size="0.15 0.035 0.003" />
</geometry>
<material name="tibia_horn_side_material">
<color rgba="0.615686 0.811765 0.929412 1.0"/>
</material>
</visual>
<inertial>
<origin xyz="-0.07 -1.76067e-13 -0.00139217" rpy="0 0 0"/>
<mass value="0.0501468" />
<inertia ixx="1.6277e-05" ixy="-2.50302e-17"  ixz="1.29958e-13" iyy="0.000261996" iyz="-3.33222e-16" izz="0.000248145" />
</inertial>
</link>

<link name="mx106_with_u_r_2">
<!-- Shapes for inner -->
<collision>
<origin xyz="0.01515 -0.00015 -0.0165" rpy="2.47719e-15 -1.88738e-15 1.5708" />
<geometry>
<box size="0.027 0.058 0.026" />
</geometry>
</collision>
<!-- Shapes for inner -->
<visual>
<origin xyz="0.01515 -0.00015 -0.0165" rpy="2.47719e-15 -1.88738e-15 1.5708" />
<geometry>
<box size="0.027 0.058 0.026" />
</geometry>
<material name="inner_material">
<color rgba="0.647059 0.647059 0.647059 1.0"/>
</material>
</visual>
<!-- Shapes for inner -->
<collision>
<origin xyz="0.01515 -0.0598438 -0.01615" rpy="1.5708 -1.5708 0" />
<geometry>
<box size="0.027 0.058 0.026" />
</geometry>
</collision>
<!-- Shapes for inner -->
<visual>
<origin xyz="0.01515 -0.0598438 -0.01615" rpy="1.5708 -1.5708 0" />
<geometry>
<box size="0.027 0.058 0.026" />
</geometry>
<material name="inner_material">
<color rgba="0.647059 0.647059 0.647059 1.0"/>
</material>
</visual>
<inertial>
<origin xyz="0.0131496 -0.0274243 -0.0170322" rpy="0 0 0"/>
<mass value="0.421574" />
<inertia ixx="0.000440314" ixy="4.51991e-06"  ixz="-4.41959e-07" iyy="0.000245732" iyz="1.16474e-05" izz="0.000581579" />
</inertial>
</link>

<link name="right_foot_asm">
<!-- Shapes for cleat -->
<collision>
<origin xyz="0.052 -0.0435 -0.07563" rpy="-1.5708 1.29002 -1.5708" />
<geometry>
<cylinder length="0.016" radius="0.008" />
</geometry>
</collision>
<!-- Shapes for cleat -->
<visual>
<origin xyz="0.052 -0.0435 -0.07563" rpy="-1.5708 1.29002 -1.5708" />
<geometry>
<cylinder length="0.016" radius="0.008" />
</geometry>
<material name="cleat_material">
<color rgba="0.301961 0.290196 0.262745 1.0"/>
</material>
</visual>
<!-- Shapes for cleat -->
<collision>
<origin xyz="0.052 -0.0435 0.06597" rpy="-1.5708 -1.10788 -1.5708" />
<geometry>
<cylinder length="0.016" radius="0.008" />
</geometry>
</collision>
<!-- Shapes for cleat -->
<visual>
<origin xyz="0.052 -0.0435 0.06597" rpy="-1.5708 -1.10788 -1.5708" />
<geometry>
<cylinder length="0.016" radius="0.008" />
</geometry>
<material name="cleat_material">
<color rgba="0.301961 0.290196 0.262745 1.0"/>
</material>
</visual>
<!-- Shapes for cleat -->
<collision>
<origin xyz="0.052 0.0325 -0.07563" rpy="-1.5708 1.29002 -1.5708" />
<geometry>
<cylinder length="0.016" radius="0.008" />
</geometry>
</collision>
<!-- Shapes for cleat -->
<visual>
<origin xyz="0.052 0.0325 -0.07563" rpy="-1.5708 1.29002 -1.5708" />
<geometry>
<cylinder length="0.016" radius="0.008" />
</geometry>
<material name="cleat_material">
<color rgba="0.301961 0.290196 0.262745 1.0"/>
</material>
</visual>
<!-- Shapes for cleat -->
<collision>
<origin xyz="0.052 0.0325 0.06597" rpy="-1.5708 1.29002 -1.5708" />
<geometry>
<cylinder length="0.016" radius="0.008" />
</geometry>
</collision>
<!-- Shapes for cleat -->
<visual>
<origin xyz="0.052 0.0325 0.06597" rpy="-1.5708 1.29002 -1.5708" />
<geometry>
<cylinder length="0.016" radius="0.008" />
</geometry>
<material name="cleat_material">
<color rgba="0.301961 0.290196 0.262745 1.0"/>
</material>
</visual>
<!-- Shapes for foot_plate -->
<collision>
<origin xyz="0.0415 -0.0055 -0.00483" rpy="-1.5708 -2.99786e-19 1.5708" />
<geometry>
<box size="0.092 0.1576 0.003" />
</geometry>
</collision>
<!-- Shapes for foot_plate -->
<visual>
<origin xyz="0.0415 -0.0055 -0.00483" rpy="-1.5708 -2.99786e-19 1.5708" />
<geometry>
<box size="0.092 0.1576 0.003" />
</geometry>
<material name="foot_plate_material">
<color rgba="0.301961 0.301961 0.301961 1.0"/>
</material>
</visual>
<inertial>
<origin xyz="0.0312589 -0.00414302 0.000817452" rpy="0 0 0"/>
<mass value="0.32139" />
<inertia ixx="0.00102249" ixy="8.69712e-06"  ixz="-2.18857e-05" iyy="0.0008644" iyz="1.04066e-05" izz="0.000326572" />
</inertial>
</link>

<link name="right_foot">
<inertial>
<origin xyz="0 0 0" rpy="0 0 0" />
<mass value="1e-9" />
<inertia ixx="0" ixy="0" ixz="0" iyy="0" iyz="0" izz="0" />
</inertial>
</link>
<joint name="right_foot_frame" type="fixed">
<origin xyz="0.06 -0.0055 -0.00483" rpy="-1.661e-16 -1.5708 0" />
<parent link="right_foot_asm" />
<child link="right_foot" />
<axis xyz="0 0 0"/>
</joint>

<joint name="right_ankle_roll" type="revolute">
<origin xyz="2.77556e-16 0.0201 -0.016" rpy="1.5708 -1.43631e-15 3.14159" />
<parent link="mx106_with_u_r_2" />
<child link="right_foot_asm" />
<axis xyz="0 0 1"/>
<limit effort="10" velocity="6" lower="-0.785398" upper="0.785398"/>
<joint_properties friction="0.0"/>
</joint>

<joint name="right_ankle_pitch" type="revolute">
<origin xyz="-0.14 -1.56316e-14 -2.08167e-17" rpy="1.46503e-15 -5.21573e-15 -5.73004e-19" />
<parent link="tibia_right_full" />
<child link="mx106_with_u_r_2" />
<axis xyz="0 0 1"/>
<limit effort="10" velocity="6" lower="-1.5708" upper="1.5708"/>
<joint_properties friction="0.0"/>
</joint>

<joint name="right_knee" type="revolute">
<origin xyz="3.05311e-16 0.14 -2.01748e-14" rpy="-5.68163e-14 -6.87273e-16 -1.5708" />
<parent link="thigh_horn_right" />
<child link="tibia_right_full" />
<axis xyz="0 0 1"/>
<limit effort="10" velocity="6" lower="-0" upper="3.14159"/>
<joint_properties friction="0.0"/>
</joint>

<joint name="right_hip_pitch" type="revolute">
<origin xyz="0.000235943 -0.016 -0.0201" rpy="1.5708 -1.56511 -2.04106e-13" />
<parent link="mx106_with_u_l_2" />
<child link="thigh_horn_right" />
<axis xyz="0 0 1"/>
<limit effort="10" velocity="6" lower="-1.5708" upper="1.5708"/>
<joint_properties friction="0.0"/>
</joint>

<joint name="right_hip_roll" type="revolute">
<origin xyz="4.85723e-17 -0.0200991 -0.0604" rpy="1.5708 -1.5708 0" />
<parent link="u_hip_with_saver_2" />
<child link="mx106_with_u_l_2" />
<axis xyz="0 0 1"/>
<limit effort="10" velocity="6" lower="-0.523599" upper="0.523599"/>
<joint_properties friction="0.0"/>
</joint>

<joint name="right_hip_yaw" type="revolute">
<origin xyz="0.00586897 -0.0464 -0.0411" rpy="1.08941e-15 -2.22601e-15 1.5708" />
<parent link="torso" />
<child link="u_hip_with_saver_2" />
<axis xyz="0 0 1"/>
<limit effort="10" velocity="6" lower="-1.0472" upper="1.0472"/>
<joint_properties friction="0.0"/>
</joint>

<link name="u_neck">
<!-- Shapes for u_base_64 -->
<collision>
<origin xyz="-4.01637e-33 1.92593e-35 0.003125" rpy="3.14159 -1.29581e-30 8.40232e-30" />
<geometry>
<box size="0.049 0.03 0.00625" />
</geometry>
</collision>
<!-- Shapes for u_base_64 -->
<visual>
<origin xyz="-4.01637e-33 1.92593e-35 0.003125" rpy="3.14159 -1.29581e-30 8.40232e-30" />
<geometry>
<box size="0.049 0.03 0.00625" />
</geometry>
<material name="u_base_64_material">
<color rgba="0.301961 0.301961 0.301961 1.0"/>
</material>
</visual>
<!-- Shapes for u_side_neck -->
<collision>
<origin xyz="0.025 -3.04572e-15 0.032901" rpy="1.5708 -1.36551e-14 -1.5708" />
<geometry>
<box size="0.03 0.065802 0.003" />
</geometry>
</collision>
<!-- Shapes for u_side_neck -->
<visual>
<origin xyz="0.025 -3.04572e-15 0.032901" rpy="1.5708 -1.36551e-14 -1.5708" />
<geometry>
<box size="0.03 0.065802 0.003" />
</geometry>
<material name="u_side_neck_material">
<color rgba="0.301961 0.301961 0.301961 1.0"/>
</material>
</visual>
<!-- Shapes for u_side_neck -->
<collision>
<origin xyz="-0.025 2.111e-15 0.032901" rpy="1.5708 1.47653e-14 1.5708" />
<geometry>
<box size="0.03 0.065802 0.003" />
</geometry>
</collision>
<!-- Shapes for u_side_neck -->
<visual>
<origin xyz="-0.025 2.111e-15 0.032901" rpy="1.5708 1.47653e-14 1.5708" />
<geometry>
<box size="0.03 0.065802 0.003" />
</geometry>
<material name="u_side_neck_material">
<color rgba="0.301961 0.301961 0.301961 1.0"/>
</material>
</visual>
<inertial>
<origin xyz="-7.01198e-17 -2.25658e-16 0.0206334" rpy="0 0 0"/>
<mass value="0.0544799" />
<inertia ixx="3.05787e-05" ixy="-1.35944e-11"  ixz="-1.78883e-19" iyy="5.16952e-05" iyz="4.37148e-20" izz="2.98525e-05" />
</inertial>
</link>

<link name="head__field_of_view_false">
<!-- Shapes for mx-64at_ar -->
<collision>
<origin xyz="2.00525e-16 -0.01755 -0.0235" rpy="-3.09954e-16 1.24585e-15 1.33949e-14" />
<geometry>
<box size="0.0402 0.0611 0.041" />
</geometry>
</collision>
<!-- Shapes for mx-64at_ar -->
<visual>
<origin xyz="2.00525e-16 -0.01755 -0.0235" rpy="-3.09954e-16 1.24585e-15 1.33949e-14" />
<geometry>
<box size="0.0402 0.0611 0.041" />
</geometry>
<material name="mx-64at_ar_material">
<color rgba="0.168627 0.168627 0.168627 1.0"/>
</material>
</visual>
<!-- Shapes for head_plate -->
<collision>
<origin xyz="-0.0238 0.0365 -0.042" rpy="3.14159 -7.46249e-16 -3.14159" />
<geometry>
<cylinder length="0.003" radius="0.0235" />
</geometry>
</collision>
<collision>
<origin xyz="0.01 0.0365 -0.042" rpy="3.14159 -7.46249e-16 -3.14159" />
<geometry>
<box size="0.0616 0.047 0.003" />
</geometry>
</collision>
<!-- Shapes for head_plate -->
<visual>
<origin xyz="-0.0238 0.0365 -0.042" rpy="3.14159 -7.46249e-16 -3.14159" />
<geometry>
<cylinder length="0.003" radius="0.0235" />
</geometry>
<material name="head_plate_material">
<color rgba="0.701961 0.682353 0.623529 1.0"/>
</material>
</visual>
<visual>
<origin xyz="0.01 0.0365 -0.042" rpy="3.14159 -7.46249e-16 -3.14159" />
<geometry>
<box size="0.0616 0.047 0.003" />
</geometry>
<material name="head_plate_material">
<color rgba="0.701961 0.682353 0.623529 1.0"/>
</material>
</visual>
<!-- Shapes for head_plate -->
<collision>
<origin xyz="-0.0238 0.0365 -0.005" rpy="-3.14159 -8.57271e-16 -3.14159" />
<geometry>
<cylinder length="0.003" radius="0.0235" />
</geometry>
</collision>
<collision>
<origin xyz="0.01 0.0365 -0.005" rpy="-3.14159 -8.57271e-16 -3.14159" />
<geometry>
<box size="0.0616 0.047 0.003" />
</geometry>
</collision>
<!-- Shapes for head_plate -->
<visual>
<origin xyz="-0.0238 0.0365 -0.005" rpy="-3.14159 -8.57271e-16 -3.14159" />
<geometry>
<cylinder length="0.003" radius="0.0235" />
</geometry>
<material name="head_plate_material">
<color rgba="0.701961 0.682353 0.623529 1.0"/>
</material>
</visual>
<visual>
<origin xyz="0.01 0.0365 -0.005" rpy="-3.14159 -8.57271e-16 -3.14159" />
<geometry>
<box size="0.0616 0.047 0.003" />
</geometry>
<material name="head_plate_material">
<color rgba="0.701961 0.682353 0.623529 1.0"/>
</material>
</visual>
<inertial>
<origin xyz="0.00875694 0.0531205 -0.051962" rpy="0 0 0"/>
<mass value="0.249938" />
<inertia ixx="0.00903073" ixy="-0.00124784"  ixz="0.000737453" iyy="0.0025794" iyz="0.00384551" izz="0.00701973" />
</inertial>
</link>

<link name="camera">
<inertial>
<origin xyz="0 0 0" rpy="0 0 0" />
<mass value="1e-9" />
<inertia ixx="0" ixy="0" ixz="0" iyy="0" iyz="0" izz="0" />
</inertial>
</link>
<joint name="camera_frame" type="fixed">
<origin xyz="-0.024933 0.0335 -0.0235" rpy="3.14159 1.5708 0" />
<parent link="head__field_of_view_false" />
<child link="camera" />
<axis xyz="0 0 0"/>
</joint>

<joint name="head_pitch" type="revolute">
<origin xyz="-0.0235 1.63064e-15 0.058302" rpy="1.5708 -5.26755e-18 -1.5708" />
<parent link="u_neck" />
<child link="head__field_of_view_false" />
<axis xyz="0 0 1"/>
<limit effort="10" velocity="6" lower="-0.785398" upper="1.5708"/>
<joint_properties friction="0.0"/>
</joint>

<joint name="head_yaw" type="revolute">
<origin xyz="0.035869 2.46254e-15 0.1595" rpy="4.02456e-16 -2.25859e-14 -1.5708" />
<parent link="torso" />
<child link="u_neck" />
<axis xyz="0 0 1"/>
<limit effort="10" velocity="6" lower="-2.0944" upper="2.0944"/>
<joint_properties friction="0.0"/>
</joint>


</robot>
