<robot name="onshape">
<link name="torso">
<!-- Shapes for x_plate -->
<collision>
<origin xyz="0.057868973494375253175 3.8152671181343391224e-15 0.059499999999999941824" rpy="1.5707963267948927832 -3.7125353914934716787e-15 1.5707963267949058839" />
<geometry>
<box size="0.13300000000000000711 0.11300000000000000322 0.0060000000000000001249" />
</geometry>
</collision>
<!-- Shapes for x_plate -->
<visual>
<origin xyz="0.057868973494375253175 3.8152671181343391224e-15 0.059499999999999941824" rpy="1.5707963267948927832 -3.7125353914934716787e-15 1.5707963267949058839" />
<geometry>
<box size="0.13300000000000000711 0.11300000000000000322 0.0060000000000000001249" />
</geometry>
<material name="x_plate_material">
<color rgba="0.26274509803921569651 0.28235294117647058432 0.30196078431372547213 1.0"/>
</material>
</visual>
<!-- Shapes for mx-64at_ar -->
<collision>
<origin xyz="0.02341897349435649936 -0.046400000000006262624 -0.017000000000000247552" rpy="-3.1415926535897926719 2.0394558334225169899e-15 -1.570796326795006026" />
<geometry>
<box size="0.040199999999999999623 0.061100000000000001532 0.041000000000000001721" />
</geometry>
</collision>
<!-- Shapes for mx-64at_ar -->
<visual>
<origin xyz="0.02341897349435649936 -0.046400000000006262624 -0.017000000000000247552" rpy="-3.1415926535897926719 2.0394558334225169899e-15 -1.570796326795006026" />
<geometry>
<box size="0.040199999999999999623 0.061100000000000001532 0.041000000000000001721" />
</geometry>
<material name="mx-64at_ar_material">
<color rgba="0.1686274509803921684 0.1686274509803921684 0.1686274509803921684 1.0"/>
</material>
</visual>
<!-- Shapes for mx-64at_ar -->
<collision>
<origin xyz="0.013318973494383667261 0.056000000000007335577 0.14300000000000920308" rpy="-1.5707963267949880404 -1.5707963267948745756 0" />
<geometry>
<box size="0.040199999999999999623 0.061100000000000001532 0.041000000000000001721" />
</geometry>
</collision>
<!-- Shapes for mx-64at_ar -->
<visual>
<origin xyz="0.013318973494383667261 0.056000000000007335577 0.14300000000000920308" rpy="-1.5707963267949880404 -1.5707963267948745756 0" />
<geometry>
<box size="0.040199999999999999623 0.061100000000000001532 0.041000000000000001721" />
</geometry>
<material name="mx-64at_ar_material">
<color rgba="0.1686274509803921684 0.1686274509803921684 0.1686274509803921684 1.0"/>
</material>
</visual>
<!-- Shapes for x_plate -->
<collision>
<origin xyz="-0.057131026505643667246 7.7808727397929366905e-15 0.059499999999999671207" rpy="1.5707963267948952257 -1.2157103114052321777e-15 1.5707963267949001107" />
<geometry>
<box size="0.13300000000000000711 0.11300000000000000322 0.0060000000000000001249" />
</geometry>
</collision>
<!-- Shapes for x_plate -->
<visual>
<origin xyz="-0.057131026505643667246 7.7808727397929366905e-15 0.059499999999999671207" rpy="1.5707963267948952257 -1.2157103114052321777e-15 1.5707963267949001107" />
<geometry>
<box size="0.13300000000000000711 0.11300000000000000322 0.0060000000000000001249" />
</geometry>
<material name="x_plate_material">
<color rgba="0.26274509803921569651 0.28235294117647058432 0.30196078431372547213 1.0"/>
</material>
</visual>
<!-- Shapes for mx-64at_ar -->
<collision>
<origin xyz="0.023418973494361536997 0.046400000000008503886 -0.01700000000000032388" rpy="-3.1415926535897926719 2.0256134443711579168e-15 -1.570796326795006026" />
<geometry>
<box size="0.040199999999999999623 0.061100000000000001532 0.041000000000000001721" />
</geometry>
</collision>
<!-- Shapes for mx-64at_ar -->
<visual>
<origin xyz="0.023418973494361536997 0.046400000000008503886 -0.01700000000000032388" rpy="-3.1415926535897926719 2.0256134443711579168e-15 -1.570796326795006026" />
<geometry>
<box size="0.040199999999999999623 0.061100000000000001532 0.041000000000000001721" />
</geometry>
<material name="mx-64at_ar_material">
<color rgba="0.1686274509803921684 0.1686274509803921684 0.1686274509803921684 1.0"/>
</material>
</visual>
<!-- Shapes for mx-64at_ar -->
<collision>
<origin xyz="0.018318973494361519283 5.2069396705009071706e-15 0.13599999999999945466" rpy="4.0245584642693617077e-16 1.0634679180433978839e-14 -1.570796326795006026" />
<geometry>
<box size="0.040199999999999999623 0.061100000000000001532 0.041000000000000001721" />
</geometry>
</collision>
<!-- Shapes for mx-64at_ar -->
<visual>
<origin xyz="0.018318973494361519283 5.2069396705009071706e-15 0.13599999999999945466" rpy="4.0245584642693617077e-16 1.0634679180433978839e-14 -1.570796326795006026" />
<geometry>
<box size="0.040199999999999999623 0.061100000000000001532 0.041000000000000001721" />
</geometry>
<material name="mx-64at_ar_material">
<color rgba="0.1686274509803921684 0.1686274509803921684 0.1686274509803921684 1.0"/>
</material>
</visual>
<!-- Shapes for mx-64at_ar -->
<collision>
<origin xyz="0.013318973494376978167 -0.055999999999997503164 0.14300000000000984146" rpy="1.5707963267949873742 1.5707963267948845676 0" />
<geometry>
<box size="0.040199999999999999623 0.061100000000000001532 0.041000000000000001721" />
</geometry>
</collision>
<!-- Shapes for mx-64at_ar -->
<visual>
<origin xyz="0.013318973494376978167 -0.055999999999997503164 0.14300000000000984146" rpy="1.5707963267949873742 1.5707963267948845676 0" />
<geometry>
<box size="0.040199999999999999623 0.061100000000000001532 0.041000000000000001721" />
</geometry>
<material name="mx-64at_ar_material">
<color rgba="0.1686274509803921684 0.1686274509803921684 0.1686274509803921684 1.0"/>
</material>
</visual>
<inertial>
<origin xyz="0.0030062230546193989891 0.001852593969069586113 0.068720420317901154128" rpy="0 0 0"/>
<mass value="2.3224634991401664763" />
<inertia ixx="0.011224307318969789157" ixy="-4.8566894310192732903e-06"  ixz="0.00021812167095550168291" iyy="0.010571052859840234656" iyz="-4.7744972223613473764e-05" izz="0.0072547982502737589847" />
</inertial>
</link>

<link name="head_base">
<inertial>
<origin xyz="0 0 0" rpy="0 0 0" />
<mass value="1e-9" />
<inertia ixx="0" ixy="0" ixz="0" iyy="0" iyz="0" izz="0" />
</inertial>
</link>
<joint name="head_base_frame" type="fixed">
<origin xyz="0.035868973494361730547 2.8785898342325425989e-15 0.15950000000001055001" rpy="3.7964142151183067762e-14 -9.9503738582029639158e-15 -1.0422282733566275005e-13" />
<parent link="torso" />
<child link="head_base" />
<axis xyz="0 0 0"/>
</joint>

<link name="trunk">
<inertial>
<origin xyz="0 0 0" rpy="0 0 0" />
<mass value="1e-9" />
<inertia ixx="0" ixy="0" ixz="0" iyy="0" iyz="0" izz="0" />
</inertial>
</link>
<joint name="trunk_frame" type="fixed">
<origin xyz="0.0058680275433158485265 -3.9238251073735071353e-15 -0.10150000000000060363" rpy="5.5093833584565697626e-15 4.4079575231487197359e-25 -5.958092587816837932e-14" />
<parent link="torso" />
<child link="trunk" />
<axis xyz="0 0 0"/>
</joint>

<link name="u_shoulder">
<!-- Shapes for u_base_64 -->
<collision>
<origin xyz="-7.683691433397222108e-34 2.7755575615628910429e-17 -0.0031250000000000001735" rpy="-4.2891166020857469733e-30 6.3551188108425741845e-31 6.0397163055983716352e-31" />
<geometry>
<box size="0.049000000000000001887 0.02999999999999999889 0.0062500000000000003469" />
</geometry>
</collision>
<!-- Shapes for u_base_64 -->
<visual>
<origin xyz="-7.683691433397222108e-34 2.7755575615628910429e-17 -0.0031250000000000001735" rpy="-4.2891166020857469733e-30 6.3551188108425741845e-31 6.0397163055983716352e-31" />
<geometry>
<box size="0.049000000000000001887 0.02999999999999999889 0.0062500000000000003469" />
</geometry>
<material name="u_base_64_material">
<color rgba="0.30196078431372547213 0.30196078431372547213 0.30196078431372547213 1.0"/>
</material>
</visual>
<inertial>
<origin xyz="-1.4156304034451634546e-15 -0.0056623385441344998778 -0.015967577811135641452" rpy="0 0 0"/>
<mass value="0.057010148283040865125" />
<inertia ixx="2.217583106259896723e-05" ixy="-1.9504257099510350151e-19"  ixz="9.3427734082149327399e-19" iyy="4.0331441206531803262e-05" iyz="-6.1070324355848154338e-06" izz="3.5862924589732192513e-05" />
</inertial>
</link>

<link name="right_humerus">
<!-- Shapes for mx-64at_ar -->
<collision>
<origin xyz="2.7516877665335960954e-17 -0.017549999999999961464 -0.023500000000009999002" rpy="-7.7715611723757181158e-16 5.5511151231260292212e-17 -4.4408920985010856732e-16" />
<geometry>
<box size="0.040199999999999999623 0.061100000000000001532 0.041000000000000001721" />
</geometry>
</collision>
<!-- Shapes for mx-64at_ar -->
<visual>
<origin xyz="2.7516877665335960954e-17 -0.017549999999999961464 -0.023500000000009999002" rpy="-7.7715611723757181158e-16 5.5511151231260292212e-17 -4.4408920985010856732e-16" />
<geometry>
<box size="0.040199999999999999623 0.061100000000000001532 0.041000000000000001721" />
</geometry>
<material name="mx-64at_ar_material">
<color rgba="0.1686274509803921684 0.1686274509803921684 0.1686274509803921684 1.0"/>
</material>
</visual>
<inertial>
<origin xyz="0.00089663189558004789421 -0.050616829208722256828 -0.024227783076275471313" rpy="0 0 0"/>
<mass value="0.21891648912829692053" />
<inertia ixx="0.00062836186142250745942" ixy="1.4577972502765653838e-05"  ixz="-1.3477156532987228526e-06" iyy="6.7719613468240121706e-05" iyz="-4.0514772324774851763e-05" izz="0.00061652046704584271414" />
</inertial>
</link>

<link name="radius_v2">
<!-- Shapes for hand -->
<collision>
<origin xyz="-3.4569569429266491135e-17 0.12759999999999441234 0.042000000000008017031" rpy="3.141592653589793116 2.2204460492394213769e-16 1.57079632679489678" />
<geometry>
<cylinder length="0.0030000000000000000625" radius="0.040000000000000000833" />
</geometry>
</collision>
<collision>
<origin xyz="-1.8221668618371709475e-17 0.053975599999997639356 0.042000000000008030909" rpy="3.141592653589793116 2.2204460492394213769e-16 1.57079632679489678" />
<geometry>
<box size="0.077551200000000000689 0.041200000000000000511 0.0030000000000000000625" />
</geometry>
</collision>
<!-- Shapes for hand -->
<visual>
<origin xyz="-3.4569569429266491135e-17 0.12759999999999441234 0.042000000000008017031" rpy="3.141592653589793116 2.2204460492394213769e-16 1.57079632679489678" />
<geometry>
<cylinder length="0.0030000000000000000625" radius="0.040000000000000000833" />
</geometry>
<material name="hand_material">
<color rgba="0.30196078431372547213 0.30196078431372547213 0.30196078431372547213 1.0"/>
</material>
</visual>
<visual>
<origin xyz="-1.8221668618371709475e-17 0.053975599999997639356 0.042000000000008030909" rpy="3.141592653589793116 2.2204460492394213769e-16 1.57079632679489678" />
<geometry>
<box size="0.077551200000000000689 0.041200000000000000511 0.0030000000000000000625" />
</geometry>
<material name="hand_material">
<color rgba="0.30196078431372547213 0.30196078431372547213 0.30196078431372547213 1.0"/>
</material>
</visual>
<!-- Shapes for hand -->
<collision>
<origin xyz="-1.5265566588595971456e-16 0.12759999999999488418 0.0050000000000096495034" rpy="-3.141592653589793116 4.4408920984970245186e-16 1.570796326794896558" />
<geometry>
<cylinder length="0.0030000000000000000625" radius="0.040000000000000000833" />
</geometry>
</collision>
<collision>
<origin xyz="-1.5265566588594263079e-16 0.053975599999995946265 0.0050000000000096815958" rpy="-3.141592653589793116 4.4408920984970245186e-16 1.570796326794896558" />
<geometry>
<box size="0.077551200000000000689 0.041200000000000000511 0.0030000000000000000625" />
</geometry>
</collision>
<!-- Shapes for hand -->
<visual>
<origin xyz="-1.5265566588595971456e-16 0.12759999999999488418 0.0050000000000096495034" rpy="-3.141592653589793116 4.4408920984970245186e-16 1.570796326794896558" />
<geometry>
<cylinder length="0.0030000000000000000625" radius="0.040000000000000000833" />
</geometry>
<material name="hand_material">
<color rgba="0.30196078431372547213 0.30196078431372547213 0.30196078431372547213 1.0"/>
</material>
</visual>
<visual>
<origin xyz="-1.5265566588594263079e-16 0.053975599999995946265 0.0050000000000096815958" rpy="-3.141592653589793116 4.4408920984970245186e-16 1.570796326794896558" />
<geometry>
<box size="0.077551200000000000689 0.041200000000000000511 0.0030000000000000000625" />
</geometry>
<material name="hand_material">
<color rgba="0.30196078431372547213 0.30196078431372547213 0.30196078431372547213 1.0"/>
</material>
</visual>
<!-- Shapes for mx-64at_ar -->
<collision>
<origin xyz="4.0162317915689727837e-18 0.017549999999999239819 0.023500000000008885309" rpy="3.141592653589793116 2.7755575615626331224e-17 1.1102230246250490581e-16" />
<geometry>
<box size="0.040199999999999999623 0.061100000000000001532 0.041000000000000001721" />
</geometry>
</collision>
<!-- Shapes for mx-64at_ar -->
<visual>
<origin xyz="4.0162317915689727837e-18 0.017549999999999239819 0.023500000000008885309" rpy="3.141592653589793116 2.7755575615626331224e-17 1.1102230246250490581e-16" />
<geometry>
<box size="0.040199999999999999623 0.061100000000000001532 0.041000000000000001721" />
</geometry>
<material name="mx-64at_ar_material">
<color rgba="0.1686274509803921684 0.1686274509803921684 0.1686274509803921684 1.0"/>
</material>
</visual>
<inertial>
<origin xyz="9.007860998898360044e-05 0.050592813860685190153 0.022164128160994316791" rpy="0 0 0"/>
<mass value="0.22758681850404099967" />
<inertia ixx="0.00063622372865129283703" ixy="6.8818031269179995101e-07"  ixz="-6.3997466140504257857e-07" iyy="0.00011529484226278510848" iyz="-1.2452787769692203384e-05" izz="0.00065540810703733126587" />
</inertial>
</link>

<joint name="right_elbow" type="revolute">
<origin xyz="-0.023500000000009860224 -0.14200000000001986034 -0.0024999999999998911981" rpy="3.141592653589793116 -1.5707963267948954478 0" />
<parent link="right_humerus" />
<child link="radius_v2" />
<axis xyz="0 0 1"/>
<limit effort="10" velocity="6" lower="-2.7925268031909271649" upper="-0"/>
<joint_properties friction="0.0"/>
</joint>

<joint name="right_shoulder_roll" type="revolute">
<origin xyz="-0.023500000000005155654 -0.029999999999999651945 -0.034999999999995798361" rpy="-8.8817841970007218144e-16 -1.5707963267948961139 0" />
<parent link="u_shoulder" />
<child link="right_humerus" />
<axis xyz="0 0 1"/>
<limit effort="10" velocity="6" lower="-1.570796326794896558" upper="0.087266462599716473902"/>
<joint_properties friction="0.0"/>
</joint>

<joint name="right_shoulder_pitch" type="revolute">
<origin xyz="0.03086897349437638105 -0.079500000000014198198 0.14300000000001014677" rpy="1.5707963267948708008 -1.8374191057546290257e-14 3.141592653589783346" />
<parent link="torso" />
<child link="u_shoulder" />
<axis xyz="0 0 1"/>
<limit effort="10" velocity="6" lower="-2.1816615649929120835" upper="2.1816615649929120835"/>
<joint_properties friction="0.0"/>
</joint>

<link name="u_shoulder_2">
<!-- Shapes for u_base_64 -->
<collision>
<origin xyz="-4.3279906184833854376e-34 1.4489739225525392283e-33 0.0031250000000000001735" rpy="3.141592653589793116 1.3849569915611280084e-31 3.6977854932234928379e-31" />
<geometry>
<box size="0.049000000000000001887 0.02999999999999999889 0.0062500000000000003469" />
</geometry>
</collision>
<!-- Shapes for u_base_64 -->
<visual>
<origin xyz="-4.3279906184833854376e-34 1.4489739225525392283e-33 0.0031250000000000001735" rpy="3.141592653589793116 1.3849569915611280084e-31 3.6977854932234928379e-31" />
<geometry>
<box size="0.049000000000000001887 0.02999999999999999889 0.0062500000000000003469" />
</geometry>
<material name="u_base_64_material">
<color rgba="0.30196078431372547213 0.30196078431372547213 0.30196078431372547213 1.0"/>
</material>
</visual>
<inertial>
<origin xyz="-5.6553899744685867943e-16 0.0056623385441345952876 0.015967577811136644123" rpy="0 0 0"/>
<mass value="0.057010148283040872064" />
<inertia ixx="2.2175831062600071761e-05" ixy="1.1318477757685588281e-19"  ixz="3.1154930591197234346e-19" iyy="4.0331441206530739389e-05" iyz="-6.1070324355849899225e-06" izz="3.5862924589729902136e-05" />
</inertial>
</link>

<link name="left_humerus">
<!-- Shapes for mx-64at_ar -->
<collision>
<origin xyz="6.8195449287555767402e-18 -0.017549999999999472272 -0.023500000000009856754" rpy="6.1503598206559714161e-16 1.3981644317489581227e-29 1.0547118733937297e-15" />
<geometry>
<box size="0.040199999999999999623 0.061100000000000001532 0.041000000000000001721" />
</geometry>
</collision>
<!-- Shapes for mx-64at_ar -->
<visual>
<origin xyz="6.8195449287555767402e-18 -0.017549999999999472272 -0.023500000000009856754" rpy="6.1503598206559714161e-16 1.3981644317489581227e-29 1.0547118733937297e-15" />
<geometry>
<box size="0.040199999999999999623 0.061100000000000001532 0.041000000000000001721" />
</geometry>
<material name="mx-64at_ar_material">
<color rgba="0.1686274509803921684 0.1686274509803921684 0.1686274509803921684 1.0"/>
</material>
</visual>
<inertial>
<origin xyz="-0.00070933944006916320457 -0.050616829199538276862 -0.024244762808353224198" rpy="0 0 0"/>
<mass value="0.21891648912829692053" />
<inertia ixx="0.00062835638739088537415" ixy="-1.5955317761662271233e-05"  ixz="2.5456885382785088443e-06" iyy="6.7779986888156728794e-05" iyz="-4.0495008981122822831e-05" izz="0.00061658631376239672866" />
</inertial>
</link>

<link name="radius_v2_2">
<!-- Shapes for mx-64at_ar -->
<collision>
<origin xyz="-3.8968828164355858955e-18 -0.017549999999999742889 -0.023500000000009985124" rpy="-7.9901304630483858735e-17 1.1450494996286307426e-16 1.1102230246243865382e-16" />
<geometry>
<box size="0.040199999999999999623 0.061100000000000001532 0.041000000000000001721" />
</geometry>
</collision>
<!-- Shapes for mx-64at_ar -->
<visual>
<origin xyz="-3.8968828164355858955e-18 -0.017549999999999742889 -0.023500000000009985124" rpy="-7.9901304630483858735e-17 1.1450494996286307426e-16 1.1102230246243865382e-16" />
<geometry>
<box size="0.040199999999999999623 0.061100000000000001532 0.041000000000000001721" />
</geometry>
<material name="mx-64at_ar_material">
<color rgba="0.1686274509803921684 0.1686274509803921684 0.1686274509803921684 1.0"/>
</material>
</visual>
<!-- Shapes for hand -->
<collision>
<origin xyz="2.0845238779022407578e-16 -0.12759999999999663278 -0.0050000000000099426717" rpy="-3.5198380650383976784e-16 -7.9901304630480395142e-17 -1.57079632679489678" />
<geometry>
<cylinder length="0.0030000000000000000625" radius="0.040000000000000000833" />
</geometry>
</collision>
<collision>
<origin xyz="2.2480028860107225301e-16 -0.0539755999999977365 -0.0050000000000099478759" rpy="-3.5198380650383976784e-16 -7.9901304630480395142e-17 -1.57079632679489678" />
<geometry>
<box size="0.077551200000000000689 0.041200000000000000511 0.0030000000000000000625" />
</geometry>
</collision>
<!-- Shapes for hand -->
<visual>
<origin xyz="2.0845238779022407578e-16 -0.12759999999999663278 -0.0050000000000099426717" rpy="-3.5198380650383976784e-16 -7.9901304630480395142e-17 -1.57079632679489678" />
<geometry>
<cylinder length="0.0030000000000000000625" radius="0.040000000000000000833" />
</geometry>
<material name="hand_material">
<color rgba="0.30196078431372547213 0.30196078431372547213 0.30196078431372547213 1.0"/>
</material>
</visual>
<visual>
<origin xyz="2.2480028860107225301e-16 -0.0539755999999977365 -0.0050000000000099478759" rpy="-3.5198380650383976784e-16 -7.9901304630480395142e-17 -1.57079632679489678" />
<geometry>
<box size="0.077551200000000000689 0.041200000000000000511 0.0030000000000000000625" />
</geometry>
<material name="hand_material">
<color rgba="0.30196078431372547213 0.30196078431372547213 0.30196078431372547213 1.0"/>
</material>
</visual>
<!-- Shapes for hand -->
<collision>
<origin xyz="-2.9113822445302313372e-16 -0.12759999999999635523 -0.042000000000009987677" rpy="-1.4218472271716742932e-16 -7.9901304630480062342e-17 -1.57079632679489678" />
<geometry>
<cylinder length="0.0030000000000000000625" radius="0.040000000000000000833" />
</geometry>
</collision>
<collision>
<origin xyz="-2.870512492503005384e-16 -0.053975599999998624678 -0.042000000000009994616" rpy="-1.4218472271716742932e-16 -7.9901304630480062342e-17 -1.57079632679489678" />
<geometry>
<box size="0.077551200000000000689 0.041200000000000000511 0.0030000000000000000625" />
</geometry>
</collision>
<!-- Shapes for hand -->
<visual>
<origin xyz="-2.9113822445302313372e-16 -0.12759999999999635523 -0.042000000000009987677" rpy="-1.4218472271716742932e-16 -7.9901304630480062342e-17 -1.57079632679489678" />
<geometry>
<cylinder length="0.0030000000000000000625" radius="0.040000000000000000833" />
</geometry>
<material name="hand_material">
<color rgba="0.30196078431372547213 0.30196078431372547213 0.30196078431372547213 1.0"/>
</material>
</visual>
<visual>
<origin xyz="-2.870512492503005384e-16 -0.053975599999998624678 -0.042000000000009994616" rpy="-1.4218472271716742932e-16 -7.9901304630480062342e-17 -1.57079632679489678" />
<geometry>
<box size="0.077551200000000000689 0.041200000000000000511 0.0030000000000000000625" />
</geometry>
<material name="hand_material">
<color rgba="0.30196078431372547213 0.30196078431372547213 0.30196078431372547213 1.0"/>
</material>
</visual>
<inertial>
<origin xyz="9.007860998903207783e-05 -0.050592813860686161598 -0.022164128160995381911" rpy="0 0 0"/>
<mass value="0.22758681850404099967" />
<inertia ixx="0.0006362237286513012938" ixy="-6.8818031269096265894e-07"  ixz="6.3997466140469571858e-07" iyy="0.00011529484226278863214" iyz="-1.2452787769693135121e-05" izz="0.00065540810703735631094" />
</inertial>
</link>

<joint name="left_elbow" type="revolute">
<origin xyz="0.02349999999999953515 -0.14200000000002568901 -0.0024999999999900518466" rpy="1.6303130422869307442e-15 1.570796326794896336 0" />
<parent link="left_humerus" />
<child link="radius_v2_2" />
<axis xyz="0 0 1"/>
<limit effort="10" velocity="6" lower="-2.7925268031909271649" upper="0"/>
<joint_properties friction="0.0"/>
</joint>

<joint name="left_shoulder_roll" type="revolute">
<origin xyz="0.023500000000000003525 0.030000000000000054401 0.034999999999999933942" rpy="-3.1415926535897917837 -1.5707963267948958919 0" />
<parent link="u_shoulder_2" />
<child link="left_humerus" />
<axis xyz="0 0 1"/>
<limit effort="10" velocity="6" lower="-0.087266462599716473902" upper="1.570796326794896558"/>
<joint_properties friction="0.0"/>
</joint>

<joint name="left_shoulder_pitch" type="revolute">
<origin xyz="0.03086897349438466609 0.079500000000020845659 0.14300000000001039657" rpy="-1.5707963267949047736 -7.2164496600635995543e-15 2.4883110829860584224e-15" />
<parent link="torso" />
<child link="u_shoulder_2" />
<axis xyz="0 0 1"/>
<limit effort="10" velocity="6" lower="-2.1816615649929120835" upper="2.1816615649929120835"/>
<joint_properties friction="0.0"/>
</joint>

<link name="u_hip_with_saver">
<inertial>
<origin xyz="-6.0662048803369837395e-11 0.0012617757666187436657 -0.032913798334011076796" rpy="0 0 0"/>
<mass value="0.13603079497559261712" />
<inertia ixx="0.00012159106574302210534" ixy="4.6578657936511304279e-14"  ixz="1.9417490229974809325e-13" iyy="7.5515874860539031936e-05" iyz="7.1305998545052296019e-07" izz="5.6688399673283892445e-05" />
</inertial>
</link>

<link name="mx106_with_u_r">
<!-- Shapes for inner -->
<collision>
<origin xyz="-0.015149999999999299444 -0.00015000000000064094008 -0.079943750000000091127" rpy="-3.1415926535897922278 3.948230631324550855e-15 1.570796326794896558" />
<geometry>
<box size="0.026999999999999999695 0.058000000000000002942 0.025999999999999998807" />
</geometry>
</collision>
<!-- Shapes for inner -->
<visual>
<origin xyz="-0.015149999999999299444 -0.00015000000000064094008 -0.079943750000000091127" rpy="-3.1415926535897922278 3.948230631324550855e-15 1.570796326794896558" />
<geometry>
<box size="0.026999999999999999695 0.058000000000000002942 0.025999999999999998807" />
</geometry>
<material name="inner_material">
<color rgba="0.64705882352941179736 0.64705882352941179736 0.64705882352941179736 1.0"/>
</material>
</visual>
<!-- Shapes for inner -->
<collision>
<origin xyz="-0.015149999999999632511 -0.00049999999999979054255 -0.020249999999999983291" rpy="-1.5707963267948950037 -1.5707963267948923392 0" />
<geometry>
<box size="0.026999999999999999695 0.058000000000000002942 0.025999999999999998807" />
</geometry>
</collision>
<!-- Shapes for inner -->
<visual>
<origin xyz="-0.015149999999999632511 -0.00049999999999979054255 -0.020249999999999983291" rpy="-1.5707963267948950037 -1.5707963267948923392 0" />
<geometry>
<box size="0.026999999999999999695 0.058000000000000002942 0.025999999999999998807" />
</geometry>
<material name="inner_material">
<color rgba="0.64705882352941179736 0.64705882352941179736 0.64705882352941179736 1.0"/>
</material>
</visual>
<inertial>
<origin xyz="-0.013149571443777331378 -0.0010321542415933000238 -0.047524251739160451591" rpy="0 0 0"/>
<mass value="0.4215737648609173549" />
<inertia ixx="0.00044031356920203555943" ixy="4.4195902414030463001e-07"  ixz="-4.5199071777205478557e-06" iyy="0.00058157871502234018569" iyz="1.1647370421632168458e-05" izz="0.00024573166895922331134" />
</inertial>
</link>

<link name="thigh_horn_left">
<!-- Shapes for thigh_free_left -->
<collision>
<origin xyz="-6.2771002740172498331e-17 0.039999999999999397149 -0.0053999999999997244648" rpy="-3.1415926535897895633 1.0408241149111790378e-16 3.9898639947484103001e-17" />
<geometry>
<box size="0.02999999999999999889 0.080000000000000001665 0.0030000000000000000625" />
</geometry>
</collision>
<!-- Shapes for thigh_free_left -->
<visual>
<origin xyz="-6.2771002740172498331e-17 0.039999999999999397149 -0.0053999999999997244648" rpy="-3.1415926535897895633 1.0408241149111790378e-16 3.9898639947484103001e-17" />
<geometry>
<box size="0.02999999999999999889 0.080000000000000001665 0.0030000000000000000625" />
</geometry>
<material name="thigh_free_left_material">
<color rgba="0.61568627450980395466 0.81176470588235294379 0.92941176470588238168 1.0"/>
</material>
</visual>
<!-- Shapes for thigh_horn -->
<collision>
<origin xyz="5.5234650653321450516e-16 0.039999999999999119593 0.043600000000000999067" rpy="-3.1415926535897913396 1.1101156708843630659e-16 4.076600168546602926e-17" />
<geometry>
<box size="0.02999999999999999889 0.080000000000000001665 0.0030000000000000000625" />
</geometry>
</collision>
<!-- Shapes for thigh_horn -->
<visual>
<origin xyz="5.5234650653321450516e-16 0.039999999999999119593 0.043600000000000999067" rpy="-3.1415926535897913396 1.1101156708843630659e-16 4.076600168546602926e-17" />
<geometry>
<box size="0.02999999999999999889 0.080000000000000001665 0.0030000000000000000625" />
</geometry>
<material name="thigh_horn_material">
<color rgba="0.61568627450980395466 0.81176470588235294379 0.92941176470588238168 1.0"/>
</material>
</visual>
<!-- Shapes for inner -->
<collision>
<origin xyz="0.00014999999999996439792 0.12484999999999979448 0.016500000000020900726" rpy="3.1415926535897926719 -1.3877688100918726975e-16 -3.1415926535897926719" />
<geometry>
<box size="0.026999999999999999695 0.058000000000000002942 0.025999999999999998807" />
</geometry>
</collision>
<!-- Shapes for inner -->
<visual>
<origin xyz="0.00014999999999996439792 0.12484999999999979448 0.016500000000020900726" rpy="3.1415926535897926719 -1.3877688100918726975e-16 -3.1415926535897926719" />
<geometry>
<box size="0.026999999999999999695 0.058000000000000002942 0.025999999999999998807" />
</geometry>
<material name="inner_material">
<color rgba="0.64705882352941179736 0.64705882352941179736 0.64705882352941179736 1.0"/>
</material>
</visual>
<inertial>
<origin xyz="-1.5876030315711877066e-05 0.11282935899963093818 0.016288206429262704761" rpy="0 0 0"/>
<mass value="0.22711106780187376164" />
<inertia ixx="0.00049319619498835272006" ixy="-1.161000941219161628e-07"  ixz="-1.7669436099127624863e-08" iyy="6.3394655653102472011e-05" iyz="-4.7783986946694684858e-05" izz="0.00048370848690869712927" />
</inertial>
</link>

<link name="tibia_left_full">
<!-- Shapes for tibia_horn_side -->
<collision>
<origin xyz="-0.065000000000023733238 2.4423993331063580627e-14 0.043500000000013708257" rpy="-1.0547118733939581935e-14 -4.5578713548640804876e-14 -1.0004738475670239517e-14" />
<geometry>
<box size="0.14999999999999999445 0.035000000000000003331 0.0030000000000000000625" />
</geometry>
</collision>
<!-- Shapes for tibia_horn_side -->
<visual>
<origin xyz="-0.065000000000023733238 2.4423993331063580627e-14 0.043500000000013708257" rpy="-1.0547118733939581935e-14 -4.5578713548640804876e-14 -1.0004738475670239517e-14" />
<geometry>
<box size="0.14999999999999999445 0.035000000000000003331 0.0030000000000000000625" />
</geometry>
<material name="tibia_horn_side_material">
<color rgba="0.61568627450980395466 0.81176470588235294379 0.92941176470588238168 1.0"/>
</material>
</visual>
<!-- Shapes for tibia_left -->
<collision>
<origin xyz="-0.06500000000002371936 -0.0024999999999865026024 -0.0085000000000015115548" rpy="3.9636915715716167153e-30 -0 0" />
<geometry>
<box size="0.14999999999999999445 0.035000000000000003331 0.0030000000000000000625" />
</geometry>
</collision>
<!-- Shapes for tibia_left -->
<visual>
<origin xyz="-0.06500000000002371936 -0.0024999999999865026024 -0.0085000000000015115548" rpy="3.9636915715716167153e-30 -0 0" />
<geometry>
<box size="0.14999999999999999445 0.035000000000000003331 0.0030000000000000000625" />
</geometry>
<material name="tibia_left_material">
<color rgba="0.61568627450980395466 0.81176470588235294379 0.92941176470588238168 1.0"/>
</material>
</visual>
<inertial>
<origin xyz="-0.070000001170458805988 1.7806104867340376712e-13 0.0013921737730272624491" rpy="0 0 0"/>
<mass value="0.050146782973123575633" />
<inertia ixx="1.6277029156000852604e-05" ixy="2.2210978976311631138e-17"  ixz="-1.2987687840933925939e-13" iyy="0.00026199625807223298011" iyz="-3.3899316670412699284e-16" izz="0.00024814461872032302385" />
</inertial>
</link>

<link name="mx106_with_u_l">
<!-- Shapes for inner -->
<collision>
<origin xyz="0.015150000000000416606 -0.059843750000000320299 0.015849999999999475619" rpy="1.5707963267948910069 -1.5707963267948927832 0" />
<geometry>
<box size="0.026999999999999999695 0.058000000000000002942 0.025999999999999998807" />
</geometry>
</collision>
<!-- Shapes for inner -->
<visual>
<origin xyz="0.015150000000000416606 -0.059843750000000320299 0.015849999999999475619" rpy="1.5707963267948910069 -1.5707963267948927832 0" />
<geometry>
<box size="0.026999999999999999695 0.058000000000000002942 0.025999999999999998807" />
</geometry>
<material name="inner_material">
<color rgba="0.64705882352941179736 0.64705882352941179736 0.64705882352941179736 1.0"/>
</material>
</visual>
<!-- Shapes for inner -->
<collision>
<origin xyz="0.015149999999999792105 0.00015000000000031307734 0.016500000000000125677" rpy="3.1415926535897926719 3.8649639044764390135e-15 -1.570796326794896558" />
<geometry>
<box size="0.026999999999999999695 0.058000000000000002942 0.025999999999999998807" />
</geometry>
</collision>
<!-- Shapes for inner -->
<visual>
<origin xyz="0.015149999999999792105 0.00015000000000031307734 0.016500000000000125677" rpy="3.1415926535897926719 3.8649639044764390135e-15 -1.570796326794896558" />
<geometry>
<box size="0.026999999999999999695 0.058000000000000002942 0.025999999999999998807" />
</geometry>
<material name="inner_material">
<color rgba="0.64705882352941179736 0.64705882352941179736 0.64705882352941179736 1.0"/>
</material>
</visual>
<inertial>
<origin xyz="0.013149571443777909041 -0.027401788839542921133 0.017009691337375964365" rpy="0 0 0"/>
<mass value="0.42157376486091741041" />
<inertia ixx="0.00044085209496061368616" ixy="4.2567791059201627683e-06"  ixz="7.0508640333339137149e-07" iyy="0.00024575100476948217145" iyz="-1.194954932027522798e-05" izz="0.0005820979049706717038" />
</inertial>
</link>

<link name="left_foot_asm">
<!-- Shapes for cleat -->
<collision>
<origin xyz="0.052000000000000101696 -0.032500000000000396627 -0.075629999999999905635" rpy="1.57079632679489678 0.026366457596474868891 1.5707963267949003328" />
<geometry>
<cylinder length="0.016000000000000000333" radius="0.0080000000000000001665" />
</geometry>
</collision>
<!-- Shapes for cleat -->
<visual>
<origin xyz="0.052000000000000101696 -0.032500000000000396627 -0.075629999999999905635" rpy="1.57079632679489678 0.026366457596474868891 1.5707963267949003328" />
<geometry>
<cylinder length="0.016000000000000000333" radius="0.0080000000000000001665" />
</geometry>
<material name="cleat_material">
<color rgba="0.30196078431372547213 0.29019607843137257275 0.26274509803921569651 1.0"/>
</material>
</visual>
<!-- Shapes for cleat -->
<collision>
<origin xyz="0.052000000000000129452 0.043499999999999872102 0.065969999999999764939" rpy="-1.5707963267948970021 -1.0347510063016465143 -1.5707963267949032193" />
<geometry>
<cylinder length="0.016000000000000000333" radius="0.0080000000000000001665" />
</geometry>
</collision>
<!-- Shapes for cleat -->
<visual>
<origin xyz="0.052000000000000129452 0.043499999999999872102 0.065969999999999764939" rpy="-1.5707963267948970021 -1.0347510063016465143 -1.5707963267949032193" />
<geometry>
<cylinder length="0.016000000000000000333" radius="0.0080000000000000001665" />
</geometry>
<material name="cleat_material">
<color rgba="0.30196078431372547213 0.29019607843137257275 0.26274509803921569651 1.0"/>
</material>
</visual>
<!-- Shapes for cleat -->
<collision>
<origin xyz="0.052000000000000191902 -0.032499999999999827638 0.065970000000000167395" rpy="1.5707963267948970021 1.0034677146468358178 1.570796326794891451" />
<geometry>
<cylinder length="0.016000000000000000333" radius="0.0080000000000000001665" />
</geometry>
</collision>
<!-- Shapes for cleat -->
<visual>
<origin xyz="0.052000000000000191902 -0.032499999999999827638 0.065970000000000167395" rpy="1.5707963267948970021 1.0034677146468358178 1.570796326794891451" />
<geometry>
<cylinder length="0.016000000000000000333" radius="0.0080000000000000001665" />
</geometry>
<material name="cleat_material">
<color rgba="0.30196078431372547213 0.29019607843137257275 0.26274509803921569651 1.0"/>
</material>
</visual>
<!-- Shapes for cleat -->
<collision>
<origin xyz="0.052000000000000032307 0.043499999999999428013 -0.075630000000000363602" rpy="1.57079632679489678 0.026366457596474768277 1.5707963267948983344" />
<geometry>
<cylinder length="0.016000000000000000333" radius="0.0080000000000000001665" />
</geometry>
</collision>
<!-- Shapes for cleat -->
<visual>
<origin xyz="0.052000000000000032307 0.043499999999999428013 -0.075630000000000363602" rpy="1.57079632679489678 0.026366457596474768277 1.5707963267948983344" />
<geometry>
<cylinder length="0.016000000000000000333" radius="0.0080000000000000001665" />
</geometry>
<material name="cleat_material">
<color rgba="0.30196078431372547213 0.29019607843137257275 0.26274509803921569651 1.0"/>
</material>
</visual>
<!-- Shapes for foot_plate -->
<collision>
<origin xyz="0.041500000000000154821 0.0055000000000003899936 -0.0048299999999998725897" rpy="-1.570796326794896558 -6.9319058822545437012e-18 1.570796326794896558" />
<geometry>
<box size="0.091999999999999998446 0.1575999999999999901 0.0030000000000000000625" />
</geometry>
</collision>
<!-- Shapes for foot_plate -->
<visual>
<origin xyz="0.041500000000000154821 0.0055000000000003899936 -0.0048299999999998725897" rpy="-1.570796326794896558 -6.9319058822545437012e-18 1.570796326794896558" />
<geometry>
<box size="0.091999999999999998446 0.1575999999999999901 0.0030000000000000000625" />
</geometry>
<material name="foot_plate_material">
<color rgba="0.30196078431372547213 0.30196078431372547213 0.30196078431372547213 1.0"/>
</material>
</visual>
<inertial>
<origin xyz="0.031258906017488589935 0.0041429761138329999209 0.00081745218759699119718" rpy="0 0 0"/>
<mass value="0.32138977066764801149" />
<inertia ixx="0.0010224927730150461334" ixy="-8.6967442944990981218e-06"  ixz="-2.1885686287278133716e-05" iyy="0.0008643998627451647673" iyz="-1.0407520697590757938e-05" izz="0.00032657256034924597027" />
</inertial>
</link>

<link name="left_foot">
<inertial>
<origin xyz="0 0 0" rpy="0 0 0" />
<mass value="1e-9" />
<inertia ixx="0" ixy="0" ixz="0" iyy="0" iyz="0" izz="0" />
</inertial>
</link>
<joint name="left_foot_frame" type="fixed">
<origin xyz="0.060000000000000275335 0.0055000000000001159073 -0.0048299999999999489175" rpy="-6.2664175067465104603e-16 -1.5707963267948947816 0" />
<parent link="left_foot_asm" />
<child link="left_foot" />
<axis xyz="0 0 0"/>
</joint>

<joint name="left_ankle_roll" type="revolute">
<origin xyz="-1.1102230246251565404e-16 0.020099999999999937361 0.016000000000000135641" rpy="1.5707963267948934494 6.5049045633606117685e-15 3.1415926535897895633" />
<parent link="mx106_with_u_l" />
<child link="left_foot_asm" />
<axis xyz="0 0 1"/>
<limit effort="10" velocity="6" lower="-0.785398163397448279" upper="0.785398163397448279"/>
<joint_properties friction="0.0"/>
</joint>

<joint name="left_ankle_pitch" type="revolute">
<origin xyz="-0.14000000000002504885 1.3950646193805482653e-14 0" rpy="-6.1231560962847779576e-14 -1.8582018332858367343e-14 -5.6936840381678493267e-14" />
<parent link="tibia_left_full" />
<child link="mx106_with_u_l" />
<axis xyz="0 0 1"/>
<limit effort="10" velocity="6" lower="-1.570796326794896558" upper="1.570796326794896558"/>
<joint_properties friction="0.0"/>
</joint>

<joint name="left_knee" type="revolute">
<origin xyz="-2.3678975447083416839e-16 0.13999999999999973577 2.0757701113538473692e-14" rpy="2.8102530281515361041e-15 3.8106870795519192501e-15 -1.5707963267948208408" />
<parent link="thigh_horn_left" />
<child link="tibia_left_full" />
<axis xyz="0 0 1"/>
<limit effort="10" velocity="6" lower="0" upper="3.141592653589793116"/>
<joint_properties friction="0.0"/>
</joint>

<joint name="left_hip_pitch" type="revolute">
<origin xyz="-1.8041124150158793782e-16 0.016000000000000000333 -0.020099999999999784706" rpy="1.57079632679489678 -1.5707963267948910069 0" />
<parent link="mx106_with_u_r" />
<child link="thigh_horn_left" />
<axis xyz="0 0 1"/>
<limit effort="10" velocity="6" lower="-1.570796326794896558" upper="1.570796326794896558"/>
<joint_properties friction="0.0"/>
</joint>

<joint name="left_hip_roll" type="revolute">
<origin xyz="-8.3266726846886740532e-17 -0.020099054048956847135 -0.060400000000000342304" rpy="1.5707963267948823471 -1.5707963267948934494 0" />
<parent link="u_hip_with_saver" />
<child link="mx106_with_u_r" />
<axis xyz="0 0 1"/>
<limit effort="10" velocity="6" lower="-0.52359877559829881566" upper="0.52359877559829881566"/>
<joint_properties friction="0.0"/>
</joint>

<joint name="left_hip_yaw" type="revolute">
<origin xyz="0.0058689734943615417054 0.04640000000001042596 -0.041099999999999782541" rpy="2.3786004854476977408e-16 -4.9676806335296454892e-15 1.5707963267948459318" />
<parent link="torso" />
<child link="u_hip_with_saver" />
<axis xyz="0 0 1"/>
<limit effort="10" velocity="6" lower="-1.0471975511965976313" upper="1.0471975511965976313"/>
<joint_properties friction="0.0"/>
</joint>

<link name="u_hip_with_saver_2">
<inertial>
<origin xyz="-6.0661964204781197791e-11 0.0012617757666185727954 -0.032913798334010632707" rpy="0 0 0"/>
<mass value="0.13603079497559264488" />
<inertia ixx="0.00012159106574302117022" ixy="4.6578756815691666307e-14"  ixz="1.9417490644027779367e-13" iyy="7.5515874860538069707e-05" iyz="7.1305998545042226915e-07" izz="5.6688399673283763696e-05" />
</inertial>
</link>

<link name="mx106_with_u_l_2">
<!-- Shapes for inner -->
<collision>
<origin xyz="-0.014914056614044393645 0.00050000000000012360946 -0.019950000000000037148" rpy="1.57079632679489678 1.5707963267948921171 0" />
<geometry>
<box size="0.026999999999999999695 0.058000000000000002942 0.025999999999999998807" />
</geometry>
</collision>
<!-- Shapes for inner -->
<visual>
<origin xyz="-0.014914056614044393645 0.00050000000000012360946 -0.019950000000000037148" rpy="1.57079632679489678 1.5707963267948921171 0" />
<geometry>
<box size="0.026999999999999999695 0.058000000000000002942 0.025999999999999998807" />
</geometry>
<material name="inner_material">
<color rgba="0.64705882352941179736 0.64705882352941179736 0.64705882352941179736 1.0"/>
</material>
</visual>
<!-- Shapes for inner -->
<collision>
<origin xyz="-0.014914056614044407523 -0.00015000000000043103854 -0.07994375000000045195" rpy="3.1415926535897926719 -4.9960036108139153928e-16 1.570796326794896558" />
<geometry>
<box size="0.026999999999999999695 0.058000000000000002942 0.025999999999999998807" />
</geometry>
</collision>
<!-- Shapes for inner -->
<visual>
<origin xyz="-0.014914056614044407523 -0.00015000000000043103854 -0.07994375000000045195" rpy="3.1415926535897926719 -4.9960036108139153928e-16 1.570796326794896558" />
<geometry>
<box size="0.026999999999999999695 0.058000000000000002942 0.025999999999999998807" />
</geometry>
<material name="inner_material">
<color rgba="0.64705882352941179736 0.64705882352941179736 0.64705882352941179736 1.0"/>
</material>
</visual>
<inertial>
<origin xyz="-0.012913628057822245168 0.0010096913373759787771 -0.047501788839543208909" rpy="0 0 0"/>
<mass value="0.4215737648609173549" />
<inertia ixx="0.0004408520949606096204" ixy="-7.0508640333356638967e-07"  ixz="-4.2567791059173235138e-06" iyy="0.00058209790497066953539" iyz="-1.1949549320275263555e-05" izz="0.00024575100476948076198" />
</inertial>
</link>

<link name="thigh_horn_right">
<!-- Shapes for thigh_horn -->
<collision>
<origin xyz="-5.2321688564332298927e-16 0.03999999999999970246 -0.043399999999979919918" rpy="3.1415926535897926719 3.2612801348357292709e-16 -1.6315074291561920027e-15" />
<geometry>
<box size="0.02999999999999999889 0.080000000000000001665 0.0030000000000000000625" />
</geometry>
</collision>
<!-- Shapes for thigh_horn -->
<visual>
<origin xyz="-5.2321688564332298927e-16 0.03999999999999970246 -0.043399999999979919918" rpy="3.1415926535897926719 3.2612801348357292709e-16 -1.6315074291561920027e-15" />
<geometry>
<box size="0.02999999999999999889 0.080000000000000001665 0.0030000000000000000625" />
</geometry>
<material name="thigh_horn_material">
<color rgba="0.61568627450980395466 0.81176470588235294379 0.92941176470588238168 1.0"/>
</material>
</visual>
<!-- Shapes for inner -->
<collision>
<origin xyz="-0.00015000000000039287462 0.12485000000000004428 -0.0165000000000201201" rpy="-3.7477172512793993548e-16 -1.5751289161867753782e-15 7.042977312466169111e-16" />
<geometry>
<box size="0.026999999999999999695 0.058000000000000002942 0.025999999999999998807" />
</geometry>
</collision>
<!-- Shapes for inner -->
<visual>
<origin xyz="-0.00015000000000039287462 0.12485000000000004428 -0.0165000000000201201" rpy="-3.7477172512793993548e-16 -1.5751289161867753782e-15 7.042977312466169111e-16" />
<geometry>
<box size="0.026999999999999999695 0.058000000000000002942 0.025999999999999998807" />
</geometry>
<material name="inner_material">
<color rgba="0.64705882352941179736 0.64705882352941179736 0.64705882352941179736 1.0"/>
</material>
</visual>
<!-- Shapes for thigh_free_right -->
<collision>
<origin xyz="-2.0202660163703722037e-16 0.03600000000000030953 0.0053999999999998840594" rpy="-5.9674692791137384844e-16 -2.8449465006001896839e-16 -1.0321604682058702554e-16" />
<geometry>
<box size="0.02999999999999999889 0.080000000000000001665 0.0030000000000000000625" />
</geometry>
</collision>
<!-- Shapes for thigh_free_right -->
<visual>
<origin xyz="-2.0202660163703722037e-16 0.03600000000000030953 0.0053999999999998840594" rpy="-5.9674692791137384844e-16 -2.8449465006001896839e-16 -1.0321604682058702554e-16" />
<geometry>
<box size="0.02999999999999999889 0.080000000000000001665 0.0030000000000000000625" />
</geometry>
<material name="thigh_free_right_material">
<color rgba="0.61568627450980395466 0.81176470588235294379 0.92941176470588238168 1.0"/>
</material>
</visual>
<inertial>
<origin xyz="-5.7572673555914775359e-05 0.11282935899963118798 -0.016288206538102922849" rpy="0 0 0"/>
<mass value="0.22711106780187373388" />
<inertia ixx="0.00049319619497410099093" ixy="-2.4645187479047137763e-07"  ixz="-1.2861859320600927641e-08" iyy="6.3393960096580316619e-05" iyz="4.7783986349623572688e-05" izz="0.00048370779136642307093" />
</inertial>
</link>

<link name="tibia_right_full">
<!-- Shapes for tibia_right -->
<collision>
<origin xyz="-0.065000000000248595033 0.00050000000005469280584 0.0085000000000481652079" rpy="-3.141592653589793116 2.7938110519938794773e-31 -3.0814879117108225706e-33" />
<geometry>
<box size="0.14999999999999999445 0.035000000000000003331 0.0030000000000000000625" />
</geometry>
</collision>
<!-- Shapes for tibia_right -->
<visual>
<origin xyz="-0.065000000000248595033 0.00050000000005469280584 0.0085000000000481652079" rpy="-3.141592653589793116 2.7938110519938794773e-31 -3.0814879117108225706e-33" />
<geometry>
<box size="0.14999999999999999445 0.035000000000000003331 0.0030000000000000000625" />
</geometry>
<material name="tibia_right_material">
<color rgba="0.61568627450980395466 0.81176470588235294379 0.92941176470588238168 1.0"/>
</material>
</visual>
<!-- Shapes for tibia_horn_side -->
<collision>
<origin xyz="-0.065000000000266386357 1.0632784288916171385e-14 -0.0435000000000278636" rpy="4.9571458049512494845e-14 -1.7024572288000741573e-13 3.0538939432824751655e-14" />
<geometry>
<box size="0.14999999999999999445 0.035000000000000003331 0.0030000000000000000625" />
</geometry>
</collision>
<!-- Shapes for tibia_horn_side -->
<visual>
<origin xyz="-0.065000000000266386357 1.0632784288916171385e-14 -0.0435000000000278636" rpy="4.9571458049512494845e-14 -1.7024572288000741573e-13 3.0538939432824751655e-14" />
<geometry>
<box size="0.14999999999999999445 0.035000000000000003331 0.0030000000000000000625" />
</geometry>
<material name="tibia_horn_side_material">
<color rgba="0.61568627450980395466 0.81176470588235294379 0.92941176470588238168 1.0"/>
</material>
</visual>
<inertial>
<origin xyz="-0.070000001170570883002 -1.7604032391792960476e-13 -0.0013921737730081932844" rpy="0 0 0"/>
<mass value="0.050146782973123575633" />
<inertia ixx="1.6277029156049143647e-05" ixy="-2.4967396270163151496e-17"  ixz="1.2995763929509081269e-13" iyy="0.00026199625807307616414" iyz="-3.3321703103710267359e-16" izz="0.00024814461872111796088" />
</inertial>
</link>

<link name="mx106_with_u_r_2">
<!-- Shapes for inner -->
<collision>
<origin xyz="0.015150000000000676814 -0.00014999999999977531306 -0.016499999999999726691" rpy="2.4802208897777937949e-15 -1.8943180357655302876e-15 1.570796326794896558" />
<geometry>
<box size="0.026999999999999999695 0.058000000000000002942 0.025999999999999998807" />
</geometry>
</collision>
<!-- Shapes for inner -->
<visual>
<origin xyz="0.015150000000000676814 -0.00014999999999977531306 -0.016499999999999726691" rpy="2.4802208897777937949e-15 -1.8943180357655302876e-15 1.570796326794896558" />
<geometry>
<box size="0.026999999999999999695 0.058000000000000002942 0.025999999999999998807" />
</geometry>
<material name="inner_material">
<color rgba="0.64705882352941179736 0.64705882352941179736 0.64705882352941179736 1.0"/>
</material>
</visual>
<!-- Shapes for inner -->
<collision>
<origin xyz="0.015149999999999719247 -0.059843750000000084377 -0.016150000000000150346" rpy="1.5707963267948972241 -1.570796326794896558 0" />
<geometry>
<box size="0.026999999999999999695 0.058000000000000002942 0.025999999999999998807" />
</geometry>
</collision>
<!-- Shapes for inner -->
<visual>
<origin xyz="0.015149999999999719247 -0.059843750000000084377 -0.016150000000000150346" rpy="1.5707963267948972241 -1.570796326794896558 0" />
<geometry>
<box size="0.026999999999999999695 0.058000000000000002942 0.025999999999999998807" />
</geometry>
<material name="inner_material">
<color rgba="0.64705882352941179736 0.64705882352941179736 0.64705882352941179736 1.0"/>
</material>
</visual>
<inertial>
<origin xyz="0.01314957144377807037 -0.027424251739160351166 -0.017032154241593051858" rpy="0 0 0"/>
<mass value="0.4215737648609173549" />
<inertia ixx="0.00044031356920203501733" ixy="4.519907177717083491e-06"  ixz="-4.4195902413956135859e-07" iyy="0.00024573166895922016716" iyz="1.1647370421634174232e-05" izz="0.00058157871502234647406" />
</inertial>
</link>

<link name="right_foot_asm">
<!-- Shapes for cleat -->
<collision>
<origin xyz="0.051999999999999040046 -0.043499999999997436551 -0.075629999999997837845" rpy="1.570796326794896558 0.84200343552874756803 1.5707963267948923392" />
<geometry>
<cylinder length="0.016000000000000000333" radius="0.0080000000000000001665" />
</geometry>
</collision>
<!-- Shapes for cleat -->
<visual>
<origin xyz="0.051999999999999040046 -0.043499999999997436551 -0.075629999999997837845" rpy="1.570796326794896558 0.84200343552874756803 1.5707963267948923392" />
<geometry>
<cylinder length="0.016000000000000000333" radius="0.0080000000000000001665" />
</geometry>
<material name="cleat_material">
<color rgba="0.30196078431372547213 0.29019607843137257275 0.26274509803921569651 1.0"/>
</material>
</visual>
<!-- Shapes for cleat -->
<collision>
<origin xyz="0.051999999999999116373 -0.043499999999997381039 0.065970000000001596807" rpy="-1.570796326794896558 -1.1078788439634876806 -1.5707963267948918951" />
<geometry>
<cylinder length="0.016000000000000000333" radius="0.0080000000000000001665" />
</geometry>
</collision>
<!-- Shapes for cleat -->
<visual>
<origin xyz="0.051999999999999116373 -0.043499999999997381039 0.065970000000001596807" rpy="-1.570796326794896558 -1.1078788439634876806 -1.5707963267948918951" />
<geometry>
<cylinder length="0.016000000000000000333" radius="0.0080000000000000001665" />
</geometry>
<material name="cleat_material">
<color rgba="0.30196078431372547213 0.29019607843137257275 0.26274509803921569651 1.0"/>
</material>
</visual>
<!-- Shapes for cleat -->
<collision>
<origin xyz="0.051999999999998998412 0.032500000000001479095 -0.075629999999997504778" rpy="1.570796326794896558 0.84200343552874801212 1.5707963267948954478" />
<geometry>
<cylinder length="0.016000000000000000333" radius="0.0080000000000000001665" />
</geometry>
</collision>
<!-- Shapes for cleat -->
<visual>
<origin xyz="0.051999999999998998412 0.032500000000001479095 -0.075629999999997504778" rpy="1.570796326794896558 0.84200343552874801212 1.5707963267948954478" />
<geometry>
<cylinder length="0.016000000000000000333" radius="0.0080000000000000001665" />
</geometry>
<material name="cleat_material">
<color rgba="0.30196078431372547213 0.29019607843137257275 0.26274509803921569651 1.0"/>
</material>
</visual>
<!-- Shapes for cleat -->
<collision>
<origin xyz="0.051999999999998977596 0.032500000000001395828 0.065970000000002040896" rpy="1.570796326794896558 0.84200343552874679087 1.5707963267948981123" />
<geometry>
<cylinder length="0.016000000000000000333" radius="0.0080000000000000001665" />
</geometry>
</collision>
<!-- Shapes for cleat -->
<visual>
<origin xyz="0.051999999999998977596 0.032500000000001395828 0.065970000000002040896" rpy="1.570796326794896558 0.84200343552874679087 1.5707963267948981123" />
<geometry>
<cylinder length="0.016000000000000000333" radius="0.0080000000000000001665" />
</geometry>
<material name="cleat_material">
<color rgba="0.30196078431372547213 0.29019607843137257275 0.26274509803921569651 1.0"/>
</material>
</visual>
<!-- Shapes for foot_plate -->
<collision>
<origin xyz="0.041499999999999197253 -0.0054999999999993951297 -0.0048299999999985299137" rpy="-1.570796326794896558 -1.0759940612699560494e-29 1.570796326794896558" />
<geometry>
<box size="0.091999999999999998446 0.1575999999999999901 0.0030000000000000000625" />
</geometry>
</collision>
<!-- Shapes for foot_plate -->
<visual>
<origin xyz="0.041499999999999197253 -0.0054999999999993951297 -0.0048299999999985299137" rpy="-1.570796326794896558 -1.0759940612699560494e-29 1.570796326794896558" />
<geometry>
<box size="0.091999999999999998446 0.1575999999999999901 0.0030000000000000000625" />
</geometry>
<material name="foot_plate_material">
<color rgba="0.30196078431372547213 0.30196078431372547213 0.30196078431372547213 1.0"/>
</material>
</visual>
<inertial>
<origin xyz="0.031258906017488076456 -0.0041430219081712276602 0.00081745218760322232391" rpy="0 0 0"/>
<mass value="0.32138977066764795598" />
<inertia ixx="0.0010224924474882301269" ixy="8.6971207758325704939e-06"  ixz="-2.188568628724394069e-05" iyy="0.00086439986274518027139" iyz="1.0406619706263050887e-05" izz="0.00032657223482244243217" />
</inertial>
</link>

<link name="right_foot">
<inertial>
<origin xyz="0 0 0" rpy="0 0 0" />
<mass value="1e-9" />
<inertia ixx="0" ixy="0" ixz="0" iyy="0" iyz="0" izz="0" />
</inertial>
</link>
<joint name="right_foot_frame" type="fixed">
<origin xyz="0.05999999999999905409 -0.005500000000000331013 -0.0048299999999974474463" rpy="5.2020940636638788206e-15 -1.570796326794891451 0" />
<parent link="right_foot_asm" />
<child link="right_foot" />
<axis xyz="0 0 0"/>
</joint>

<joint name="right_ankle_roll" type="revolute">
<origin xyz="3.8857805861880478915e-16 0.020099999999999926953 -0.015999999999999691552" rpy="1.570796326794896336 2.4094412794995258621e-15 3.1415926535897926719" />
<parent link="mx106_with_u_r_2" />
<child link="right_foot_asm" />
<axis xyz="0 0 1"/>
<limit effort="10" velocity="6" lower="-0.785398163397448279" upper="0.785398163397448279"/>
<joint_properties friction="0.0"/>
</joint>

<joint name="right_ankle_pitch" type="revolute">
<origin xyz="-0.14000000000024515057 -1.5889199678209564581e-14 3.0114799542957371159e-14" rpy="5.0446957243049974607e-16 -6.5007295419637772327e-15 -1.5612511284079219651e-17" />
<parent link="tibia_right_full" />
<child link="mx106_with_u_r_2" />
<axis xyz="0 0 1"/>
<limit effort="10" velocity="6" lower="-1.570796326794896558" upper="1.570796326794896558"/>
<joint_properties friction="0.0"/>
</joint>

<joint name="right_knee" type="revolute">
<origin xyz="-2.9143354396410359186e-16 0.14000000000000067946 -9.5756735873919751612e-16" rpy="-3.9621086151768392032e-15 7.7674449885245198315e-16 -1.5707963267948938935" />
<parent link="thigh_horn_right" />
<child link="tibia_right_full" />
<axis xyz="0 0 1"/>
<limit effort="10" velocity="6" lower="-0" upper="3.141592653589793116"/>
<joint_properties friction="0.0"/>
</joint>

<joint name="right_hip_pitch" type="revolute">
<origin xyz="0.00023594338595557540206 -0.01599999999999995523 -0.020100000000000020628" rpy="1.5707963267949038855 -1.5707963267948861219 0" />
<parent link="mx106_with_u_l_2" />
<child link="thigh_horn_right" />
<axis xyz="0 0 1"/>
<limit effort="10" velocity="6" lower="-1.570796326794896558" upper="1.570796326794896558"/>
<joint_properties friction="0.0"/>
</joint>

<joint name="right_hip_roll" type="revolute">
<origin xyz="4.8572257327350598644e-17 -0.020099054048955403845 -0.06039999999999973862" rpy="1.5707963267949003328 -1.5707963267948901187 0" />
<parent link="u_hip_with_saver_2" />
<child link="mx106_with_u_l_2" />
<axis xyz="0 0 1"/>
<limit effort="10" velocity="6" lower="-0.52359877559829881566" upper="0.52359877559829881566"/>
<joint_properties friction="0.0"/>
</joint>

<joint name="right_hip_yaw" type="revolute">
<origin xyz="0.0058689734943568345332 -0.046400000000004472389 -0.041099999999999956013" rpy="3.9664277854914981584e-16 -5.2373734976912576551e-15 1.5707963267948397146" />
<parent link="torso" />
<child link="u_hip_with_saver_2" />
<axis xyz="0 0 1"/>
<limit effort="10" velocity="6" lower="-1.0471975511965976313" upper="1.0471975511965976313"/>
<joint_properties friction="0.0"/>
</joint>

<link name="u_neck">
<!-- Shapes for u_base_64 -->
<collision>
<origin xyz="-1.5841869951446374715e-30 1.9005683112325801655e-33 0.0031250000000000001735" rpy="3.141592653589793116 1.0760150683960479162e-30 2.5435149567047161031e-30" />
<geometry>
<box size="0.049000000000000001887 0.02999999999999999889 0.0062500000000000003469" />
</geometry>
</collision>
<!-- Shapes for u_base_64 -->
<visual>
<origin xyz="-1.5841869951446374715e-30 1.9005683112325801655e-33 0.0031250000000000001735" rpy="3.141592653589793116 1.0760150683960479162e-30 2.5435149567047161031e-30" />
<geometry>
<box size="0.049000000000000001887 0.02999999999999999889 0.0062500000000000003469" />
</geometry>
<material name="u_base_64_material">
<color rgba="0.30196078431372547213 0.30196078431372547213 0.30196078431372547213 1.0"/>
</material>
</visual>
<!-- Shapes for u_side_neck -->
<collision>
<origin xyz="0.024999999999997531142 -3.0457189381881090812e-15 0.032901041851019170725" rpy="1.5707963267948832353 -1.3655105410866222494e-14 -1.5707963267950497688" />
<geometry>
<box size="0.02999999999999999889 0.065802000000000013258 0.0030000000000000000625" />
</geometry>
</collision>
<!-- Shapes for u_side_neck -->
<visual>
<origin xyz="0.024999999999997531142 -3.0457189381881090812e-15 0.032901041851019170725" rpy="1.5707963267948832353 -1.3655105410866222494e-14 -1.5707963267950497688" />
<geometry>
<box size="0.02999999999999999889 0.065802000000000013258 0.0030000000000000000625" />
</geometry>
<material name="u_side_neck_material">
<color rgba="0.30196078431372547213 0.30196078431372547213 0.30196078431372547213 1.0"/>
</material>
</visual>
<!-- Shapes for u_side_neck -->
<collision>
<origin xyz="-0.024999999999997954414 2.1110032865301041812e-15 0.032901041851018872353" rpy="1.5707963267949138775 1.4765328435491386923e-14 1.5707963267947435693" />
<geometry>
<box size="0.02999999999999999889 0.065802000000000013258 0.0030000000000000000625" />
</geometry>
</collision>
<!-- Shapes for u_side_neck -->
<visual>
<origin xyz="-0.024999999999997954414 2.1110032865301041812e-15 0.032901041851018872353" rpy="1.5707963267949138775 1.4765328435491386923e-14 1.5707963267947435693" />
<geometry>
<box size="0.02999999999999999889 0.065802000000000013258 0.0030000000000000000625" />
</geometry>
<material name="u_side_neck_material">
<color rgba="0.30196078431372547213 0.30196078431372547213 0.30196078431372547213 1.0"/>
</material>
</visual>
<inertial>
<origin xyz="-7.2980541624496337685e-17 -2.2550272171318596093e-16 0.020633402679854667694" rpy="0 0 0"/>
<mass value="0.054479900613359215356" />
<inertia ixx="3.0578702573705855315e-05" ixy="-1.359442073240762873e-11"  ixz="-2.0302320954501511252e-19" iyy="5.1695196768444141172e-05" iyz="4.3860424800011739432e-20" izz="2.9852490907286756438e-05" />
</inertial>
</link>

<link name="head__field_of_view_false">
<!-- Shapes for mx-64at_ar -->
<collision>
<origin xyz="2.0003793705409979402e-16 -0.017549999999999999628 -0.023500000000009090007" rpy="-3.0995404954062957907e-16 1.2458494113711814868e-15 1.3367138803608229201e-14" />
<geometry>
<box size="0.040199999999999999623 0.061100000000000001532 0.041000000000000001721" />
</geometry>
</collision>
<!-- Shapes for mx-64at_ar -->
<visual>
<origin xyz="2.0003793705409979402e-16 -0.017549999999999999628 -0.023500000000009090007" rpy="-3.0995404954062957907e-16 1.2458494113711814868e-15 1.3367138803608229201e-14" />
<geometry>
<box size="0.040199999999999999623 0.061100000000000001532 0.041000000000000001721" />
</geometry>
<material name="mx-64at_ar_material">
<color rgba="0.1686274509803921684 0.1686274509803921684 0.1686274509803921684 1.0"/>
</material>
</visual>
<!-- Shapes for head_plate -->
<collision>
<origin xyz="-0.023799999999999668643 0.036499999999999692413 -0.042000000000008384793" rpy="3.141592653589793116 -7.4624905029014848483e-16 -3.1415926535897797933" />
<geometry>
<cylinder length="0.0030000000000000000625" radius="0.023500000000000000056" />
</geometry>
</collision>
<collision>
<origin xyz="0.0099999999999991692756 0.036500000000000143441 -0.042000000000008412548" rpy="3.141592653589793116 -7.4624905029014848483e-16 -3.1415926535897797933" />
<geometry>
<box size="0.061600000000000001976 0.047000000000000000111 0.0030000000000000000625" />
</geometry>
</collision>
<!-- Shapes for head_plate -->
<visual>
<origin xyz="-0.023799999999999668643 0.036499999999999692413 -0.042000000000008384793" rpy="3.141592653589793116 -7.4624905029014848483e-16 -3.1415926535897797933" />
<geometry>
<cylinder length="0.0030000000000000000625" radius="0.023500000000000000056" />
</geometry>
<material name="head_plate_material">
<color rgba="0.70196078431372543882 0.68235294117647060652 0.62352941176470588758 1.0"/>
</material>
</visual>
<visual>
<origin xyz="0.0099999999999991692756 0.036500000000000143441 -0.042000000000008412548" rpy="3.141592653589793116 -7.4624905029014848483e-16 -3.1415926535897797933" />
<geometry>
<box size="0.061600000000000001976 0.047000000000000000111 0.0030000000000000000625" />
</geometry>
<material name="head_plate_material">
<color rgba="0.70196078431372543882 0.68235294117647060652 0.62352941176470588758 1.0"/>
</material>
</visual>
<!-- Shapes for head_plate -->
<collision>
<origin xyz="-0.023800000000009622486 0.036500000000009705237 -0.0049999999999997546407" rpy="-3.141592653589793116 -8.5727135275261197545e-16 -3.1415926535897797933" />
<geometry>
<cylinder length="0.0030000000000000000625" radius="0.023500000000000000056" />
</geometry>
</collision>
<collision>
<origin xyz="0.0099999999999891998198 0.036500000000010163204 -0.004999999999999784131" rpy="-3.141592653589793116 -8.5727135275261197545e-16 -3.1415926535897797933" />
<geometry>
<box size="0.061600000000000001976 0.047000000000000000111 0.0030000000000000000625" />
</geometry>
</collision>
<!-- Shapes for head_plate -->
<visual>
<origin xyz="-0.023800000000009622486 0.036500000000009705237 -0.0049999999999997546407" rpy="-3.141592653589793116 -8.5727135275261197545e-16 -3.1415926535897797933" />
<geometry>
<cylinder length="0.0030000000000000000625" radius="0.023500000000000000056" />
</geometry>
<material name="head_plate_material">
<color rgba="0.70196078431372543882 0.68235294117647060652 0.62352941176470588758 1.0"/>
</material>
</visual>
<visual>
<origin xyz="0.0099999999999891998198 0.036500000000010163204 -0.004999999999999784131" rpy="-3.141592653589793116 -8.5727135275261197545e-16 -3.1415926535897797933" />
<geometry>
<box size="0.061600000000000001976 0.047000000000000000111 0.0030000000000000000625" />
</geometry>
<material name="head_plate_material">
<color rgba="0.70196078431372543882 0.68235294117647060652 0.62352941176470588758 1.0"/>
</material>
</visual>
<inertial>
<origin xyz="-0.0010300354651199463557 0.002129411732546657339 -0.022097835096360075868" rpy="0 0 0"/>
<mass value="0.22740577538449363582" />
<inertia ixx="0.00021508425454752963654" ixy="1.0807486480165486045e-05"  ixz="3.0361594707888172005e-07" iyy="8.2015204757477066502e-05" iyz="4.1996875137765527311e-06" izz="0.00021574975376809194015" />
</inertial>
</link>

<link name="camera">
<inertial>
<origin xyz="0 0 0" rpy="0 0 0" />
<mass value="1e-9" />
<inertia ixx="0" ixy="0" ixz="0" iyy="0" iyz="0" izz="0" />
</inertial>
</link>
<joint name="camera_frame" type="fixed">
<origin xyz="-0.024933000004023209151 0.033500000000054735994 -0.023500000000009093476" rpy="3.1415926535897797933 1.5707963267948958919 0" />
<parent link="head__field_of_view_false" />
<child link="camera" />
<axis xyz="0 0 0"/>
</joint>

<joint name="head_pitch" type="revolute">
<origin xyz="-0.023499999999997519401 2.2482016248659419944e-15 0.058302041851018837626" rpy="1.5707963267948794606 -9.3778577129540909355e-15 -1.5707963267950493247" />
<parent link="u_neck" />
<child link="head__field_of_view_false" />
<axis xyz="0 0 1"/>
<limit effort="10" velocity="6" lower="-0.785398163397448279" upper="1.570796326794896558"/>
<joint_properties friction="0.0"/>
</joint>

<joint name="head_yaw" type="revolute">
<origin xyz="0.035868973494361702792 -2.0768736888402729908e-15 0.15950000000001013367" rpy="9.7750460134011636162e-15 -1.1951368418674699747e-14 -1.5707963267948004127" />
<parent link="torso" />
<child link="u_neck" />
<axis xyz="0 0 1"/>
<limit effort="10" velocity="6" lower="-2.0943951023931952626" upper="2.0943951023931952626"/>
<joint_properties friction="0.0"/>
</joint>


</robot>
